{
  "version": 8,
  "blockIdVersion": 11,
  "anchorX": 1,
  "anchorY": 6,
  "anchorZ": -4,
  "blocks": [
    {
      "x": -7,
      "y": 4,
      "z": -4,
      "name": "Soil_Dirt"
    },
    {
      "x": -7,
      "y": 5,
      "z": -4,
      "name": "Soil_Pathway"
    },
    {
      "x": -7,
      "y": 5,
      "z": -3,
      "name": "Soil_Pathway"
    },
    {
      "x": -6,
      "y": 5,
      "z": -5,
      "name": "Soil_Pathway"
    },
    {
      "x": -6,
      "y": 4,
      "z": -4,
      "name": "Soil_Dirt"
    },
    {
      "x": -6,
      "y": 5,
      "z": -4,
      "name": "Soil_Pathway"
    },
    {
      "x": -6,
      "y": 5,
      "z": -3,
      "name": "Soil_Pathway"
    },
    {
      "x": -6,
      "y": 5,
      "z": -2,
      "name": "Soil_Pathway"
    },
    {
      "x": -6,
      "y": 5,
      "z": -1,
      "name": "Soil_Pathway"
    },
    {
      "x": -5,
      "y": 5,
      "z": -6,
      "name": "Soil_Pathway"
    },
    {
      "x": -5,
      "y": 5,
      "z": -5,
      "name": "Soil_Pathway"
    },
    {
      "x": -5,
      "y": 4,
      "z": -4,
      "name": "Soil_Dirt"
    },
    {
      "x": -5,
      "y": 5,
      "z": -4,
      "name": "Soil_Dirt"
    },
    {
      "x": -5,
      "y": 4,
      "z": -3,
      "name": "Soil_Dirt"
    },
    {
      "x": -5,
      "y": 5,
      "z": -3,
      "name": "Soil_Dirt"
    },
    {
      "x": -5,
      "y": 5,
      "z": -2,
      "name": "Soil_Dirt"
    },
    {
      "x": -5,
      "y": 5,
      "z": -1,
      "name": "Soil_Pathway"
    },
    {
      "x": -5,
      "y": 5,
      "z": 0,
      "name": "Soil_Pathway"
    },
    {
      "x": -4,
      "y": 5,
      "z": -7,
      "name": "Soil_Pathway"
    },
    {
      "x": -4,
      "y": 5,
      "z": -6,
      "name": "Soil_Pathway"
    },
    {
      "x": -4,
      "y": 5,
      "z": -5,
      "name": "Soil_Pathway"
    },
    {
      "x": -4,
      "y": 4,
      "z": -4,
      "name": "Soil_Dirt"
    },
    {
      "x": -4,
      "y": 5,
      "z": -4,
      "name": "Soil_Dirt"
    },
    {
      "x": -4,
      "y": 4,
      "z": -3,
      "name": "Soil_Dirt"
    },
    {
      "x": -4,
      "y": 5,
      "z": -3,
      "name": "Soil_Dirt_Tilled",
      "components": {
        "Components": {
          "PlacedByInteraction": {
            "WhoPlacedUuid": {
              "$binary": "9ZjLHQsUQaC73VAqONe4MQ==",
              "$type": "04"
            }
          },
          "TilledSoil": {
            "Version": 1,
            "DecayTime": "0001-01-02T18:15:19Z"
          }
        }
      }
    },
    {
      "x": -4,
      "y": 6,
      "z": -3,
      "name": "*Plant_Crop_Carrot_Block_State_Definitions_Stage2",
      "components": {
        "Components": {
          "FarmingBlock": {
            "LastTickGameTime": "0001-01-01T12:00:00Z"
          },
          "PlacedByInteraction": {
            "WhoPlacedUuid": {
              "$binary": "9ZjLHQsUQaC73VAqONe4MQ==",
              "$type": "04"
            }
          }
        }
      }
    },
    {
      "x": -4,
      "y": 5,
      "z": -2,
      "name": "Soil_Dirt"
    },
    {
      "x": -4,
      "y": 5,
      "z": -1,
      "name": "Soil_Dirt"
    },
    {
      "x": -4,
      "y": 5,
      "z": 0,
      "name": "Soil_Pathway"
    },
    {
      "x": -4,
      "y": 5,
      "z": 1,
      "name": "Soil_Pathway"
    },
    {
      "x": -3,
      "y": 16,
      "z": -12,
      "name": "Plant_Leaves_Oak"
    },
    {
      "x": -3,
      "y": 16,
      "z": -11,
      "name": "Plant_Leaves_Oak"
    },
    {
      "x": -3,
      "y": 17,
      "z": -11,
      "name": "Plant_Leaves_Oak"
    },
    {
      "x": -3,
      "y": 15,
      "z": -10,
      "name": "Plant_Leaves_Oak"
    },
    {
      "x": -3,
      "y": 16,
      "z": -10,
      "name": "Plant_Leaves_Oak"
    },
    {
      "x": -3,
      "y": 17,
      "z": -10,
      "name": "Plant_Leaves_Oak"
    },
    {
      "x": -3,
      "y": 16,
      "z": -9,
      "name": "Plant_Leaves_Oak"
    },
    {
      "x": -3,
      "y": 5,
      "z": -8,
      "name": "Soil_Pathway"
    },
    {
      "x": -3,
      "y": 5,
      "z": -7,
      "name": "Soil_Grass_Deep"
    },
    {
      "x": -3,
      "y": 18,
      "z": -7,
      "name": "Plant_Leaves_Oak"
    },
    {
      "x": -3,
      "y": 5,
      "z": -6,
      "name": "Soil_Pathway"
    },
    {
      "x": -3,
      "y": 17,
      "z": -6,
      "name": "Plant_Leaves_Oak"
    },
    {
      "x": -3,
      "y": 18,
      "z": -6,
      "name": "Plant_Leaves_Oak"
    },
    {
      "x": -3,
      "y": 5,
      "z": -5,
      "name": "Soil_Grass_Deep"
    },
    {
      "x": -3,
      "y": 16,
      "z": -5,
      "name": "Plant_Leaves_Oak"
    },
    {
      "x": -3,
      "y": 17,
      "z": -5,
      "name": "Plant_Leaves_Oak"
    },
    {
      "x": -3,
      "y": 4,
      "z": -4,
      "name": "Soil_Dirt"
    },
    {
      "x": -3,
      "y": 5,
      "z": -4,
      "name": "Soil_Grass_Deep"
    },
    {
      "x": -3,
      "y": 16,
      "z": -4,
      "name": "Plant_Leaves_Oak"
    },
    {
      "x": -3,
      "y": 17,
      "z": -4,
      "name": "Plant_Leaves_Oak"
    },
    {
      "x": -3,
      "y": 4,
      "z": -3,
      "name": "Soil_Dirt"
    },
    {
      "x": -3,
      "y": 5,
      "z": -3,
      "name": "Soil_Dirt_Tilled",
      "components": {
        "Components": {
          "PlacedByInteraction": {
            "WhoPlacedUuid": {
              "$binary": "9ZjLHQsUQaC73VAqONe4MQ==",
              "$type": "04"
            }
          },
          "TilledSoil": {
            "Version": 1,
            "DecayTime": "0001-01-02T19:30:10Z"
          }
        }
      }
    },
    {
      "x": -3,
      "y": 6,
      "z": -3,
      "name": "*Plant_Crop_Carrot_Block_State_Definitions_Stage2",
      "components": {
        "Components": {
          "FarmingBlock": {
            "LastTickGameTime": "0001-01-01T12:00:00Z"
          },
          "PlacedByInteraction": {
            "WhoPlacedUuid": {
              "$binary": "9ZjLHQsUQaC73VAqONe4MQ==",
              "$type": "04"
            }
          }
        }
      }
    },
    {
      "x": -3,
      "y": 4,
      "z": -2,
      "name": "Soil_Dirt"
    },
    {
      "x": -3,
      "y": 5,
      "z": -2,
      "name": "Soil_Dirt_Tilled",
      "components": {
        "Components": {
          "PlacedByInteraction": {
            "WhoPlacedUuid": {
              "$binary": "9ZjLHQsUQaC73VAqONe4MQ==",
              "$type": "04"
            }
          },
          "TilledSoil": {
            "Version": 1,
            "DecayTime": "0001-01-02T23:19:13Z"
          }
        }
      }
    },
    {
      "x": -3,
      "y": 6,
      "z": -2,
      "name": "*Plant_Crop_Carrot_Block_State_Definitions_Stage2",
      "components": {
        "Components": {
          "FarmingBlock": {
            "LastTickGameTime": "0001-01-01T12:00:00Z"
          },
          "PlacedByInteraction": {
            "WhoPlacedUuid": {
              "$binary": "9ZjLHQsUQaC73VAqONe4MQ==",
              "$type": "04"
            }
          }
        }
      }
    },
    {
      "x": -3,
      "y": 4,
      "z": -1,
      "name": "Soil_Dirt"
    },
    {
      "x": -3,
      "y": 5,
      "z": -1,
      "name": "Soil_Dirt"
    },
    {
      "x": -3,
      "y": 5,
      "z": 0,
      "name": "Soil_Dirt"
    },
    {
      "x": -3,
      "y": 5,
      "z": 1,
      "name": "Soil_Pathway"
    },
    {
      "x": -3,
      "y": 5,
      "z": 2,
      "name": "Soil_Pathway"
    },
    {
      "x": -2,
      "y": 16,
      "z": -13,
      "name": "Plant_Leaves_Oak"
    },
    {
      "x": -2,
      "y": 17,
      "z": -12,
      "name": "Plant_Leaves_Oak"
    },
    {
      "x": -2,
      "y": 16,
      "z": -11,
      "name": "Plant_Leaves_Oak"
    },
    {
      "x": -2,
      "y": 17,
      "z": -11,
      "name": "Plant_Leaves_Oak"
    },
    {
      "x": -2,
      "y": 5,
      "z": -10,
      "name": "Soil_Pathway"
    },
    {
      "x": -2,
      "y": 17,
      "z": -10,
      "name": "Plant_Leaves_Oak"
    },
    {
      "x": -2,
      "y": 18,
      "z": -10,
      "name": "Plant_Leaves_Oak"
    },
    {
      "x": -2,
      "y": 5,
      "z": -9,
      "name": "Soil_Pathway"
    },
    {
      "x": -2,
      "y": 15,
      "z": -9,
      "name": "Plant_Leaves_Oak"
    },
    {
      "x": -2,
      "y": 16,
      "z": -9,
      "name": "Plant_Leaves_Oak"
    },
    {
      "x": -2,
      "y": 17,
      "z": -9,
      "name": "Plant_Leaves_Oak"
    },
    {
      "x": -2,
      "y": 18,
      "z": -9,
      "name": "Plant_Leaves_Oak"
    },
    {
      "x": -2,
      "y": 5,
      "z": -8,
      "name": "Soil_Leaves"
    },
    {
      "x": -2,
      "y": 17,
      "z": -8,
      "name": "Plant_Leaves_Oak"
    },
    {
      "x": -2,
      "y": 18,
      "z": -8,
      "name": "Plant_Leaves_Oak"
    },
    {
      "x": -2,
      "y": 5,
      "z": -7,
      "name": "Soil_Leaves"
    },
    {
      "x": -2,
      "y": 18,
      "z": -7,
      "name": "Plant_Leaves_Oak"
    },
    {
      "x": -2,
      "y": 19,
      "z": -7,
      "name": "Plant_Leaves_Oak"
    },
    {
      "x": -2,
      "y": 5,
      "z": -6,
      "name": "Soil_Grass_Deep"
    },
    {
      "x": -2,
      "y": 17,
      "z": -6,
      "name": "Plant_Leaves_Oak"
    },
    {
      "x": -2,
      "y": 18,
      "z": -6,
      "name": "Plant_Leaves_Oak"
    },
    {
      "x": -2,
      "y": 19,
      "z": -6,
      "name": "Plant_Leaves_Oak"
    },
    {
      "x": -2,
      "y": 5,
      "z": -5,
      "name": "Soil_Grass_Deep"
    },
    {
      "x": -2,
      "y": 17,
      "z": -5,
      "name": "Plant_Leaves_Oak"
    },
    {
      "x": -2,
      "y": 18,
      "z": -5,
      "name": "Plant_Leaves_Oak"
    },
    {
      "x": -2,
      "y": 19,
      "z": -5,
      "name": "Plant_Leaves_Oak"
    },
    {
      "x": -2,
      "y": 4,
      "z": -4,
      "name": "Soil_Dirt"
    },
    {
      "x": -2,
      "y": 5,
      "z": -4,
      "name": "Soil_Grass_Deep"
    },
    {
      "x": -2,
      "y": 16,
      "z": -4,
      "name": "Plant_Leaves_Oak"
    },
    {
      "x": -2,
      "y": 17,
      "z": -4,
      "name": "Plant_Leaves_Oak"
    },
    {
      "x": -2,
      "y": 18,
      "z": -4,
      "name": "Plant_Leaves_Oak"
    },
    {
      "x": -2,
      "y": 4,
      "z": -3,
      "name": "Soil_Dirt"
    },
    {
      "x": -2,
      "y": 5,
      "z": -3,
      "name": "Soil_Dirt_Tilled",
      "components": {
        "Components": {
          "PlacedByInteraction": {
            "WhoPlacedUuid": {
              "$binary": "9ZjLHQsUQaC73VAqONe4MQ==",
              "$type": "04"
            }
          },
          "TilledSoil": {
            "Version": 1,
            "DecayTime": "0001-01-02T19:34:43Z"
          }
        }
      }
    },
    {
      "x": -2,
      "y": 6,
      "z": -3,
      "name": "*Plant_Crop_Carrot_Block_State_Definitions_Stage1",
      "components": {
        "Components": {
          "FarmingBlock": {
            "LastTickGameTime": "0001-01-01T12:00:00Z"
          },
          "PlacedByInteraction": {
            "WhoPlacedUuid": {
              "$binary": "9ZjLHQsUQaC73VAqONe4MQ==",
              "$type": "04"
            }
          }
        }
      }
    },
    {
      "x": -2,
      "y": 16,
      "z": -3,
      "name": "Plant_Leaves_Oak"
    },
    {
      "x": -2,
      "y": 17,
      "z": -3,
      "name": "Plant_Leaves_Oak"
    },
    {
      "x": -2,
      "y": 4,
      "z": -2,
      "name": "Soil_Dirt"
    },
    {
      "x": -2,
      "y": 5,
      "z": -2,
      "name": "Soil_Dirt_Tilled",
      "components": {
        "Components": {
          "PlacedByInteraction": {
            "WhoPlacedUuid": {
              "$binary": "9ZjLHQsUQaC73VAqONe4MQ==",
              "$type": "04"
            }
          },
          "TilledSoil": {
            "Version": 1,
            "DecayTime": "0001-01-02T18:15:32Z"
          }
        }
      }
    },
    {
      "x": -2,
      "y": 6,
      "z": -2,
      "name": "*Plant_Crop_Carrot_Block_State_Definitions_Stage2",
      "components": {
        "Components": {
          "FarmingBlock": {
            "LastTickGameTime": "0001-01-01T12:00:00Z"
          },
          "PlacedByInteraction": {
            "WhoPlacedUuid": {
              "$binary": "9ZjLHQsUQaC73VAqONe4MQ==",
              "$type": "04"
            }
          }
        }
      }
    },
    {
      "x": -2,
      "y": 4,
      "z": -1,
      "name": "Soil_Dirt"
    },
    {
      "x": -2,
      "y": 5,
      "z": -1,
      "name": "Soil_Dirt"
    },
    {
      "x": -2,
      "y": 4,
      "z": 0,
      "name": "Soil_Dirt"
    },
    {
      "x": -2,
      "y": 5,
      "z": 0,
      "name": "Soil_Dirt"
    },
    {
      "x": -2,
      "y": 5,
      "z": 1,
      "name": "Soil_Dirt"
    },
    {
      "x": -2,
      "y": 5,
      "z": 2,
      "name": "Soil_Pathway"
    },
    {
      "x": -2,
      "y": 5,
      "z": 3,
      "name": "Soil_Pathway"
    },
    {
      "x": -1,
      "y": 16,
      "z": -13,
      "name": "Plant_Leaves_Oak"
    },
    {
      "x": -1,
      "y": 17,
      "z": -13,
      "name": "Plant_Leaves_Oak"
    },
    {
      "x": -1,
      "y": 16,
      "z": -12,
      "name": "Plant_Leaves_Oak"
    },
    {
      "x": -1,
      "y": 17,
      "z": -12,
      "name": "Plant_Leaves_Oak"
    },
    {
      "x": -1,
      "y": 18,
      "z": -12,
      "name": "Plant_Leaves_Oak"
    },
    {
      "x": -1,
      "y": 5,
      "z": -11,
      "name": "Soil_Pathway"
    },
    {
      "x": -1,
      "y": 16,
      "z": -11,
      "name": "Wood_Oak_Trunk_Full"
    },
    {
      "x": -1,
      "y": 17,
      "z": -11,
      "name": "Plant_Leaves_Oak"
    },
    {
      "x": -1,
      "y": 18,
      "z": -11,
      "name": "Plant_Leaves_Oak"
    },
    {
      "x": -1,
      "y": 19,
      "z": -11,
      "name": "Plant_Leaves_Oak"
    },
    {
      "x": -1,
      "y": 0,
      "z": -10,
      "name": "Soil_Dirt"
    },
    {
      "x": -1,
      "y": 1,
      "z": -10,
      "name": "Soil_Dirt"
    },
    {
      "x": -1,
      "y": 2,
      "z": -10,
      "name": "Soil_Dirt"
    },
    {
      "x": -1,
      "y": 3,
      "z": -10,
      "name": "Soil_Dirt"
    },
    {
      "x": -1,
      "y": 4,
      "z": -10,
      "name": "Soil_Dirt"
    },
    {
      "x": -1,
      "y": 5,
      "z": -10,
      "name": "Soil_Leaves"
    },
    {
      "x": -1,
      "y": 17,
      "z": -10,
      "name": "Plant_Leaves_Oak"
    },
    {
      "x": -1,
      "y": 18,
      "z": -10,
      "name": "Plant_Leaves_Oak"
    },
    {
      "x": -1,
      "y": 19,
      "z": -10,
      "name": "Plant_Leaves_Oak"
    },
    {
      "x": -1,
      "y": 0,
      "z": -9,
      "name": "Soil_Dirt"
    },
    {
      "x": -1,
      "y": 1,
      "z": -9,
      "name": "Soil_Dirt"
    },
    {
      "x": -1,
      "y": 2,
      "z": -9,
      "name": "Soil_Dirt"
    },
    {
      "x": -1,
      "y": 3,
      "z": -9,
      "name": "Soil_Dirt"
    },
    {
      "x": -1,
      "y": 4,
      "z": -9,
      "name": "Soil_Dirt"
    },
    {
      "x": -1,
      "y": 5,
      "z": -9,
      "name": "Soil_Leaves"
    },
    {
      "x": -1,
      "y": 16,
      "z": -9,
      "name": "Plant_Leaves_Oak"
    },
    {
      "x": -1,
      "y": 17,
      "z": -9,
      "name": "Plant_Leaves_Oak"
    },
    {
      "x": -1,
      "y": 18,
      "z": -9,
      "name": "Plant_Leaves_Oak"
    },
    {
      "x": -1,
      "y": 0,
      "z": -8,
      "name": "Soil_Dirt"
    },
    {
      "x": -1,
      "y": 1,
      "z": -8,
      "name": "Soil_Dirt"
    },
    {
      "x": -1,
      "y": 2,
      "z": -8,
      "name": "Soil_Dirt"
    },
    {
      "x": -1,
      "y": 3,
      "z": -8,
      "name": "Soil_Dirt"
    },
    {
      "x": -1,
      "y": 4,
      "z": -8,
      "name": "Soil_Dirt"
    },
    {
      "x": -1,
      "y": 5,
      "z": -8,
      "name": "Soil_Leaves"
    },
    {
      "x": -1,
      "y": 17,
      "z": -8,
      "name": "Plant_Leaves_Oak"
    },
    {
      "x": -1,
      "y": 18,
      "z": -8,
      "name": "Plant_Leaves_Oak"
    },
    {
      "x": -1,
      "y": 19,
      "z": -8,
      "name": "Plant_Leaves_Oak"
    },
    {
      "x": -1,
      "y": 0,
      "z": -7,
      "name": "Soil_Dirt"
    },
    {
      "x": -1,
      "y": 1,
      "z": -7,
      "name": "Soil_Dirt"
    },
    {
      "x": -1,
      "y": 2,
      "z": -7,
      "name": "Soil_Dirt"
    },
    {
      "x": -1,
      "y": 3,
      "z": -7,
      "name": "Soil_Dirt"
    },
    {
      "x": -1,
      "y": 4,
      "z": -7,
      "name": "Soil_Dirt"
    },
    {
      "x": -1,
      "y": 5,
      "z": -7,
      "name": "Soil_Leaves"
    },
    {
      "x": -1,
      "y": 17,
      "z": -7,
      "name": "Plant_Leaves_Oak"
    },
    {
      "x": -1,
      "y": 18,
      "z": -7,
      "name": "Plant_Leaves_Oak"
    },
    {
      "x": -1,
      "y": 19,
      "z": -7,
      "name": "Plant_Leaves_Oak"
    },
    {
      "x": -1,
      "y": 20,
      "z": -7,
      "name": "Plant_Leaves_Oak"
    },
    {
      "x": -1,
      "y": 0,
      "z": -6,
      "name": "Soil_Dirt"
    },
    {
      "x": -1,
      "y": 1,
      "z": -6,
      "name": "Soil_Dirt"
    },
    {
      "x": -1,
      "y": 2,
      "z": -6,
      "name": "Soil_Dirt"
    },
    {
      "x": -1,
      "y": 3,
      "z": -6,
      "name": "Soil_Dirt"
    },
    {
      "x": -1,
      "y": 4,
      "z": -6,
      "name": "Soil_Dirt"
    },
    {
      "x": -1,
      "y": 5,
      "z": -6,
      "name": "Soil_Leaves"
    },
    {
      "x": -1,
      "y": 18,
      "z": -6,
      "name": "Wood_Oak_Trunk_Full"
    },
    {
      "x": -1,
      "y": 19,
      "z": -6,
      "name": "Plant_Leaves_Oak"
    },
    {
      "x": -1,
      "y": 20,
      "z": -6,
      "name": "Plant_Leaves_Oak"
    },
    {
      "x": -1,
      "y": 0,
      "z": -5,
      "name": "Soil_Dirt"
    },
    {
      "x": -1,
      "y": 1,
      "z": -5,
      "name": "Soil_Dirt"
    },
    {
      "x": -1,
      "y": 2,
      "z": -5,
      "name": "Soil_Dirt"
    },
    {
      "x": -1,
      "y": 3,
      "z": -5,
      "name": "Soil_Dirt"
    },
    {
      "x": -1,
      "y": 4,
      "z": -5,
      "name": "Soil_Dirt"
    },
    {
      "x": -1,
      "y": 5,
      "z": -5,
      "name": "Soil_Grass_Deep"
    },
    {
      "x": -1,
      "y": 18,
      "z": -5,
      "name": "Plant_Leaves_Oak"
    },
    {
      "x": -1,
      "y": 19,
      "z": -5,
      "name": "Plant_Leaves_Oak"
    },
    {
      "x": -1,
      "y": 20,
      "z": -5,
      "name": "Plant_Leaves_Oak"
    },
    {
      "x": -1,
      "y": 4,
      "z": -4,
      "name": "Soil_Dirt"
    },
    {
      "x": -1,
      "y": 5,
      "z": -4,
      "name": "Soil_Grass_Deep"
    },
    {
      "x": -1,
      "y": 17,
      "z": -4,
      "name": "Plant_Leaves_Oak"
    },
    {
      "x": -1,
      "y": 18,
      "z": -4,
      "name": "Plant_Leaves_Oak"
    },
    {
      "x": -1,
      "y": 19,
      "z": -4,
      "name": "Plant_Leaves_Oak"
    },
    {
      "x": -1,
      "y": 4,
      "z": -3,
      "name": "Soil_Dirt"
    },
    {
      "x": -1,
      "y": 5,
      "z": -3,
      "name": "Soil_Grass_Deep"
    },
    {
      "x": -1,
      "y": 16,
      "z": -3,
      "name": "Plant_Leaves_Oak"
    },
    {
      "x": -1,
      "y": 17,
      "z": -3,
      "name": "Plant_Leaves_Oak"
    },
    {
      "x": -1,
      "y": 18,
      "z": -3,
      "name": "Plant_Leaves_Oak"
    },
    {
      "x": -1,
      "y": 4,
      "z": -2,
      "name": "Soil_Dirt"
    },
    {
      "x": -1,
      "y": 5,
      "z": -2,
      "name": "Soil_Grass_Deep"
    },
    {
      "x": -1,
      "y": 16,
      "z": -2,
      "name": "Plant_Leaves_Oak"
    },
    {
      "x": -1,
      "y": 17,
      "z": -2,
      "name": "Plant_Leaves_Oak"
    },
    {
      "x": -1,
      "y": 4,
      "z": -1,
      "name": "Soil_Dirt"
    },
    {
      "x": -1,
      "y": 5,
      "z": -1,
      "name": "Soil_Dirt"
    },
    {
      "x": -1,
      "y": 4,
      "z": 0,
      "name": "Soil_Dirt"
    },
    {
      "x": -1,
      "y": 5,
      "z": 0,
      "name": "Soil_Dirt_Tilled",
      "components": {
        "Components": {
          "PlacedByInteraction": {
            "WhoPlacedUuid": {
              "$binary": "9ZjLHQsUQaC73VAqONe4MQ==",
              "$type": "04"
            }
          },
          "TilledSoil": {
            "Version": 1,
            "DecayTime": "0001-01-02T23:00:14Z"
          }
        }
      }
    },
    {
      "x": -1,
      "y": 6,
      "z": 0,
      "name": "*Plant_Crop_Cauliflower_Block_State_Definitions_Stage2",
      "components": {
        "Components": {
          "FarmingBlock": {
            "GrowthProgress": -0.6315237879753113,
            "LastTickGameTime": "0001-01-01T12:00:00Z"
          },
          "PlacedByInteraction": {
            "WhoPlacedUuid": {
              "$binary": "9ZjLHQsUQaC73VAqONe4MQ==",
              "$type": "04"
            }
          }
        }
      }
    },
    {
      "x": -1,
      "y": 5,
      "z": 1,
      "name": "Soil_Dirt_Tilled",
      "components": {
        "Components": {
          "PlacedByInteraction": {
            "WhoPlacedUuid": {
              "$binary": "9ZjLHQsUQaC73VAqONe4MQ==",
              "$type": "04"
            }
          },
          "TilledSoil": {
            "Version": 1,
            "DecayTime": "0001-01-02T20:14:46Z"
          }
        }
      }
    },
    {
      "x": -1,
      "y": 6,
      "z": 1,
      "name": "*Plant_Crop_Cauliflower_Block_State_Definitions_Stage2",
      "components": {
        "Components": {
          "FarmingBlock": {
            "GrowthProgress": -0.6345714330673218,
            "LastTickGameTime": "0001-01-01T12:00:00Z"
          },
          "PlacedByInteraction": {
            "WhoPlacedUuid": {
              "$binary": "9ZjLHQsUQaC73VAqONe4MQ==",
              "$type": "04"
            }
          }
        }
      }
    },
    {
      "x": -1,
      "y": 5,
      "z": 2,
      "name": "Soil_Dirt_Tilled",
      "components": {
        "Components": {
          "PlacedByInteraction": {
            "WhoPlacedUuid": {
              "$binary": "9ZjLHQsUQaC73VAqONe4MQ==",
              "$type": "04"
            }
          },
          "TilledSoil": {
            "Version": 1,
            "DecayTime": "0001-01-02T21:29:53Z"
          }
        }
      }
    },
    {
      "x": -1,
      "y": 5,
      "z": 3,
      "name": "Soil_Pathway"
    },
    {
      "x": 0,
      "y": 16,
      "z": -15,
      "name": "Plant_Leaves_Oak"
    },
    {
      "x": 0,
      "y": 17,
      "z": -15,
      "name": "Plant_Leaves_Oak"
    },
    {
      "x": 0,
      "y": 17,
      "z": -14,
      "name": "Plant_Leaves_Oak"
    },
    {
      "x": 0,
      "y": 18,
      "z": -14,
      "name": "Plant_Leaves_Oak"
    },
    {
      "x": 0,
      "y": 16,
      "z": -13,
      "name": "Plant_Leaves_Oak"
    },
    {
      "x": 0,
      "y": 18,
      "z": -13,
      "name": "Plant_Leaves_Oak"
    },
    {
      "x": 0,
      "y": 5,
      "z": -12,
      "name": "Soil_Pathway"
    },
    {
      "x": 0,
      "y": 16,
      "z": -12,
      "name": "Plant_Leaves_Oak"
    },
    {
      "x": 0,
      "y": 17,
      "z": -12,
      "name": "Plant_Leaves_Oak"
    },
    {
      "x": 0,
      "y": 18,
      "z": -12,
      "name": "Plant_Leaves_Oak"
    },
    {
      "x": 0,
      "y": 0,
      "z": -11,
      "name": "Soil_Dirt"
    },
    {
      "x": 0,
      "y": 1,
      "z": -11,
      "name": "Soil_Dirt"
    },
    {
      "x": 0,
      "y": 2,
      "z": -11,
      "name": "Soil_Dirt"
    },
    {
      "x": 0,
      "y": 3,
      "z": -11,
      "name": "Soil_Dirt"
    },
    {
      "x": 0,
      "y": 4,
      "z": -11,
      "name": "Soil_Dirt"
    },
    {
      "x": 0,
      "y": 5,
      "z": -11,
      "name": "Soil_Grass_Deep"
    },
    {
      "x": 0,
      "y": 16,
      "z": -11,
      "name": "Wood_Oak_Trunk_Full"
    },
    {
      "x": 0,
      "y": 17,
      "z": -11,
      "name": "Plant_Leaves_Oak"
    },
    {
      "x": 0,
      "y": 18,
      "z": -11,
      "name": "Plant_Leaves_Oak"
    },
    {
      "x": 0,
      "y": 19,
      "z": -11,
      "name": "Plant_Leaves_Oak"
    },
    {
      "x": 0,
      "y": 0,
      "z": -10,
      "name": "Soil_Dirt"
    },
    {
      "x": 0,
      "y": 1,
      "z": -10,
      "name": "Soil_Dirt"
    },
    {
      "x": 0,
      "y": 2,
      "z": -10,
      "name": "Soil_Dirt"
    },
    {
      "x": 0,
      "y": 3,
      "z": -10,
      "name": "Soil_Dirt"
    },
    {
      "x": 0,
      "y": 4,
      "z": -10,
      "name": "Soil_Dirt"
    },
    {
      "x": 0,
      "y": 5,
      "z": -10,
      "name": "Soil_Leaves"
    },
    {
      "x": 0,
      "y": 16,
      "z": -10,
      "name": "Wood_Oak_Trunk_Full"
    },
    {
      "x": 0,
      "y": 17,
      "z": -10,
      "name": "Plant_Leaves_Oak"
    },
    {
      "x": 0,
      "y": 18,
      "z": -10,
      "name": "Plant_Leaves_Oak"
    },
    {
      "x": 0,
      "y": 19,
      "z": -10,
      "name": "Plant_Leaves_Oak"
    },
    {
      "x": 0,
      "y": 0,
      "z": -9,
      "name": "Soil_Dirt"
    },
    {
      "x": 0,
      "y": 1,
      "z": -9,
      "name": "Soil_Dirt"
    },
    {
      "x": 0,
      "y": 2,
      "z": -9,
      "name": "Soil_Dirt"
    },
    {
      "x": 0,
      "y": 3,
      "z": -9,
      "name": "Soil_Dirt"
    },
    {
      "x": 0,
      "y": 4,
      "z": -9,
      "name": "Soil_Dirt"
    },
    {
      "x": 0,
      "y": 5,
      "z": -9,
      "name": "Soil_Leaves"
    },
    {
      "x": 0,
      "y": 7,
      "z": -9,
      "name": "Furniture_Kweebec_Sign",
      "rotation": 3
    },
    {
      "x": 0,
      "y": 0,
      "z": -8,
      "name": "Soil_Dirt"
    },
    {
      "x": 0,
      "y": 1,
      "z": -8,
      "name": "Soil_Dirt"
    },
    {
      "x": 0,
      "y": 2,
      "z": -8,
      "name": "Soil_Dirt"
    },
    {
      "x": 0,
      "y": 3,
      "z": -8,
      "name": "Soil_Dirt"
    },
    {
      "x": 0,
      "y": 4,
      "z": -8,
      "name": "Soil_Dirt"
    },
    {
      "x": 0,
      "y": 5,
      "z": -8,
      "name": "Soil_Grass_Deep"
    },
    {
      "x": 0,
      "y": 18,
      "z": -8,
      "name": "Plant_Leaves_Oak"
    },
    {
      "x": 0,
      "y": 19,
      "z": -8,
      "name": "Plant_Leaves_Oak"
    },
    {
      "x": 0,
      "y": 0,
      "z": -7,
      "name": "Soil_Dirt"
    },
    {
      "x": 0,
      "y": 1,
      "z": -7,
      "name": "Soil_Dirt"
    },
    {
      "x": 0,
      "y": 2,
      "z": -7,
      "name": "Soil_Dirt"
    },
    {
      "x": 0,
      "y": 3,
      "z": -7,
      "name": "Soil_Dirt"
    },
    {
      "x": 0,
      "y": 4,
      "z": -7,
      "name": "Soil_Dirt"
    },
    {
      "x": 0,
      "y": 5,
      "z": -7,
      "name": "Soil_Grass_Deep"
    },
    {
      "x": 0,
      "y": 17,
      "z": -7,
      "name": "Plant_Leaves_Oak"
    },
    {
      "x": 0,
      "y": 18,
      "z": -7,
      "name": "Plant_Leaves_Oak"
    },
    {
      "x": 0,
      "y": 19,
      "z": -7,
      "name": "Plant_Leaves_Oak"
    },
    {
      "x": 0,
      "y": 0,
      "z": -6,
      "name": "Soil_Dirt"
    },
    {
      "x": 0,
      "y": 1,
      "z": -6,
      "name": "Soil_Dirt"
    },
    {
      "x": 0,
      "y": 2,
      "z": -6,
      "name": "Soil_Dirt"
    },
    {
      "x": 0,
      "y": 3,
      "z": -6,
      "name": "Soil_Dirt"
    },
    {
      "x": 0,
      "y": 4,
      "z": -6,
      "name": "Soil_Dirt"
    },
    {
      "x": 0,
      "y": 5,
      "z": -6,
      "name": "Wood_Oak_Trunk_Full"
    },
    {
      "x": 0,
      "y": 6,
      "z": -6,
      "name": "Wood_Oak_Trunk_Full"
    },
    {
      "x": 0,
      "y": 18,
      "z": -6,
      "name": "Wood_Oak_Trunk_Full"
    },
    {
      "x": 0,
      "y": 19,
      "z": -6,
      "name": "Plant_Leaves_Oak"
    },
    {
      "x": 0,
      "y": 20,
      "z": -6,
      "name": "Plant_Leaves_Oak"
    },
    {
      "x": 0,
      "y": 0,
      "z": -5,
      "name": "Soil_Dirt"
    },
    {
      "x": 0,
      "y": 1,
      "z": -5,
      "name": "Soil_Dirt"
    },
    {
      "x": 0,
      "y": 2,
      "z": -5,
      "name": "Soil_Dirt"
    },
    {
      "x": 0,
      "y": 3,
      "z": -5,
      "name": "Soil_Dirt"
    },
    {
      "x": 0,
      "y": 4,
      "z": -5,
      "name": "Soil_Dirt"
    },
    {
      "x": 0,
      "y": 5,
      "z": -5,
      "name": "Soil_Leaves"
    },
    {
      "x": 0,
      "y": 17,
      "z": -5,
      "name": "Plant_Leaves_Oak"
    },
    {
      "x": 0,
      "y": 19,
      "z": -5,
      "name": "Plant_Leaves_Oak"
    },
    {
      "x": 0,
      "y": 0,
      "z": -4,
      "name": "Soil_Dirt"
    },
    {
      "x": 0,
      "y": 1,
      "z": -4,
      "name": "Soil_Dirt"
    },
    {
      "x": 0,
      "y": 2,
      "z": -4,
      "name": "Soil_Dirt"
    },
    {
      "x": 0,
      "y": 3,
      "z": -4,
      "name": "Soil_Dirt"
    },
    {
      "x": 0,
      "y": 4,
      "z": -4,
      "name": "Soil_Dirt"
    },
    {
      "x": 0,
      "y": 5,
      "z": -4,
      "name": "Soil_Grass_Deep"
    },
    {
      "x": 0,
      "y": 17,
      "z": -4,
      "name": "Plant_Leaves_Oak"
    },
    {
      "x": 0,
      "y": 18,
      "z": -4,
      "name": "Plant_Leaves_Oak"
    },
    {
      "x": 0,
      "y": 19,
      "z": -4,
      "name": "Plant_Leaves_Oak"
    },
    {
      "x": 0,
      "y": 20,
      "z": -4,
      "name": "Plant_Leaves_Oak"
    },
    {
      "x": 0,
      "y": 4,
      "z": -3,
      "name": "Soil_Dirt"
    },
    {
      "x": 0,
      "y": 5,
      "z": -3,
      "name": "Soil_Grass_Deep"
    },
    {
      "x": 0,
      "y": 17,
      "z": -3,
      "name": "Plant_Leaves_Oak"
    },
    {
      "x": 0,
      "y": 18,
      "z": -3,
      "name": "Plant_Leaves_Oak"
    },
    {
      "x": 0,
      "y": 19,
      "z": -3,
      "name": "Plant_Leaves_Oak"
    },
    {
      "x": 0,
      "y": 4,
      "z": -2,
      "name": "Soil_Dirt"
    },
    {
      "x": 0,
      "y": 5,
      "z": -2,
      "name": "Soil_Grass_Deep"
    },
    {
      "x": 0,
      "y": 16,
      "z": -2,
      "name": "Plant_Leaves_Oak"
    },
    {
      "x": 0,
      "y": 17,
      "z": -2,
      "name": "Plant_Leaves_Oak"
    },
    {
      "x": 0,
      "y": 4,
      "z": -1,
      "name": "Soil_Dirt"
    },
    {
      "x": 0,
      "y": 5,
      "z": -1,
      "name": "Soil_Dirt"
    },
    {
      "x": 0,
      "y": 4,
      "z": 0,
      "name": "Soil_Dirt"
    },
    {
      "x": 0,
      "y": 5,
      "z": 0,
      "name": "Soil_Dirt_Tilled",
      "components": {
        "Components": {
          "PlacedByInteraction": {
            "WhoPlacedUuid": {
              "$binary": "9ZjLHQsUQaC73VAqONe4MQ==",
              "$type": "04"
            }
          },
          "TilledSoil": {
            "Version": 1,
            "DecayTime": "0001-01-02T18:02:49Z"
          }
        }
      }
    },
    {
      "x": 0,
      "y": 4,
      "z": 1,
      "name": "Soil_Dirt"
    },
    {
      "x": 0,
      "y": 5,
      "z": 1,
      "name": "Soil_Dirt_Tilled",
      "components": {
        "Components": {
          "PlacedByInteraction": {
            "WhoPlacedUuid": {
              "$binary": "9ZjLHQsUQaC73VAqONe4MQ==",
              "$type": "04"
            }
          },
          "TilledSoil": {
            "Version": 1,
            "DecayTime": "0001-01-02T21:25:13Z"
          }
        }
      }
    },
    {
      "x": 0,
      "y": 6,
      "z": 1,
      "name": "*Plant_Crop_Cauliflower_Block_State_Definitions_Stage1",
      "components": {
        "Components": {
          "FarmingBlock": {
            "GrowthProgress": -0.6337142586708069,
            "LastTickGameTime": "0001-01-01T12:00:00Z"
          },
          "PlacedByInteraction": {
            "WhoPlacedUuid": {
              "$binary": "9ZjLHQsUQaC73VAqONe4MQ==",
              "$type": "04"
            }
          }
        }
      }
    },
    {
      "x": 0,
      "y": 5,
      "z": 2,
      "name": "Soil_Dirt_Tilled",
      "components": {
        "Components": {
          "PlacedByInteraction": {
            "WhoPlacedUuid": {
              "$binary": "9ZjLHQsUQaC73VAqONe4MQ==",
              "$type": "04"
            }
          },
          "TilledSoil": {
            "Version": 1,
            "DecayTime": "0001-01-02T23:00:47Z"
          }
        }
      }
    },
    {
      "x": 0,
      "y": 6,
      "z": 2,
      "name": "*Plant_Crop_Cauliflower_Block_State_Definitions_Stage1",
      "components": {
        "Components": {
          "FarmingBlock": {
            "GrowthProgress": -0.6451428532600403,
            "LastTickGameTime": "0001-01-01T12:00:00Z"
          },
          "PlacedByInteraction": {
            "WhoPlacedUuid": {
              "$binary": "9ZjLHQsUQaC73VAqONe4MQ==",
              "$type": "04"
            }
          }
        }
      }
    },
    {
      "x": 0,
      "y": 5,
      "z": 3,
      "name": "Soil_Pathway"
    },
    {
      "x": 0,
      "y": 5,
      "z": 4,
      "name": "Soil_Pathway"
    },
    {
      "x": 1,
      "y": 16,
      "z": -16,
      "name": "Plant_Leaves_Oak"
    },
    {
      "x": 1,
      "y": 16,
      "z": -15,
      "name": "Plant_Leaves_Oak"
    },
    {
      "x": 1,
      "y": 17,
      "z": -15,
      "name": "Plant_Leaves_Oak"
    },
    {
      "x": 1,
      "y": 17,
      "z": -14,
      "name": "Plant_Leaves_Oak"
    },
    {
      "x": 1,
      "y": 18,
      "z": -14,
      "name": "Plant_Leaves_Oak"
    },
    {
      "x": 1,
      "y": 5,
      "z": -13,
      "name": "Soil_Grass_Deep"
    },
    {
      "x": 1,
      "y": 17,
      "z": -13,
      "name": "Plant_Leaves_Oak"
    },
    {
      "x": 1,
      "y": 18,
      "z": -13,
      "name": "Plant_Leaves_Oak"
    },
    {
      "x": 1,
      "y": 19,
      "z": -13,
      "name": "Plant_Leaves_Oak"
    },
    {
      "x": 1,
      "y": 0,
      "z": -12,
      "name": "Soil_Dirt"
    },
    {
      "x": 1,
      "y": 1,
      "z": -12,
      "name": "Soil_Dirt"
    },
    {
      "x": 1,
      "y": 2,
      "z": -12,
      "name": "Soil_Dirt"
    },
    {
      "x": 1,
      "y": 3,
      "z": -12,
      "name": "Soil_Dirt"
    },
    {
      "x": 1,
      "y": 4,
      "z": -12,
      "name": "Soil_Dirt"
    },
    {
      "x": 1,
      "y": 5,
      "z": -12,
      "name": "Soil_Grass_Deep"
    },
    {
      "x": 1,
      "y": 19,
      "z": -12,
      "name": "Plant_Leaves_Oak"
    },
    {
      "x": 1,
      "y": 20,
      "z": -12,
      "name": "Plant_Leaves_Oak"
    },
    {
      "x": 1,
      "y": 0,
      "z": -11,
      "name": "Soil_Dirt"
    },
    {
      "x": 1,
      "y": 1,
      "z": -11,
      "name": "Soil_Dirt"
    },
    {
      "x": 1,
      "y": 2,
      "z": -11,
      "name": "Soil_Dirt"
    },
    {
      "x": 1,
      "y": 3,
      "z": -11,
      "name": "Soil_Dirt"
    },
    {
      "x": 1,
      "y": 4,
      "z": -11,
      "name": "Soil_Dirt"
    },
    {
      "x": 1,
      "y": 5,
      "z": -11,
      "name": "Soil_Grass_Deep"
    },
    {
      "x": 1,
      "y": 17,
      "z": -11,
      "name": "Plant_Leaves_Oak"
    },
    {
      "x": 1,
      "y": 19,
      "z": -11,
      "name": "Plant_Leaves_Oak"
    },
    {
      "x": 1,
      "y": 20,
      "z": -11,
      "name": "Plant_Leaves_Oak"
    },
    {
      "x": 1,
      "y": 0,
      "z": -10,
      "name": "Soil_Dirt"
    },
    {
      "x": 1,
      "y": 1,
      "z": -10,
      "name": "Soil_Dirt"
    },
    {
      "x": 1,
      "y": 2,
      "z": -10,
      "name": "Soil_Dirt"
    },
    {
      "x": 1,
      "y": 3,
      "z": -10,
      "name": "Soil_Dirt"
    },
    {
      "x": 1,
      "y": 4,
      "z": -10,
      "name": "Wood_Oak_Trunk_Full"
    },
    {
      "x": 1,
      "y": 5,
      "z": -10,
      "name": "Wood_Oak_Trunk_Full"
    },
    {
      "x": 1,
      "y": 6,
      "z": -10,
      "name": "Wood_Oak_Trunk_Full"
    },
    {
      "x": 1,
      "y": 15,
      "z": -10,
      "name": "Wood_Oak_Trunk_Full"
    },
    {
      "x": 1,
      "y": 16,
      "z": -10,
      "name": "Wood_Oak_Trunk_Full"
    },
    {
      "x": 1,
      "y": 20,
      "z": -10,
      "name": "Plant_Leaves_Oak"
    },
    {
      "x": 1,
      "y": 0,
      "z": -9,
      "name": "Soil_Dirt"
    },
    {
      "x": 1,
      "y": 1,
      "z": -9,
      "name": "Soil_Dirt"
    },
    {
      "x": 1,
      "y": 2,
      "z": -9,
      "name": "Soil_Dirt"
    },
    {
      "x": 1,
      "y": 3,
      "z": -9,
      "name": "Soil_Dirt"
    },
    {
      "x": 1,
      "y": 4,
      "z": -9,
      "name": "Soil_Dirt"
    },
    {
      "x": 1,
      "y": 5,
      "z": -9,
      "name": "Soil_Grass_Deep"
    },
    {
      "x": 1,
      "y": 6,
      "z": -9,
      "name": "Wood_Oak_Trunk_Full"
    },
    {
      "x": 1,
      "y": 7,
      "z": -9,
      "name": "Wood_Oak_Trunk_Full"
    },
    {
      "x": 1,
      "y": 8,
      "z": -9,
      "name": "Wood_Oak_Trunk_Full"
    },
    {
      "x": 1,
      "y": 9,
      "z": -9,
      "name": "Wood_Oak_Trunk_Full"
    },
    {
      "x": 1,
      "y": 10,
      "z": -9,
      "name": "Wood_Oak_Trunk_Full"
    },
    {
      "x": 1,
      "y": 20,
      "z": -9,
      "name": "Plant_Leaves_Oak"
    },
    {
      "x": 1,
      "y": 21,
      "z": -9,
      "name": "Plant_Leaves_Oak"
    },
    {
      "x": 1,
      "y": 0,
      "z": -8,
      "name": "Soil_Dirt"
    },
    {
      "x": 1,
      "y": 1,
      "z": -8,
      "name": "Soil_Dirt"
    },
    {
      "x": 1,
      "y": 2,
      "z": -8,
      "name": "Soil_Dirt"
    },
    {
      "x": 1,
      "y": 3,
      "z": -8,
      "name": "Soil_Dirt"
    },
    {
      "x": 1,
      "y": 4,
      "z": -8,
      "name": "Soil_Dirt"
    },
    {
      "x": 1,
      "y": 5,
      "z": -8,
      "name": "Soil_Grass_Deep"
    },
    {
      "x": 1,
      "y": 6,
      "z": -8,
      "name": "Soil_Clay_Brick_Half",
      "rotation": 4
    },
    {
      "x": 1,
      "y": 7,
      "z": -8,
      "name": "Soil_Clay_Brick_Half",
      "rotation": 4
    },
    {
      "x": 1,
      "y": 8,
      "z": -8,
      "name": "Wood_Oak_Trunk_Full"
    },
    {
      "x": 1,
      "y": 9,
      "z": -8,
      "name": "Wood_Oak_Trunk_Full"
    },
    {
      "x": 1,
      "y": 10,
      "z": -8,
      "name": "Wood_Oak_Trunk_Full"
    },
    {
      "x": 1,
      "y": 11,
      "z": -8,
      "name": "Wood_Oak_Trunk_Full"
    },
    {
      "x": 1,
      "y": 12,
      "z": -8,
      "name": "Wood_Oak_Trunk_Full"
    },
    {
      "x": 1,
      "y": 18,
      "z": -8,
      "name": "Plant_Leaves_Oak"
    },
    {
      "x": 1,
      "y": 19,
      "z": -8,
      "name": "Plant_Leaves_Oak"
    },
    {
      "x": 1,
      "y": 0,
      "z": -7,
      "name": "Soil_Dirt"
    },
    {
      "x": 1,
      "y": 1,
      "z": -7,
      "name": "Soil_Dirt"
    },
    {
      "x": 1,
      "y": 2,
      "z": -7,
      "name": "Soil_Dirt"
    },
    {
      "x": 1,
      "y": 3,
      "z": -7,
      "name": "Soil_Dirt"
    },
    {
      "x": 1,
      "y": 4,
      "z": -7,
      "name": "Soil_Dirt"
    },
    {
      "x": 1,
      "y": 5,
      "z": -7,
      "name": "Soil_Grass_Deep"
    },
    {
      "x": 1,
      "y": 6,
      "z": -7,
      "name": "Soil_Clay_Brick_Half",
      "rotation": 6
    },
    {
      "x": 1,
      "y": 7,
      "z": -7,
      "name": "Soil_Clay_Brick_Half",
      "rotation": 6
    },
    {
      "x": 1,
      "y": 8,
      "z": -7,
      "name": "Wood_Oak_Trunk_Full"
    },
    {
      "x": 1,
      "y": 9,
      "z": -7,
      "name": "Wood_Oak_Trunk_Full"
    },
    {
      "x": 1,
      "y": 18,
      "z": -7,
      "name": "Plant_Leaves_Oak"
    },
    {
      "x": 1,
      "y": 19,
      "z": -7,
      "name": "Plant_Leaves_Oak"
    },
    {
      "x": 1,
      "y": 20,
      "z": -7,
      "name": "Plant_Leaves_Oak"
    },
    {
      "x": 1,
      "y": 0,
      "z": -6,
      "name": "Soil_Dirt"
    },
    {
      "x": 1,
      "y": 1,
      "z": -6,
      "name": "Soil_Dirt"
    },
    {
      "x": 1,
      "y": 2,
      "z": -6,
      "name": "Soil_Dirt"
    },
    {
      "x": 1,
      "y": 3,
      "z": -6,
      "name": "Wood_Oak_Trunk_Full"
    },
    {
      "x": 1,
      "y": 4,
      "z": -6,
      "name": "Wood_Oak_Trunk_Full"
    },
    {
      "x": 1,
      "y": 5,
      "z": -6,
      "name": "Wood_Oak_Trunk_Full"
    },
    {
      "x": 1,
      "y": 6,
      "z": -6,
      "name": "Wood_Oak_Trunk_Full"
    },
    {
      "x": 1,
      "y": 7,
      "z": -6,
      "name": "Wood_Oak_Trunk_Full"
    },
    {
      "x": 1,
      "y": 8,
      "z": -6,
      "name": "Wood_Oak_Trunk_Full"
    },
    {
      "x": 1,
      "y": 14,
      "z": -6,
      "name": "Furniture_Kweebec_Lantern"
    },
    {
      "x": 1,
      "y": 15,
      "z": -6,
      "name": "Deco_Rope"
    },
    {
      "x": 1,
      "y": 16,
      "z": -6,
      "name": "Deco_Rope"
    },
    {
      "x": 1,
      "y": 17,
      "z": -6,
      "name": "Wood_Oak_Trunk_Full"
    },
    {
      "x": 1,
      "y": 18,
      "z": -6,
      "name": "Wood_Oak_Trunk_Full"
    },
    {
      "x": 1,
      "y": 19,
      "z": -6,
      "name": "Plant_Leaves_Oak"
    },
    {
      "x": 1,
      "y": 20,
      "z": -6,
      "name": "Plant_Leaves_Oak"
    },
    {
      "x": 1,
      "y": 21,
      "z": -6,
      "name": "Plant_Leaves_Oak"
    },
    {
      "x": 1,
      "y": 0,
      "z": -5,
      "name": "Soil_Dirt"
    },
    {
      "x": 1,
      "y": 1,
      "z": -5,
      "name": "Soil_Dirt"
    },
    {
      "x": 1,
      "y": 2,
      "z": -5,
      "name": "Soil_Dirt"
    },
    {
      "x": 1,
      "y": 3,
      "z": -5,
      "name": "Soil_Dirt"
    },
    {
      "x": 1,
      "y": 4,
      "z": -5,
      "name": "Soil_Dirt"
    },
    {
      "x": 1,
      "y": 5,
      "z": -5,
      "name": "Soil_Leaves"
    },
    {
      "x": 1,
      "y": 19,
      "z": -5,
      "name": "Plant_Leaves_Oak"
    },
    {
      "x": 1,
      "y": 20,
      "z": -5,
      "name": "Plant_Leaves_Oak"
    },
    {
      "x": 1,
      "y": 0,
      "z": -4,
      "name": "Soil_Dirt"
    },
    {
      "x": 1,
      "y": 1,
      "z": -4,
      "name": "Soil_Dirt"
    },
    {
      "x": 1,
      "y": 2,
      "z": -4,
      "name": "Soil_Dirt"
    },
    {
      "x": 1,
      "y": 3,
      "z": -4,
      "name": "Soil_Dirt"
    },
    {
      "x": 1,
      "y": 4,
      "z": -4,
      "name": "Soil_Dirt"
    },
    {
      "x": 1,
      "y": 5,
      "z": -4,
      "name": "Soil_Leaves"
    },
    {
      "x": 1,
      "y": 6,
      "z": -4,
      "name": "Empty"
    },
    {
      "x": 1,
      "y": 17,
      "z": -4,
      "name": "Plant_Leaves_Oak"
    },
    {
      "x": 1,
      "y": 18,
      "z": -4,
      "name": "Plant_Leaves_Oak"
    },
    {
      "x": 1,
      "y": 20,
      "z": -4,
      "name": "Plant_Leaves_Oak"
    },
    {
      "x": 1,
      "y": 4,
      "z": -3,
      "name": "Soil_Dirt"
    },
    {
      "x": 1,
      "y": 5,
      "z": -3,
      "name": "Soil_Grass_Deep"
    },
    {
      "x": 1,
      "y": 18,
      "z": -3,
      "name": "Plant_Leaves_Oak"
    },
    {
      "x": 1,
      "y": 4,
      "z": -2,
      "name": "Soil_Dirt"
    },
    {
      "x": 1,
      "y": 5,
      "z": -2,
      "name": "Soil_Grass_Deep"
    },
    {
      "x": 1,
      "y": 17,
      "z": -2,
      "name": "Plant_Leaves_Oak"
    },
    {
      "x": 1,
      "y": 18,
      "z": -2,
      "name": "Plant_Leaves_Oak"
    },
    {
      "x": 1,
      "y": 4,
      "z": -1,
      "name": "Soil_Dirt"
    },
    {
      "x": 1,
      "y": 5,
      "z": -1,
      "name": "Soil_Dirt"
    },
    {
      "x": 1,
      "y": 17,
      "z": -1,
      "name": "Plant_Leaves_Oak"
    },
    {
      "x": 1,
      "y": 4,
      "z": 0,
      "name": "Soil_Dirt"
    },
    {
      "x": 1,
      "y": 5,
      "z": 0,
      "name": "Soil_Dirt_Tilled",
      "components": {
        "Components": {
          "PlacedByInteraction": {
            "WhoPlacedUuid": {
              "$binary": "9ZjLHQsUQaC73VAqONe4MQ==",
              "$type": "04"
            }
          },
          "TilledSoil": {
            "Version": 1,
            "DecayTime": "0001-01-02T18:33:42Z"
          }
        }
      }
    },
    {
      "x": 1,
      "y": 4,
      "z": 1,
      "name": "Soil_Dirt"
    },
    {
      "x": 1,
      "y": 5,
      "z": 1,
      "name": "Soil_Dirt_Tilled",
      "components": {
        "Components": {
          "PlacedByInteraction": {
            "WhoPlacedUuid": {
              "$binary": "9ZjLHQsUQaC73VAqONe4MQ==",
              "$type": "04"
            }
          },
          "TilledSoil": {
            "Version": 1,
            "DecayTime": "0001-01-02T17:59:51Z"
          }
        }
      }
    },
    {
      "x": 1,
      "y": 6,
      "z": 1,
      "name": "*Plant_Crop_Cauliflower_Block_State_Definitions_Stage1",
      "components": {
        "Components": {
          "FarmingBlock": {
            "GrowthProgress": -0.6403809785842896,
            "LastTickGameTime": "0001-01-01T12:00:00Z"
          },
          "PlacedByInteraction": {
            "WhoPlacedUuid": {
              "$binary": "9ZjLHQsUQaC73VAqONe4MQ==",
              "$type": "04"
            }
          }
        }
      }
    },
    {
      "x": 1,
      "y": 4,
      "z": 2,
      "name": "Soil_Dirt"
    },
    {
      "x": 1,
      "y": 5,
      "z": 2,
      "name": "Soil_Dirt_Tilled",
      "components": {
        "Components": {
          "PlacedByInteraction": {
            "WhoPlacedUuid": {
              "$binary": "9ZjLHQsUQaC73VAqONe4MQ==",
              "$type": "04"
            }
          },
          "TilledSoil": {
            "Version": 1,
            "DecayTime": "0001-01-02T22:09:00Z"
          }
        }
      }
    },
    {
      "x": 1,
      "y": 6,
      "z": 2,
      "name": "*Plant_Crop_Cauliflower_Block_State_Definitions_Stage2",
      "components": {
        "Components": {
          "FarmingBlock": {
            "GrowthProgress": -0.6369524002075195,
            "LastTickGameTime": "0001-01-01T12:00:00Z"
          },
          "PlacedByInteraction": {
            "WhoPlacedUuid": {
              "$binary": "9ZjLHQsUQaC73VAqONe4MQ==",
              "$type": "04"
            }
          }
        }
      }
    },
    {
      "x": 1,
      "y": 4,
      "z": 3,
      "name": "Soil_Dirt"
    },
    {
      "x": 1,
      "y": 5,
      "z": 3,
      "name": "Soil_Dirt"
    },
    {
      "x": 1,
      "y": 4,
      "z": 4,
      "name": "Soil_Dirt"
    },
    {
      "x": 1,
      "y": 5,
      "z": 4,
      "name": "Soil_Pathway"
    },
    {
      "x": 2,
      "y": 16,
      "z": -16,
      "name": "Plant_Leaves_Oak"
    },
    {
      "x": 2,
      "y": 17,
      "z": -16,
      "name": "Plant_Leaves_Oak"
    },
    {
      "x": 2,
      "y": 16,
      "z": -15,
      "name": "Plant_Leaves_Oak"
    },
    {
      "x": 2,
      "y": 17,
      "z": -15,
      "name": "Plant_Leaves_Oak"
    },
    {
      "x": 2,
      "y": 18,
      "z": -15,
      "name": "Plant_Leaves_Oak"
    },
    {
      "x": 2,
      "y": 17,
      "z": -14,
      "name": "Plant_Leaves_Oak"
    },
    {
      "x": 2,
      "y": 18,
      "z": -14,
      "name": "Plant_Leaves_Oak"
    },
    {
      "x": 2,
      "y": 19,
      "z": -14,
      "name": "Plant_Leaves_Oak"
    },
    {
      "x": 2,
      "y": 5,
      "z": -13,
      "name": "Soil_Pathway"
    },
    {
      "x": 2,
      "y": 17,
      "z": -13,
      "name": "Plant_Leaves_Oak"
    },
    {
      "x": 2,
      "y": 18,
      "z": -13,
      "name": "Wood_Oak_Trunk_Full"
    },
    {
      "x": 2,
      "y": 19,
      "z": -13,
      "name": "Plant_Leaves_Oak"
    },
    {
      "x": 2,
      "y": 20,
      "z": -13,
      "name": "Plant_Leaves_Oak"
    },
    {
      "x": 2,
      "y": 0,
      "z": -12,
      "name": "Soil_Dirt"
    },
    {
      "x": 2,
      "y": 1,
      "z": -12,
      "name": "Soil_Dirt"
    },
    {
      "x": 2,
      "y": 2,
      "z": -12,
      "name": "Soil_Dirt"
    },
    {
      "x": 2,
      "y": 3,
      "z": -12,
      "name": "Soil_Dirt"
    },
    {
      "x": 2,
      "y": 4,
      "z": -12,
      "name": "Soil_Dirt"
    },
    {
      "x": 2,
      "y": 5,
      "z": -12,
      "name": "Soil_Grass_Deep"
    },
    {
      "x": 2,
      "y": 15,
      "z": -12,
      "name": "Wood_Oak_Trunk_Full"
    },
    {
      "x": 2,
      "y": 17,
      "z": -12,
      "name": "Plant_Leaves_Oak"
    },
    {
      "x": 2,
      "y": 19,
      "z": -12,
      "name": "Plant_Leaves_Oak"
    },
    {
      "x": 2,
      "y": 20,
      "z": -12,
      "name": "Plant_Leaves_Oak"
    },
    {
      "x": 2,
      "y": 0,
      "z": -11,
      "name": "Soil_Dirt"
    },
    {
      "x": 2,
      "y": 1,
      "z": -11,
      "name": "Soil_Dirt"
    },
    {
      "x": 2,
      "y": 2,
      "z": -11,
      "name": "Soil_Dirt"
    },
    {
      "x": 2,
      "y": 3,
      "z": -11,
      "name": "Soil_Dirt"
    },
    {
      "x": 2,
      "y": 4,
      "z": -11,
      "name": "Soil_Dirt"
    },
    {
      "x": 2,
      "y": 5,
      "z": -11,
      "name": "Soil_Grass_Deep"
    },
    {
      "x": 2,
      "y": 14,
      "z": -11,
      "name": "Wood_Oak_Trunk_Full"
    },
    {
      "x": 2,
      "y": 15,
      "z": -11,
      "name": "Wood_Oak_Trunk_Full"
    },
    {
      "x": 2,
      "y": 18,
      "z": -11,
      "name": "Plant_Leaves_Oak"
    },
    {
      "x": 2,
      "y": 19,
      "z": -11,
      "name": "Plant_Leaves_Oak"
    },
    {
      "x": 2,
      "y": 20,
      "z": -11,
      "name": "Plant_Leaves_Oak"
    },
    {
      "x": 2,
      "y": 0,
      "z": -10,
      "name": "Soil_Dirt"
    },
    {
      "x": 2,
      "y": 1,
      "z": -10,
      "name": "Soil_Dirt"
    },
    {
      "x": 2,
      "y": 2,
      "z": -10,
      "name": "Soil_Dirt"
    },
    {
      "x": 2,
      "y": 3,
      "z": -10,
      "name": "Soil_Dirt"
    },
    {
      "x": 2,
      "y": 4,
      "z": -10,
      "name": "Wood_Oak_Trunk_Full"
    },
    {
      "x": 2,
      "y": 5,
      "z": -10,
      "name": "Wood_Oak_Trunk_Full"
    },
    {
      "x": 2,
      "y": 6,
      "z": -10,
      "name": "Wood_Oak_Trunk_Full"
    },
    {
      "x": 2,
      "y": 7,
      "z": -10,
      "name": "Wood_Oak_Trunk_Full"
    },
    {
      "x": 2,
      "y": 8,
      "z": -10,
      "name": "Wood_Oak_Trunk_Full"
    },
    {
      "x": 2,
      "y": 14,
      "z": -10,
      "name": "Wood_Oak_Trunk_Full"
    },
    {
      "x": 2,
      "y": 15,
      "z": -10,
      "name": "Wood_Oak_Trunk_Full"
    },
    {
      "x": 2,
      "y": 18,
      "z": -10,
      "name": "Plant_Leaves_Oak"
    },
    {
      "x": 2,
      "y": 19,
      "z": -10,
      "name": "Plant_Leaves_Oak"
    },
    {
      "x": 2,
      "y": 20,
      "z": -10,
      "name": "Plant_Leaves_Oak"
    },
    {
      "x": 2,
      "y": 21,
      "z": -10,
      "name": "Plant_Leaves_Oak"
    },
    {
      "x": 2,
      "y": 0,
      "z": -9,
      "name": "Soil_Dirt"
    },
    {
      "x": 2,
      "y": 1,
      "z": -9,
      "name": "Soil_Dirt"
    },
    {
      "x": 2,
      "y": 2,
      "z": -9,
      "name": "Soil_Dirt"
    },
    {
      "x": 2,
      "y": 3,
      "z": -9,
      "name": "Soil_Dirt"
    },
    {
      "x": 2,
      "y": 4,
      "z": -9,
      "name": "Soil_Dirt"
    },
    {
      "x": 2,
      "y": 5,
      "z": -9,
      "name": "Soil_Grass_Deep"
    },
    {
      "x": 2,
      "y": 6,
      "z": -9,
      "name": "Plant_Crop_Mushroom_Common_Brown",
      "components": {
        "Components": {
          "FarmingBlock": {
            "LastTickGameTime": "0001-01-01T12:00:00Z"
          }
        }
      }
    },
    {
      "x": 2,
      "y": 7,
      "z": -9,
      "name": "Furniture_Kweebec_Painting"
    },
    {
      "x": 2,
      "y": 8,
      "z": -9,
      "name": "Plant_Vine"
    },
    {
      "x": 2,
      "y": 9,
      "z": -9,
      "name": "Wood_Oak_Trunk_Full"
    },
    {
      "x": 2,
      "y": 10,
      "z": -9,
      "name": "Wood_Oak_Trunk_Full"
    },
    {
      "x": 2,
      "y": 11,
      "z": -9,
      "name": "Wood_Oak_Trunk_Full"
    },
    {
      "x": 2,
      "y": 12,
      "z": -9,
      "name": "Wood_Oak_Trunk_Full"
    },
    {
      "x": 2,
      "y": 13,
      "z": -9,
      "name": "Wood_Oak_Trunk_Full"
    },
    {
      "x": 2,
      "y": 14,
      "z": -9,
      "name": "Wood_Oak_Trunk_Full"
    },
    {
      "x": 2,
      "y": 15,
      "z": -9,
      "name": "Wood_Oak_Trunk_Full"
    },
    {
      "x": 2,
      "y": 20,
      "z": -9,
      "name": "Plant_Leaves_Oak"
    },
    {
      "x": 2,
      "y": 21,
      "z": -9,
      "name": "Plant_Leaves_Oak"
    },
    {
      "x": 2,
      "y": 0,
      "z": -8,
      "name": "Soil_Dirt"
    },
    {
      "x": 2,
      "y": 1,
      "z": -8,
      "name": "Soil_Dirt"
    },
    {
      "x": 2,
      "y": 2,
      "z": -8,
      "name": "Soil_Dirt"
    },
    {
      "x": 2,
      "y": 3,
      "z": -8,
      "name": "Soil_Dirt"
    },
    {
      "x": 2,
      "y": 4,
      "z": -8,
      "name": "Soil_Dirt"
    },
    {
      "x": 2,
      "y": 5,
      "z": -8,
      "name": "Soil_Grass_Deep"
    },
    {
      "x": 2,
      "y": 8,
      "z": -8,
      "name": "Plant_Vine_Wall",
      "rotation": 1
    },
    {
      "x": 2,
      "y": 9,
      "z": -8,
      "name": "Wood_Oak_Trunk_Full"
    },
    {
      "x": 2,
      "y": 10,
      "z": -8,
      "name": "Wood_Oak_Trunk_Full"
    },
    {
      "x": 2,
      "y": 11,
      "z": -8,
      "name": "Wood_Oak_Trunk_Full"
    },
    {
      "x": 2,
      "y": 12,
      "z": -8,
      "name": "Wood_Oak_Trunk_Full"
    },
    {
      "x": 2,
      "y": 13,
      "z": -8,
      "name": "Wood_Oak_Trunk_Full"
    },
    {
      "x": 2,
      "y": 14,
      "z": -8,
      "name": "Wood_Oak_Trunk_Full"
    },
    {
      "x": 2,
      "y": 21,
      "z": -8,
      "name": "Plant_Leaves_Oak"
    },
    {
      "x": 2,
      "y": 0,
      "z": -7,
      "name": "Soil_Dirt"
    },
    {
      "x": 2,
      "y": 1,
      "z": -7,
      "name": "Soil_Dirt"
    },
    {
      "x": 2,
      "y": 2,
      "z": -7,
      "name": "Soil_Dirt"
    },
    {
      "x": 2,
      "y": 3,
      "z": -7,
      "name": "Soil_Dirt"
    },
    {
      "x": 2,
      "y": 4,
      "z": -7,
      "name": "Soil_Dirt"
    },
    {
      "x": 2,
      "y": 5,
      "z": -7,
      "name": "Soil_Pathway"
    },
    {
      "x": 2,
      "y": 7,
      "z": -7,
      "name": "Plant_Vine_Wall",
      "rotation": 1
    },
    {
      "x": 2,
      "y": 8,
      "z": -7,
      "name": "Plant_Vine",
      "rotation": 1
    },
    {
      "x": 2,
      "y": 9,
      "z": -7,
      "name": "Wood_Oak_Trunk_Full"
    },
    {
      "x": 2,
      "y": 10,
      "z": -7,
      "name": "Wood_Oak_Trunk_Full"
    },
    {
      "x": 2,
      "y": 11,
      "z": -7,
      "name": "Wood_Oak_Trunk_Full"
    },
    {
      "x": 2,
      "y": 17,
      "z": -7,
      "name": "Wood_Oak_Trunk_Full"
    },
    {
      "x": 2,
      "y": 20,
      "z": -7,
      "name": "Plant_Leaves_Oak"
    },
    {
      "x": 2,
      "y": 21,
      "z": -7,
      "name": "Plant_Leaves_Oak"
    },
    {
      "x": 2,
      "y": 0,
      "z": -6,
      "name": "Soil_Dirt"
    },
    {
      "x": 2,
      "y": 1,
      "z": -6,
      "name": "Soil_Dirt"
    },
    {
      "x": 2,
      "y": 2,
      "z": -6,
      "name": "Soil_Dirt"
    },
    {
      "x": 2,
      "y": 3,
      "z": -6,
      "name": "Wood_Oak_Trunk_Full"
    },
    {
      "x": 2,
      "y": 4,
      "z": -6,
      "name": "Wood_Oak_Trunk_Full"
    },
    {
      "x": 2,
      "y": 5,
      "z": -6,
      "name": "Soil_Pathway"
    },
    {
      "x": 2,
      "y": 6,
      "z": -6,
      "name": "Furniture_Kweebec_Bed",
      "components": {
        "Components": {
          "RespawnBlock": {}
        }
      },
      "rotation": 1
    },
    {
      "x": 2,
      "y": 7,
      "z": -6,
      "name": "Furniture_Kweebec_Bed",
      "components": {
        "Components": {
          "RespawnBlock": {}
        }
      },
      "filler": 1024,
      "rotation": 1
    },
    {
      "x": 2,
      "y": 8,
      "z": -6,
      "name": "Plant_Seeds_Pine"
    },
    {
      "x": 2,
      "y": 9,
      "z": -6,
      "name": "Wood_Oak_Trunk_Full"
    },
    {
      "x": 2,
      "y": 10,
      "z": -6,
      "name": "Wood_Oak_Trunk_Full"
    },
    {
      "x": 2,
      "y": 17,
      "z": -6,
      "name": "Wood_Oak_Trunk_Full"
    },
    {
      "x": 2,
      "y": 19,
      "z": -6,
      "name": "Plant_Leaves_Oak"
    },
    {
      "x": 2,
      "y": 20,
      "z": -6,
      "name": "Plant_Leaves_Oak"
    },
    {
      "x": 2,
      "y": 21,
      "z": -6,
      "name": "Plant_Leaves_Oak"
    },
    {
      "x": 2,
      "y": 0,
      "z": -5,
      "name": "Wood_Oak_Trunk_Full"
    },
    {
      "x": 2,
      "y": 1,
      "z": -5,
      "name": "Wood_Oak_Trunk_Full"
    },
    {
      "x": 2,
      "y": 2,
      "z": -5,
      "name": "Soil_Dirt"
    },
    {
      "x": 2,
      "y": 3,
      "z": -5,
      "name": "Soil_Dirt"
    },
    {
      "x": 2,
      "y": 4,
      "z": -5,
      "name": "Soil_Dirt"
    },
    {
      "x": 2,
      "y": 5,
      "z": -5,
      "name": "Wood_Oak_Trunk_Full"
    },
    {
      "x": 2,
      "y": 6,
      "z": -5,
      "name": "Wood_Oak_Trunk_Full"
    },
    {
      "x": 2,
      "y": 7,
      "z": -5,
      "name": "Wood_Oak_Trunk_Full"
    },
    {
      "x": 2,
      "y": 8,
      "z": -5,
      "name": "Wood_Oak_Trunk_Full"
    },
    {
      "x": 2,
      "y": 17,
      "z": -5,
      "name": "Wood_Oak_Trunk_Full"
    },
    {
      "x": 2,
      "y": 19,
      "z": -5,
      "name": "Plant_Leaves_Oak"
    },
    {
      "x": 2,
      "y": 20,
      "z": -5,
      "name": "Plant_Leaves_Oak"
    },
    {
      "x": 2,
      "y": 0,
      "z": -4,
      "name": "Soil_Dirt"
    },
    {
      "x": 2,
      "y": 1,
      "z": -4,
      "name": "Soil_Dirt"
    },
    {
      "x": 2,
      "y": 2,
      "z": -4,
      "name": "Soil_Dirt"
    },
    {
      "x": 2,
      "y": 3,
      "z": -4,
      "name": "Soil_Dirt"
    },
    {
      "x": 2,
      "y": 4,
      "z": -4,
      "name": "Soil_Dirt"
    },
    {
      "x": 2,
      "y": 5,
      "z": -4,
      "name": "Soil_Grass_Deep"
    },
    {
      "x": 2,
      "y": 4,
      "z": -3,
      "name": "Soil_Dirt"
    },
    {
      "x": 2,
      "y": 5,
      "z": -3,
      "name": "Soil_Grass_Deep"
    },
    {
      "x": 2,
      "y": 18,
      "z": -3,
      "name": "Plant_Leaves_Oak"
    },
    {
      "x": 2,
      "y": 19,
      "z": -3,
      "name": "Plant_Leaves_Oak"
    },
    {
      "x": 2,
      "y": 4,
      "z": -2,
      "name": "Soil_Dirt"
    },
    {
      "x": 2,
      "y": 5,
      "z": -2,
      "name": "Soil_Grass_Deep"
    },
    {
      "x": 2,
      "y": 17,
      "z": -2,
      "name": "Plant_Leaves_Oak"
    },
    {
      "x": 2,
      "y": 18,
      "z": -2,
      "name": "Plant_Leaves_Oak"
    },
    {
      "x": 2,
      "y": 4,
      "z": -1,
      "name": "Soil_Dirt"
    },
    {
      "x": 2,
      "y": 5,
      "z": -1,
      "name": "Soil_Dirt"
    },
    {
      "x": 2,
      "y": 16,
      "z": -1,
      "name": "Plant_Leaves_Oak"
    },
    {
      "x": 2,
      "y": 17,
      "z": -1,
      "name": "Plant_Leaves_Oak"
    },
    {
      "x": 2,
      "y": 18,
      "z": -1,
      "name": "Plant_Leaves_Oak"
    },
    {
      "x": 2,
      "y": 4,
      "z": 0,
      "name": "Soil_Dirt"
    },
    {
      "x": 2,
      "y": 5,
      "z": 0,
      "name": "Soil_Dirt"
    },
    {
      "x": 2,
      "y": 16,
      "z": 0,
      "name": "Plant_Leaves_Oak"
    },
    {
      "x": 2,
      "y": 17,
      "z": 0,
      "name": "Plant_Leaves_Oak"
    },
    {
      "x": 2,
      "y": 4,
      "z": 1,
      "name": "Soil_Dirt"
    },
    {
      "x": 2,
      "y": 5,
      "z": 1,
      "name": "Soil_Dirt_Tilled",
      "components": {
        "Components": {
          "PlacedByInteraction": {
            "WhoPlacedUuid": {
              "$binary": "9ZjLHQsUQaC73VAqONe4MQ==",
              "$type": "04"
            }
          },
          "TilledSoil": {
            "Version": 1,
            "DecayTime": "0001-01-02T23:33:29Z"
          }
        }
      }
    },
    {
      "x": 2,
      "y": 6,
      "z": 1,
      "name": "*Plant_Crop_Cauliflower_Block_State_Definitions_Stage2",
      "components": {
        "Components": {
          "FarmingBlock": {
            "GrowthProgress": -0.6387618780136108,
            "LastTickGameTime": "0001-01-01T12:00:00Z"
          },
          "PlacedByInteraction": {
            "WhoPlacedUuid": {
              "$binary": "9ZjLHQsUQaC73VAqONe4MQ==",
              "$type": "04"
            }
          }
        }
      }
    },
    {
      "x": 2,
      "y": 5,
      "z": 2,
      "name": "Soil_Dirt_Tilled",
      "components": {
        "Components": {
          "PlacedByInteraction": {
            "WhoPlacedUuid": {
              "$binary": "9ZjLHQsUQaC73VAqONe4MQ==",
              "$type": "04"
            }
          },
          "TilledSoil": {
            "Version": 1,
            "DecayTime": "0001-01-02T20:55:40Z"
          }
        }
      }
    },
    {
      "x": 2,
      "y": 5,
      "z": 3,
      "name": "Soil_Dirt"
    },
    {
      "x": 2,
      "y": 5,
      "z": 4,
      "name": "Soil_Pathway"
    },
    {
      "x": 3,
      "y": 16,
      "z": -16,
      "name": "Plant_Leaves_Oak"
    },
    {
      "x": 3,
      "y": 17,
      "z": -16,
      "name": "Plant_Leaves_Oak"
    },
    {
      "x": 3,
      "y": 16,
      "z": -15,
      "name": "Plant_Leaves_Oak"
    },
    {
      "x": 3,
      "y": 17,
      "z": -15,
      "name": "Plant_Leaves_Oak"
    },
    {
      "x": 3,
      "y": 18,
      "z": -15,
      "name": "Plant_Leaves_Oak"
    },
    {
      "x": 3,
      "y": 5,
      "z": -14,
      "name": "Soil_Grass_Deep"
    },
    {
      "x": 3,
      "y": 16,
      "z": -14,
      "name": "Wood_Oak_Trunk_Full"
    },
    {
      "x": 3,
      "y": 17,
      "z": -14,
      "name": "Plant_Leaves_Oak"
    },
    {
      "x": 3,
      "y": 18,
      "z": -14,
      "name": "Plant_Leaves_Oak"
    },
    {
      "x": 3,
      "y": 19,
      "z": -14,
      "name": "Plant_Leaves_Oak"
    },
    {
      "x": 3,
      "y": 5,
      "z": -13,
      "name": "Soil_Grass_Deep"
    },
    {
      "x": 3,
      "y": 15,
      "z": -13,
      "name": "Wood_Oak_Trunk_Full"
    },
    {
      "x": 3,
      "y": 16,
      "z": -13,
      "name": "Wood_Oak_Trunk_Full"
    },
    {
      "x": 3,
      "y": 17,
      "z": -13,
      "name": "Plant_Leaves_Oak"
    },
    {
      "x": 3,
      "y": 18,
      "z": -13,
      "name": "Wood_Oak_Trunk_Full"
    },
    {
      "x": 3,
      "y": 19,
      "z": -13,
      "name": "Plant_Leaves_Oak"
    },
    {
      "x": 3,
      "y": 20,
      "z": -13,
      "name": "Plant_Leaves_Oak"
    },
    {
      "x": 3,
      "y": 0,
      "z": -12,
      "name": "Soil_Dirt"
    },
    {
      "x": 3,
      "y": 1,
      "z": -12,
      "name": "Soil_Dirt"
    },
    {
      "x": 3,
      "y": 2,
      "z": -12,
      "name": "Soil_Dirt"
    },
    {
      "x": 3,
      "y": 3,
      "z": -12,
      "name": "Soil_Dirt"
    },
    {
      "x": 3,
      "y": 4,
      "z": -12,
      "name": "Soil_Dirt"
    },
    {
      "x": 3,
      "y": 5,
      "z": -12,
      "name": "Soil_Grass_Deep"
    },
    {
      "x": 3,
      "y": 15,
      "z": -12,
      "name": "Wood_Oak_Trunk_Full"
    },
    {
      "x": 3,
      "y": 16,
      "z": -12,
      "name": "Plant_Leaves_Oak"
    },
    {
      "x": 3,
      "y": 17,
      "z": -12,
      "name": "Plant_Leaves_Oak"
    },
    {
      "x": 3,
      "y": 18,
      "z": -12,
      "name": "Wood_Oak_Trunk_Full"
    },
    {
      "x": 3,
      "y": 19,
      "z": -12,
      "name": "Plant_Leaves_Oak"
    },
    {
      "x": 3,
      "y": 20,
      "z": -12,
      "name": "Plant_Leaves_Oak"
    },
    {
      "x": 3,
      "y": 21,
      "z": -12,
      "name": "Plant_Leaves_Oak"
    },
    {
      "x": 3,
      "y": 0,
      "z": -11,
      "name": "Soil_Dirt"
    },
    {
      "x": 3,
      "y": 1,
      "z": -11,
      "name": "Soil_Dirt"
    },
    {
      "x": 3,
      "y": 2,
      "z": -11,
      "name": "Soil_Dirt"
    },
    {
      "x": 3,
      "y": 3,
      "z": -11,
      "name": "Soil_Dirt"
    },
    {
      "x": 3,
      "y": 4,
      "z": -11,
      "name": "Soil_Dirt"
    },
    {
      "x": 3,
      "y": 5,
      "z": -11,
      "name": "Wood_Oak_Trunk_Full"
    },
    {
      "x": 3,
      "y": 6,
      "z": -11,
      "name": "Wood_Oak_Trunk_Full"
    },
    {
      "x": 3,
      "y": 7,
      "z": -11,
      "name": "Furniture_Kweebec_Window"
    },
    {
      "x": 3,
      "y": 18,
      "z": -11,
      "name": "Wood_Oak_Trunk_Full"
    },
    {
      "x": 3,
      "y": 19,
      "z": -11,
      "name": "Plant_Leaves_Oak"
    },
    {
      "x": 3,
      "y": 20,
      "z": -11,
      "name": "Plant_Leaves_Oak"
    },
    {
      "x": 3,
      "y": 21,
      "z": -11,
      "name": "Plant_Leaves_Oak"
    },
    {
      "x": 3,
      "y": 0,
      "z": -10,
      "name": "Soil_Dirt"
    },
    {
      "x": 3,
      "y": 1,
      "z": -10,
      "name": "Soil_Dirt"
    },
    {
      "x": 3,
      "y": 2,
      "z": -10,
      "name": "Soil_Dirt"
    },
    {
      "x": 3,
      "y": 3,
      "z": -10,
      "name": "Wood_Oak_Trunk_Full"
    },
    {
      "x": 3,
      "y": 4,
      "z": -10,
      "name": "Wood_Oak_Trunk_Full"
    },
    {
      "x": 3,
      "y": 5,
      "z": -10,
      "name": "Soil_Pathway"
    },
    {
      "x": 3,
      "y": 6,
      "z": -10,
      "name": "Furniture_Kweebec_Wardrobe",
      "filler": 31
    },
    {
      "x": 3,
      "y": 7,
      "z": -10,
      "name": "Furniture_Kweebec_Wardrobe",
      "filler": 1055
    },
    {
      "x": 3,
      "y": 8,
      "z": -10,
      "name": "Wood_Oak_Trunk_Full"
    },
    {
      "x": 3,
      "y": 9,
      "z": -10,
      "name": "Wood_Oak_Trunk_Full"
    },
    {
      "x": 3,
      "y": 13,
      "z": -10,
      "name": "Wood_Oak_Trunk_Full"
    },
    {
      "x": 3,
      "y": 14,
      "z": -10,
      "name": "Wood_Oak_Trunk_Full"
    },
    {
      "x": 3,
      "y": 19,
      "z": -10,
      "name": "Plant_Leaves_Oak"
    },
    {
      "x": 3,
      "y": 21,
      "z": -10,
      "name": "Plant_Leaves_Oak"
    },
    {
      "x": 3,
      "y": 0,
      "z": -9,
      "name": "Soil_Dirt"
    },
    {
      "x": 3,
      "y": 1,
      "z": -9,
      "name": "Soil_Dirt"
    },
    {
      "x": 3,
      "y": 2,
      "z": -9,
      "name": "Soil_Dirt"
    },
    {
      "x": 3,
      "y": 3,
      "z": -9,
      "name": "Wood_Oak_Trunk_Full"
    },
    {
      "x": 3,
      "y": 4,
      "z": -9,
      "name": "Soil_Pathway"
    },
    {
      "x": 3,
      "y": 5,
      "z": -9,
      "name": "Soil_Pathway"
    },
    {
      "x": 3,
      "y": 9,
      "z": -9,
      "name": "Wood_Oak_Trunk_Full"
    },
    {
      "x": 3,
      "y": 10,
      "z": -9,
      "name": "Wood_Oak_Trunk_Full"
    },
    {
      "x": 3,
      "y": 11,
      "z": -9,
      "name": "Wood_Oak_Trunk_Full"
    },
    {
      "x": 3,
      "y": 12,
      "z": -9,
      "name": "Wood_Oak_Trunk_Full"
    },
    {
      "x": 3,
      "y": 13,
      "z": -9,
      "name": "Wood_Oak_Trunk_Full"
    },
    {
      "x": 3,
      "y": 14,
      "z": -9,
      "name": "Wood_Oak_Trunk_Full"
    },
    {
      "x": 3,
      "y": 19,
      "z": -9,
      "name": "Plant_Leaves_Oak"
    },
    {
      "x": 3,
      "y": 20,
      "z": -9,
      "name": "Plant_Leaves_Oak"
    },
    {
      "x": 3,
      "y": 21,
      "z": -9,
      "name": "Plant_Leaves_Oak"
    },
    {
      "x": 3,
      "y": 22,
      "z": -9,
      "name": "Plant_Leaves_Oak"
    },
    {
      "x": 3,
      "y": 0,
      "z": -8,
      "name": "Soil_Dirt"
    },
    {
      "x": 3,
      "y": 1,
      "z": -8,
      "name": "Soil_Dirt"
    },
    {
      "x": 3,
      "y": 2,
      "z": -8,
      "name": "Soil_Dirt"
    },
    {
      "x": 3,
      "y": 3,
      "z": -8,
      "name": "Soil_Dirt"
    },
    {
      "x": 3,
      "y": 4,
      "z": -8,
      "name": "Soil_Dirt"
    },
    {
      "x": 3,
      "y": 5,
      "z": -8,
      "name": "Soil_Grass_Deep"
    },
    {
      "x": 3,
      "y": 9,
      "z": -8,
      "name": "Wood_Oak_Trunk_Full"
    },
    {
      "x": 3,
      "y": 10,
      "z": -8,
      "name": "Wood_Oak_Trunk_Full"
    },
    {
      "x": 3,
      "y": 11,
      "z": -8,
      "name": "Wood_Oak_Trunk_Full"
    },
    {
      "x": 3,
      "y": 12,
      "z": -8,
      "name": "Wood_Oak_Trunk_Full"
    },
    {
      "x": 3,
      "y": 13,
      "z": -8,
      "name": "Wood_Oak_Trunk_Full"
    },
    {
      "x": 3,
      "y": 14,
      "z": -8,
      "name": "Wood_Oak_Trunk_Full"
    },
    {
      "x": 3,
      "y": 15,
      "z": -8,
      "name": "Wood_Oak_Trunk_Full"
    },
    {
      "x": 3,
      "y": 16,
      "z": -8,
      "name": "Wood_Oak_Trunk_Full"
    },
    {
      "x": 3,
      "y": 17,
      "z": -8,
      "name": "Wood_Oak_Trunk_Full"
    },
    {
      "x": 3,
      "y": 18,
      "z": -8,
      "name": "Wood_Oak_Trunk_Full"
    },
    {
      "x": 3,
      "y": 20,
      "z": -8,
      "name": "Plant_Leaves_Oak"
    },
    {
      "x": 3,
      "y": 21,
      "z": -8,
      "name": "Plant_Leaves_Oak"
    },
    {
      "x": 3,
      "y": 22,
      "z": -8,
      "name": "Plant_Leaves_Oak"
    },
    {
      "x": 3,
      "y": 0,
      "z": -7,
      "name": "Soil_Dirt"
    },
    {
      "x": 3,
      "y": 1,
      "z": -7,
      "name": "Soil_Dirt"
    },
    {
      "x": 3,
      "y": 2,
      "z": -7,
      "name": "Soil_Dirt"
    },
    {
      "x": 3,
      "y": 3,
      "z": -7,
      "name": "Soil_Dirt"
    },
    {
      "x": 3,
      "y": 4,
      "z": -7,
      "name": "Soil_Dirt"
    },
    {
      "x": 3,
      "y": 5,
      "z": -7,
      "name": "Soil_Leaves"
    },
    {
      "x": 3,
      "y": 9,
      "z": -7,
      "name": "Wood_Oak_Trunk_Full"
    },
    {
      "x": 3,
      "y": 10,
      "z": -7,
      "name": "Wood_Oak_Trunk_Full"
    },
    {
      "x": 3,
      "y": 11,
      "z": -7,
      "name": "Wood_Oak_Trunk_Full"
    },
    {
      "x": 3,
      "y": 12,
      "z": -7,
      "name": "Wood_Oak_Trunk_Full"
    },
    {
      "x": 3,
      "y": 15,
      "z": -7,
      "name": "Wood_Oak_Trunk_Full"
    },
    {
      "x": 3,
      "y": 16,
      "z": -7,
      "name": "Wood_Oak_Trunk_Full"
    },
    {
      "x": 3,
      "y": 17,
      "z": -7,
      "name": "Wood_Oak_Trunk_Full"
    },
    {
      "x": 3,
      "y": 20,
      "z": -7,
      "name": "Plant_Leaves_Oak"
    },
    {
      "x": 3,
      "y": 21,
      "z": -7,
      "name": "Plant_Leaves_Oak"
    },
    {
      "x": 3,
      "y": 0,
      "z": -6,
      "name": "Soil_Dirt"
    },
    {
      "x": 3,
      "y": 1,
      "z": -6,
      "name": "Soil_Dirt"
    },
    {
      "x": 3,
      "y": 2,
      "z": -6,
      "name": "Soil_Dirt"
    },
    {
      "x": 3,
      "y": 3,
      "z": -6,
      "name": "Wood_Oak_Trunk_Full"
    },
    {
      "x": 3,
      "y": 4,
      "z": -6,
      "name": "Wood_Oak_Trunk_Full"
    },
    {
      "x": 3,
      "y": 5,
      "z": -6,
      "name": "Soil_Pathway"
    },
    {
      "x": 3,
      "y": 6,
      "z": -6,
      "name": "Furniture_Kweebec_Bed",
      "components": {
        "Components": {
          "RespawnBlock": {}
        }
      },
      "filler": 1,
      "rotation": 1
    },
    {
      "x": 3,
      "y": 7,
      "z": -6,
      "name": "Furniture_Kweebec_Bed",
      "components": {
        "Components": {
          "RespawnBlock": {}
        }
      },
      "filler": 1025,
      "rotation": 1
    },
    {
      "x": 3,
      "y": 9,
      "z": -6,
      "name": "Wood_Oak_Trunk_Full"
    },
    {
      "x": 3,
      "y": 10,
      "z": -6,
      "name": "Wood_Oak_Trunk_Full"
    },
    {
      "x": 3,
      "y": 11,
      "z": -6,
      "name": "Wood_Oak_Trunk_Full"
    },
    {
      "x": 3,
      "y": 19,
      "z": -6,
      "name": "Plant_Leaves_Oak"
    },
    {
      "x": 3,
      "y": 20,
      "z": -6,
      "name": "Plant_Leaves_Oak"
    },
    {
      "x": 3,
      "y": 21,
      "z": -6,
      "name": "Plant_Leaves_Oak"
    },
    {
      "x": 3,
      "y": 22,
      "z": -6,
      "name": "Plant_Leaves_Oak"
    },
    {
      "x": 3,
      "y": 0,
      "z": -5,
      "name": "Soil_Dirt"
    },
    {
      "x": 3,
      "y": 1,
      "z": -5,
      "name": "Wood_Oak_Trunk_Full"
    },
    {
      "x": 3,
      "y": 2,
      "z": -5,
      "name": "Wood_Oak_Trunk_Full"
    },
    {
      "x": 3,
      "y": 3,
      "z": -5,
      "name": "Wood_Oak_Trunk_Full"
    },
    {
      "x": 3,
      "y": 4,
      "z": -5,
      "name": "Soil_Dirt"
    },
    {
      "x": 3,
      "y": 5,
      "z": -5,
      "name": "Wood_Oak_Trunk_Full"
    },
    {
      "x": 3,
      "y": 6,
      "z": -5,
      "name": "Wood_Oak_Trunk_Full"
    },
    {
      "x": 3,
      "y": 7,
      "z": -5,
      "name": "Furniture_Kweebec_Window"
    },
    {
      "x": 3,
      "y": 8,
      "z": -5,
      "name": "Wood_Oak_Trunk_Full"
    },
    {
      "x": 3,
      "y": 9,
      "z": -5,
      "name": "Wood_Oak_Trunk_Full"
    },
    {
      "x": 3,
      "y": 17,
      "z": -5,
      "name": "Wood_Oak_Trunk_Full"
    },
    {
      "x": 3,
      "y": 18,
      "z": -5,
      "name": "Plant_Leaves_Oak"
    },
    {
      "x": 3,
      "y": 19,
      "z": -5,
      "name": "Plant_Leaves_Oak"
    },
    {
      "x": 3,
      "y": 20,
      "z": -5,
      "name": "Plant_Leaves_Oak"
    },
    {
      "x": 3,
      "y": 21,
      "z": -5,
      "name": "Plant_Leaves_Oak"
    },
    {
      "x": 3,
      "y": 22,
      "z": -5,
      "name": "Plant_Leaves_Oak"
    },
    {
      "x": 3,
      "y": 0,
      "z": -4,
      "name": "Soil_Dirt"
    },
    {
      "x": 3,
      "y": 1,
      "z": -4,
      "name": "Soil_Dirt"
    },
    {
      "x": 3,
      "y": 2,
      "z": -4,
      "name": "Soil_Dirt"
    },
    {
      "x": 3,
      "y": 3,
      "z": -4,
      "name": "Soil_Dirt"
    },
    {
      "x": 3,
      "y": 4,
      "z": -4,
      "name": "Soil_Dirt"
    },
    {
      "x": 3,
      "y": 5,
      "z": -4,
      "name": "Soil_Grass_Deep"
    },
    {
      "x": 3,
      "y": 17,
      "z": -4,
      "name": "Wood_Oak_Trunk_Full"
    },
    {
      "x": 3,
      "y": 19,
      "z": -4,
      "name": "Plant_Leaves_Oak"
    },
    {
      "x": 3,
      "y": 21,
      "z": -4,
      "name": "Plant_Leaves_Oak"
    },
    {
      "x": 3,
      "y": 4,
      "z": -3,
      "name": "Soil_Dirt"
    },
    {
      "x": 3,
      "y": 5,
      "z": -3,
      "name": "Soil_Leaves"
    },
    {
      "x": 3,
      "y": 18,
      "z": -3,
      "name": "Plant_Leaves_Oak"
    },
    {
      "x": 3,
      "y": 19,
      "z": -3,
      "name": "Plant_Leaves_Oak"
    },
    {
      "x": 3,
      "y": 4,
      "z": -2,
      "name": "Soil_Dirt"
    },
    {
      "x": 3,
      "y": 5,
      "z": -2,
      "name": "Soil_Grass_Deep"
    },
    {
      "x": 3,
      "y": 18,
      "z": -2,
      "name": "Plant_Leaves_Oak"
    },
    {
      "x": 3,
      "y": 19,
      "z": -2,
      "name": "Plant_Leaves_Oak"
    },
    {
      "x": 3,
      "y": 4,
      "z": -1,
      "name": "Soil_Dirt"
    },
    {
      "x": 3,
      "y": 5,
      "z": -1,
      "name": "Soil_Grass_Deep"
    },
    {
      "x": 3,
      "y": 17,
      "z": -1,
      "name": "Plant_Leaves_Oak"
    },
    {
      "x": 3,
      "y": 18,
      "z": -1,
      "name": "Plant_Leaves_Oak"
    },
    {
      "x": 3,
      "y": 19,
      "z": -1,
      "name": "Plant_Leaves_Oak"
    },
    {
      "x": 3,
      "y": 4,
      "z": 0,
      "name": "Soil_Dirt"
    },
    {
      "x": 3,
      "y": 5,
      "z": 0,
      "name": "Soil_Grass_Deep"
    },
    {
      "x": 3,
      "y": 16,
      "z": 0,
      "name": "Plant_Leaves_Oak"
    },
    {
      "x": 3,
      "y": 17,
      "z": 0,
      "name": "Plant_Leaves_Oak"
    },
    {
      "x": 3,
      "y": 18,
      "z": 0,
      "name": "Plant_Leaves_Oak"
    },
    {
      "x": 3,
      "y": 4,
      "z": 1,
      "name": "Soil_Dirt"
    },
    {
      "x": 3,
      "y": 5,
      "z": 1,
      "name": "Soil_Dirt"
    },
    {
      "x": 3,
      "y": 16,
      "z": 1,
      "name": "Plant_Leaves_Oak"
    },
    {
      "x": 3,
      "y": 17,
      "z": 1,
      "name": "Plant_Leaves_Oak"
    },
    {
      "x": 3,
      "y": 5,
      "z": 2,
      "name": "Soil_Dirt"
    },
    {
      "x": 3,
      "y": 5,
      "z": 3,
      "name": "Soil_Pathway"
    },
    {
      "x": 3,
      "y": 5,
      "z": 4,
      "name": "Soil_Pathway"
    },
    {
      "x": 4,
      "y": 17,
      "z": -16,
      "name": "Plant_Leaves_Oak"
    },
    {
      "x": 4,
      "y": 18,
      "z": -16,
      "name": "Plant_Leaves_Oak"
    },
    {
      "x": 4,
      "y": 15,
      "z": -15,
      "name": "Plant_Leaves_Oak"
    },
    {
      "x": 4,
      "y": 16,
      "z": -15,
      "name": "Plant_Leaves_Oak"
    },
    {
      "x": 4,
      "y": 17,
      "z": -15,
      "name": "Plant_Leaves_Oak"
    },
    {
      "x": 4,
      "y": 18,
      "z": -15,
      "name": "Plant_Leaves_Oak"
    },
    {
      "x": 4,
      "y": 5,
      "z": -14,
      "name": "Soil_Grass_Deep"
    },
    {
      "x": 4,
      "y": 15,
      "z": -14,
      "name": "Plant_Leaves_Oak"
    },
    {
      "x": 4,
      "y": 16,
      "z": -14,
      "name": "Plant_Leaves_Oak"
    },
    {
      "x": 4,
      "y": 17,
      "z": -14,
      "name": "Plant_Leaves_Oak"
    },
    {
      "x": 4,
      "y": 18,
      "z": -14,
      "name": "Plant_Leaves_Oak"
    },
    {
      "x": 4,
      "y": 19,
      "z": -14,
      "name": "Plant_Leaves_Oak"
    },
    {
      "x": 4,
      "y": 3,
      "z": -13,
      "name": "Wood_Oak_Trunk_Full"
    },
    {
      "x": 4,
      "y": 4,
      "z": -13,
      "name": "Wood_Oak_Trunk_Full"
    },
    {
      "x": 4,
      "y": 5,
      "z": -13,
      "name": "Soil_Grass_Deep"
    },
    {
      "x": 4,
      "y": 16,
      "z": -13,
      "name": "Plant_Leaves_Oak"
    },
    {
      "x": 4,
      "y": 17,
      "z": -13,
      "name": "Plant_Leaves_Oak"
    },
    {
      "x": 4,
      "y": 18,
      "z": -13,
      "name": "Plant_Leaves_Oak"
    },
    {
      "x": 4,
      "y": 19,
      "z": -13,
      "name": "Plant_Leaves_Oak"
    },
    {
      "x": 4,
      "y": 21,
      "z": -13,
      "name": "Plant_Leaves_Oak"
    },
    {
      "x": 4,
      "y": 0,
      "z": -12,
      "name": "Soil_Dirt"
    },
    {
      "x": 4,
      "y": 1,
      "z": -12,
      "name": "Soil_Dirt"
    },
    {
      "x": 4,
      "y": 2,
      "z": -12,
      "name": "Soil_Dirt"
    },
    {
      "x": 4,
      "y": 3,
      "z": -12,
      "name": "Soil_Dirt"
    },
    {
      "x": 4,
      "y": 4,
      "z": -12,
      "name": "Wood_Oak_Trunk_Full"
    },
    {
      "x": 4,
      "y": 5,
      "z": -12,
      "name": "Wood_Oak_Trunk_Full"
    },
    {
      "x": 4,
      "y": 6,
      "z": -12,
      "name": "Wood_Oak_Trunk_Full"
    },
    {
      "x": 4,
      "y": 7,
      "z": -12,
      "name": "Wood_Oak_Trunk_Full"
    },
    {
      "x": 4,
      "y": 16,
      "z": -12,
      "name": "Plant_Leaves_Oak"
    },
    {
      "x": 4,
      "y": 19,
      "z": -12,
      "name": "Plant_Leaves_Oak"
    },
    {
      "x": 4,
      "y": 20,
      "z": -12,
      "name": "Plant_Leaves_Oak"
    },
    {
      "x": 4,
      "y": 21,
      "z": -12,
      "name": "Plant_Leaves_Oak"
    },
    {
      "x": 4,
      "y": 0,
      "z": -11,
      "name": "Soil_Dirt"
    },
    {
      "x": 4,
      "y": 1,
      "z": -11,
      "name": "Soil_Dirt"
    },
    {
      "x": 4,
      "y": 2,
      "z": -11,
      "name": "Soil_Dirt"
    },
    {
      "x": 4,
      "y": 3,
      "z": -11,
      "name": "Soil_Dirt"
    },
    {
      "x": 4,
      "y": 4,
      "z": -11,
      "name": "Wood_Oak_Trunk_Full"
    },
    {
      "x": 4,
      "y": 5,
      "z": -11,
      "name": "Wood_Oak_Trunk_Full"
    },
    {
      "x": 4,
      "y": 6,
      "z": -11,
      "name": "Wood_Oak_Trunk_Full"
    },
    {
      "x": 4,
      "y": 7,
      "z": -11,
      "name": "Wood_Oak_Trunk_Full"
    },
    {
      "x": 4,
      "y": 8,
      "z": -11,
      "name": "Wood_Oak_Trunk_Full"
    },
    {
      "x": 4,
      "y": 18,
      "z": -11,
      "name": "Wood_Oak_Trunk_Full"
    },
    {
      "x": 4,
      "y": 21,
      "z": -11,
      "name": "Plant_Leaves_Oak"
    },
    {
      "x": 4,
      "y": 22,
      "z": -11,
      "name": "Plant_Leaves_Oak"
    },
    {
      "x": 4,
      "y": 0,
      "z": -10,
      "name": "Soil_Dirt"
    },
    {
      "x": 4,
      "y": 1,
      "z": -10,
      "name": "Soil_Dirt"
    },
    {
      "x": 4,
      "y": 2,
      "z": -10,
      "name": "Soil_Dirt"
    },
    {
      "x": 4,
      "y": 3,
      "z": -10,
      "name": "Wood_Oak_Trunk_Full"
    },
    {
      "x": 4,
      "y": 4,
      "z": -10,
      "name": "Wood_Oak_Trunk_Full"
    },
    {
      "x": 4,
      "y": 5,
      "z": -10,
      "name": "Soil_Pathway"
    },
    {
      "x": 4,
      "y": 6,
      "z": -10,
      "name": "Furniture_Kweebec_Wardrobe"
    },
    {
      "x": 4,
      "y": 7,
      "z": -10,
      "name": "Furniture_Kweebec_Wardrobe",
      "filler": 1024
    },
    {
      "x": 4,
      "y": 9,
      "z": -10,
      "name": "Wood_Oak_Trunk_Full"
    },
    {
      "x": 4,
      "y": 10,
      "z": -10,
      "name": "Wood_Oak_Trunk_Full"
    },
    {
      "x": 4,
      "y": 11,
      "z": -10,
      "name": "Wood_Oak_Trunk_Full"
    },
    {
      "x": 4,
      "y": 16,
      "z": -10,
      "name": "Wood_Oak_Trunk_Full"
    },
    {
      "x": 4,
      "y": 21,
      "z": -10,
      "name": "Plant_Leaves_Oak"
    },
    {
      "x": 4,
      "y": 22,
      "z": -10,
      "name": "Plant_Leaves_Oak"
    },
    {
      "x": 4,
      "y": 0,
      "z": -9,
      "name": "Soil_Dirt"
    },
    {
      "x": 4,
      "y": 1,
      "z": -9,
      "name": "Soil_Dirt"
    },
    {
      "x": 4,
      "y": 2,
      "z": -9,
      "name": "Wood_Oak_Trunk_Full"
    },
    {
      "x": 4,
      "y": 3,
      "z": -9,
      "name": "Wood_Oak_Trunk_Full"
    },
    {
      "x": 4,
      "y": 4,
      "z": -9,
      "name": "Wood_Oak_Trunk_Full"
    },
    {
      "x": 4,
      "y": 5,
      "z": -9,
      "name": "Soil_Pathway"
    },
    {
      "x": 4,
      "y": 9,
      "z": -9,
      "name": "Wood_Oak_Trunk_Full"
    },
    {
      "x": 4,
      "y": 10,
      "z": -9,
      "name": "Wood_Oak_Trunk_Full"
    },
    {
      "x": 4,
      "y": 11,
      "z": -9,
      "name": "Wood_Oak_Trunk_Full"
    },
    {
      "x": 4,
      "y": 12,
      "z": -9,
      "name": "Wood_Oak_Trunk_Full"
    },
    {
      "x": 4,
      "y": 13,
      "z": -9,
      "name": "Wood_Oak_Trunk_Full"
    },
    {
      "x": 4,
      "y": 16,
      "z": -9,
      "name": "Wood_Oak_Trunk_Full"
    },
    {
      "x": 4,
      "y": 20,
      "z": -9,
      "name": "Plant_Leaves_Oak"
    },
    {
      "x": 4,
      "y": 21,
      "z": -9,
      "name": "Plant_Leaves_Oak"
    },
    {
      "x": 4,
      "y": 22,
      "z": -9,
      "name": "Plant_Leaves_Oak"
    },
    {
      "x": 4,
      "y": 0,
      "z": -8,
      "name": "Wood_Oak_Trunk_Full"
    },
    {
      "x": 4,
      "y": 1,
      "z": -8,
      "name": "Wood_Oak_Trunk_Full"
    },
    {
      "x": 4,
      "y": 2,
      "z": -8,
      "name": "Wood_Oak_Trunk_Full"
    },
    {
      "x": 4,
      "y": 4,
      "z": -8,
      "name": "Soil_Pathway"
    },
    {
      "x": 4,
      "y": 5,
      "z": -8,
      "name": "Soil_Leaves"
    },
    {
      "x": 4,
      "y": 9,
      "z": -8,
      "name": "Wood_Oak_Trunk_Full"
    },
    {
      "x": 4,
      "y": 10,
      "z": -8,
      "name": "Wood_Oak_Trunk_Full"
    },
    {
      "x": 4,
      "y": 11,
      "z": -8,
      "name": "Wood_Oak_Trunk_Full"
    },
    {
      "x": 4,
      "y": 12,
      "z": -8,
      "name": "Wood_Oak_Trunk_Full"
    },
    {
      "x": 4,
      "y": 13,
      "z": -8,
      "name": "Wood_Oak_Trunk_Full"
    },
    {
      "x": 4,
      "y": 14,
      "z": -8,
      "name": "Wood_Oak_Trunk_Full"
    },
    {
      "x": 4,
      "y": 15,
      "z": -8,
      "name": "Wood_Oak_Trunk_Full"
    },
    {
      "x": 4,
      "y": 16,
      "z": -8,
      "name": "Wood_Oak_Trunk_Full"
    },
    {
      "x": 4,
      "y": 17,
      "z": -8,
      "name": "Wood_Oak_Trunk_Full"
    },
    {
      "x": 4,
      "y": 18,
      "z": -8,
      "name": "Wood_Oak_Trunk_Full"
    },
    {
      "x": 4,
      "y": 19,
      "z": -8,
      "name": "Wood_Oak_Trunk_Full"
    },
    {
      "x": 4,
      "y": 20,
      "z": -8,
      "name": "Plant_Leaves_Oak"
    },
    {
      "x": 4,
      "y": 21,
      "z": -8,
      "name": "Plant_Leaves_Oak"
    },
    {
      "x": 4,
      "y": 22,
      "z": -8,
      "name": "Plant_Leaves_Oak"
    },
    {
      "x": 4,
      "y": 23,
      "z": -8,
      "name": "Plant_Leaves_Oak"
    },
    {
      "x": 4,
      "y": 0,
      "z": -7,
      "name": "Soil_Dirt"
    },
    {
      "x": 4,
      "y": 1,
      "z": -7,
      "name": "Soil_Dirt"
    },
    {
      "x": 4,
      "y": 2,
      "z": -7,
      "name": "Soil_Dirt"
    },
    {
      "x": 4,
      "y": 3,
      "z": -7,
      "name": "Soil_Dirt"
    },
    {
      "x": 4,
      "y": 4,
      "z": -7,
      "name": "Soil_Dirt"
    },
    {
      "x": 4,
      "y": 5,
      "z": -7,
      "name": "Soil_Leaves"
    },
    {
      "x": 4,
      "y": 6,
      "z": -7,
      "name": "Furniture_Kweebec_Stool"
    },
    {
      "x": 4,
      "y": 9,
      "z": -7,
      "name": "Wood_Oak_Trunk_Full"
    },
    {
      "x": 4,
      "y": 10,
      "z": -7,
      "name": "Wood_Oak_Trunk_Full"
    },
    {
      "x": 4,
      "y": 11,
      "z": -7,
      "name": "Wood_Oak_Trunk_Full"
    },
    {
      "x": 4,
      "y": 20,
      "z": -7,
      "name": "Plant_Leaves_Oak"
    },
    {
      "x": 4,
      "y": 21,
      "z": -7,
      "name": "Plant_Leaves_Oak"
    },
    {
      "x": 4,
      "y": 22,
      "z": -7,
      "name": "Plant_Leaves_Oak"
    },
    {
      "x": 4,
      "y": 0,
      "z": -6,
      "name": "Soil_Dirt"
    },
    {
      "x": 4,
      "y": 1,
      "z": -6,
      "name": "Soil_Dirt"
    },
    {
      "x": 4,
      "y": 2,
      "z": -6,
      "name": "Soil_Dirt"
    },
    {
      "x": 4,
      "y": 3,
      "z": -6,
      "name": "Soil_Dirt"
    },
    {
      "x": 4,
      "y": 4,
      "z": -6,
      "name": "Soil_Dirt"
    },
    {
      "x": 4,
      "y": 5,
      "z": -6,
      "name": "Soil_Leaves"
    },
    {
      "x": 4,
      "y": 6,
      "z": -6,
      "name": "Furniture_Kweebec_Platform"
    },
    {
      "x": 4,
      "y": 7,
      "z": -6,
      "name": "Deco_Nest"
    },
    {
      "x": 4,
      "y": 9,
      "z": -6,
      "name": "Wood_Oak_Trunk_Full"
    },
    {
      "x": 4,
      "y": 10,
      "z": -6,
      "name": "Wood_Oak_Trunk_Full"
    },
    {
      "x": 4,
      "y": 11,
      "z": -6,
      "name": "Wood_Oak_Trunk_Full"
    },
    {
      "x": 4,
      "y": 21,
      "z": -6,
      "name": "Plant_Leaves_Oak"
    },
    {
      "x": 4,
      "y": 22,
      "z": -6,
      "name": "Plant_Leaves_Oak"
    },
    {
      "x": 4,
      "y": 0,
      "z": -5,
      "name": "Soil_Dirt"
    },
    {
      "x": 4,
      "y": 1,
      "z": -5,
      "name": "Soil_Dirt"
    },
    {
      "x": 4,
      "y": 2,
      "z": -5,
      "name": "Soil_Dirt"
    },
    {
      "x": 4,
      "y": 3,
      "z": -5,
      "name": "Soil_Dirt"
    },
    {
      "x": 4,
      "y": 4,
      "z": -5,
      "name": "Wood_Oak_Trunk_Full"
    },
    {
      "x": 4,
      "y": 5,
      "z": -5,
      "name": "Wood_Oak_Trunk_Full"
    },
    {
      "x": 4,
      "y": 6,
      "z": -5,
      "name": "Wood_Oak_Trunk_Full"
    },
    {
      "x": 4,
      "y": 7,
      "z": -5,
      "name": "Wood_Oak_Trunk_Full"
    },
    {
      "x": 4,
      "y": 8,
      "z": -5,
      "name": "Wood_Oak_Trunk_Full"
    },
    {
      "x": 4,
      "y": 9,
      "z": -5,
      "name": "Wood_Oak_Trunk_Full"
    },
    {
      "x": 4,
      "y": 18,
      "z": -5,
      "name": "Plant_Leaves_Oak"
    },
    {
      "x": 4,
      "y": 19,
      "z": -5,
      "name": "Plant_Leaves_Oak"
    },
    {
      "x": 4,
      "y": 20,
      "z": -5,
      "name": "Plant_Leaves_Oak"
    },
    {
      "x": 4,
      "y": 21,
      "z": -5,
      "name": "Plant_Leaves_Oak"
    },
    {
      "x": 4,
      "y": 22,
      "z": -5,
      "name": "Plant_Leaves_Oak"
    },
    {
      "x": 4,
      "y": 0,
      "z": -4,
      "name": "Soil_Dirt"
    },
    {
      "x": 4,
      "y": 1,
      "z": -4,
      "name": "Soil_Dirt"
    },
    {
      "x": 4,
      "y": 2,
      "z": -4,
      "name": "Soil_Dirt"
    },
    {
      "x": 4,
      "y": 3,
      "z": -4,
      "name": "Soil_Dirt"
    },
    {
      "x": 4,
      "y": 4,
      "z": -4,
      "name": "Soil_Dirt"
    },
    {
      "x": 4,
      "y": 5,
      "z": -4,
      "name": "Soil_Grass_Deep"
    },
    {
      "x": 4,
      "y": 17,
      "z": -4,
      "name": "Wood_Oak_Trunk_Full"
    },
    {
      "x": 4,
      "y": 18,
      "z": -4,
      "name": "Wood_Oak_Trunk_Full"
    },
    {
      "x": 4,
      "y": 19,
      "z": -4,
      "name": "Plant_Leaves_Oak"
    },
    {
      "x": 4,
      "y": 20,
      "z": -4,
      "name": "Plant_Leaves_Oak"
    },
    {
      "x": 4,
      "y": 21,
      "z": -4,
      "name": "Plant_Leaves_Oak"
    },
    {
      "x": 4,
      "y": 4,
      "z": -3,
      "name": "Soil_Dirt"
    },
    {
      "x": 4,
      "y": 5,
      "z": -3,
      "name": "Soil_Leaves"
    },
    {
      "x": 4,
      "y": 18,
      "z": -3,
      "name": "Plant_Leaves_Oak"
    },
    {
      "x": 4,
      "y": 19,
      "z": -3,
      "name": "Plant_Leaves_Oak"
    },
    {
      "x": 4,
      "y": 20,
      "z": -3,
      "name": "Plant_Leaves_Oak"
    },
    {
      "x": 4,
      "y": 4,
      "z": -2,
      "name": "Soil_Dirt"
    },
    {
      "x": 4,
      "y": 5,
      "z": -2,
      "name": "Soil_Leaves"
    },
    {
      "x": 4,
      "y": 18,
      "z": -2,
      "name": "Plant_Leaves_Oak"
    },
    {
      "x": 4,
      "y": 19,
      "z": -2,
      "name": "Plant_Leaves_Oak"
    },
    {
      "x": 4,
      "y": 4,
      "z": -1,
      "name": "Soil_Dirt"
    },
    {
      "x": 4,
      "y": 5,
      "z": -1,
      "name": "Soil_Grass_Deep"
    },
    {
      "x": 4,
      "y": 18,
      "z": -1,
      "name": "Plant_Leaves_Oak"
    },
    {
      "x": 4,
      "y": 19,
      "z": -1,
      "name": "Plant_Leaves_Oak"
    },
    {
      "x": 4,
      "y": 4,
      "z": 0,
      "name": "Soil_Dirt"
    },
    {
      "x": 4,
      "y": 5,
      "z": 0,
      "name": "Soil_Grass_Deep"
    },
    {
      "x": 4,
      "y": 16,
      "z": 0,
      "name": "Plant_Leaves_Oak"
    },
    {
      "x": 4,
      "y": 17,
      "z": 0,
      "name": "Plant_Leaves_Oak"
    },
    {
      "x": 4,
      "y": 18,
      "z": 0,
      "name": "Plant_Leaves_Oak"
    },
    {
      "x": 4,
      "y": 19,
      "z": 0,
      "name": "Plant_Leaves_Oak"
    },
    {
      "x": 4,
      "y": 5,
      "z": 1,
      "name": "Soil_Pathway"
    },
    {
      "x": 4,
      "y": 16,
      "z": 1,
      "name": "Plant_Leaves_Oak"
    },
    {
      "x": 4,
      "y": 17,
      "z": 1,
      "name": "Plant_Leaves_Oak"
    },
    {
      "x": 4,
      "y": 5,
      "z": 2,
      "name": "Soil_Pathway"
    },
    {
      "x": 4,
      "y": 5,
      "z": 3,
      "name": "Soil_Pathway"
    },
    {
      "x": 5,
      "y": 17,
      "z": -16,
      "name": "Plant_Leaves_Oak"
    },
    {
      "x": 5,
      "y": 15,
      "z": -15,
      "name": "Plant_Leaves_Oak"
    },
    {
      "x": 5,
      "y": 17,
      "z": -15,
      "name": "Plant_Leaves_Oak"
    },
    {
      "x": 5,
      "y": 18,
      "z": -15,
      "name": "Plant_Leaves_Oak"
    },
    {
      "x": 5,
      "y": 5,
      "z": -14,
      "name": "Soil_Pathway"
    },
    {
      "x": 5,
      "y": 15,
      "z": -14,
      "name": "Plant_Leaves_Oak"
    },
    {
      "x": 5,
      "y": 16,
      "z": -14,
      "name": "Plant_Leaves_Oak"
    },
    {
      "x": 5,
      "y": 19,
      "z": -14,
      "name": "Plant_Leaves_Oak"
    },
    {
      "x": 5,
      "y": 20,
      "z": -14,
      "name": "Plant_Leaves_Oak"
    },
    {
      "x": 5,
      "y": 1,
      "z": -13,
      "name": "Wood_Oak_Trunk_Full"
    },
    {
      "x": 5,
      "y": 2,
      "z": -13,
      "name": "Wood_Oak_Trunk_Full"
    },
    {
      "x": 5,
      "y": 3,
      "z": -13,
      "name": "Wood_Oak_Trunk_Full"
    },
    {
      "x": 5,
      "y": 5,
      "z": -13,
      "name": "Soil_Grass_Deep"
    },
    {
      "x": 5,
      "y": 16,
      "z": -13,
      "name": "Plant_Leaves_Oak"
    },
    {
      "x": 5,
      "y": 19,
      "z": -13,
      "name": "Plant_Leaves_Oak"
    },
    {
      "x": 5,
      "y": 20,
      "z": -13,
      "name": "Plant_Leaves_Oak"
    },
    {
      "x": 5,
      "y": 0,
      "z": -12,
      "name": "Soil_Dirt"
    },
    {
      "x": 5,
      "y": 1,
      "z": -12,
      "name": "Soil_Dirt"
    },
    {
      "x": 5,
      "y": 2,
      "z": -12,
      "name": "Soil_Dirt"
    },
    {
      "x": 5,
      "y": 3,
      "z": -12,
      "name": "Soil_Dirt"
    },
    {
      "x": 5,
      "y": 4,
      "z": -12,
      "name": "Soil_Dirt"
    },
    {
      "x": 5,
      "y": 5,
      "z": -12,
      "name": "Soil_Leaves"
    },
    {
      "x": 5,
      "y": 6,
      "z": -12,
      "name": "Plant_Grass_Lush_Short"
    },
    {
      "x": 5,
      "y": 19,
      "z": -12,
      "name": "Plant_Leaves_Oak"
    },
    {
      "x": 5,
      "y": 0,
      "z": -11,
      "name": "Soil_Dirt"
    },
    {
      "x": 5,
      "y": 1,
      "z": -11,
      "name": "Soil_Dirt"
    },
    {
      "x": 5,
      "y": 2,
      "z": -11,
      "name": "Soil_Dirt"
    },
    {
      "x": 5,
      "y": 3,
      "z": -11,
      "name": "Soil_Dirt"
    },
    {
      "x": 5,
      "y": 4,
      "z": -11,
      "name": "Soil_Dirt"
    },
    {
      "x": 5,
      "y": 5,
      "z": -11,
      "name": "Wood_Oak_Trunk_Full"
    },
    {
      "x": 5,
      "y": 6,
      "z": -11,
      "name": "Wood_Oak_Trunk_Full"
    },
    {
      "x": 5,
      "y": 7,
      "z": -11,
      "name": "Wood_Oak_Trunk_Full"
    },
    {
      "x": 5,
      "y": 8,
      "z": -11,
      "name": "Wood_Oak_Trunk_Full"
    },
    {
      "x": 5,
      "y": 17,
      "z": -11,
      "name": "Wood_Oak_Trunk_Full"
    },
    {
      "x": 5,
      "y": 18,
      "z": -11,
      "name": "Wood_Oak_Trunk_Full"
    },
    {
      "x": 5,
      "y": 21,
      "z": -11,
      "name": "Plant_Leaves_Oak"
    },
    {
      "x": 5,
      "y": 22,
      "z": -11,
      "name": "Plant_Leaves_Oak"
    },
    {
      "x": 5,
      "y": 0,
      "z": -10,
      "name": "Soil_Dirt"
    },
    {
      "x": 5,
      "y": 1,
      "z": -10,
      "name": "Soil_Dirt"
    },
    {
      "x": 5,
      "y": 2,
      "z": -10,
      "name": "Soil_Dirt"
    },
    {
      "x": 5,
      "y": 3,
      "z": -10,
      "name": "Soil_Dirt"
    },
    {
      "x": 5,
      "y": 4,
      "z": -10,
      "name": "Soil_Dirt"
    },
    {
      "x": 5,
      "y": 5,
      "z": -10,
      "name": "Wood_Oak_Trunk_Full"
    },
    {
      "x": 5,
      "y": 6,
      "z": -10,
      "name": "Block_Spawner_Block",
      "components": {
        "Components": {
          "BlockSpawner": {
            "BlockSpawnerId": "Zone1_Kweebec_Tier3"
          }
        }
      }
    },
    {
      "x": 5,
      "y": 7,
      "z": -10,
      "name": "Furniture_Kweebec_Lantern"
    },
    {
      "x": 5,
      "y": 8,
      "z": -10,
      "name": "Deco_Rope"
    },
    {
      "x": 5,
      "y": 9,
      "z": -10,
      "name": "Wood_Oak_Trunk_Full"
    },
    {
      "x": 5,
      "y": 16,
      "z": -10,
      "name": "Wood_Oak_Trunk_Full"
    },
    {
      "x": 5,
      "y": 17,
      "z": -10,
      "name": "Wood_Oak_Trunk_Full"
    },
    {
      "x": 5,
      "y": 20,
      "z": -10,
      "name": "Plant_Leaves_Oak"
    },
    {
      "x": 5,
      "y": 21,
      "z": -10,
      "name": "Plant_Leaves_Oak"
    },
    {
      "x": 5,
      "y": 22,
      "z": -10,
      "name": "Plant_Leaves_Oak"
    },
    {
      "x": 5,
      "y": 23,
      "z": -10,
      "name": "Plant_Leaves_Oak"
    },
    {
      "x": 5,
      "y": 0,
      "z": -9,
      "name": "Soil_Dirt"
    },
    {
      "x": 5,
      "y": 1,
      "z": -9,
      "name": "Soil_Dirt"
    },
    {
      "x": 5,
      "y": 2,
      "z": -9,
      "name": "Soil_Dirt"
    },
    {
      "x": 5,
      "y": 3,
      "z": -9,
      "name": "Soil_Dirt"
    },
    {
      "x": 5,
      "y": 4,
      "z": -9,
      "name": "Soil_Dirt"
    },
    {
      "x": 5,
      "y": 5,
      "z": -9,
      "name": "Soil_Pathway"
    },
    {
      "x": 5,
      "y": 9,
      "z": -9,
      "name": "Wood_Oak_Trunk_Full"
    },
    {
      "x": 5,
      "y": 10,
      "z": -9,
      "name": "Wood_Oak_Trunk_Full"
    },
    {
      "x": 5,
      "y": 20,
      "z": -9,
      "name": "Plant_Leaves_Oak"
    },
    {
      "x": 5,
      "y": 21,
      "z": -9,
      "name": "Plant_Leaves_Oak"
    },
    {
      "x": 5,
      "y": 22,
      "z": -9,
      "name": "Plant_Leaves_Oak"
    },
    {
      "x": 5,
      "y": 23,
      "z": -9,
      "name": "Plant_Leaves_Oak"
    },
    {
      "x": 5,
      "y": 0,
      "z": -8,
      "name": "Soil_Dirt"
    },
    {
      "x": 5,
      "y": 1,
      "z": -8,
      "name": "Soil_Dirt"
    },
    {
      "x": 5,
      "y": 2,
      "z": -8,
      "name": "Soil_Dirt"
    },
    {
      "x": 5,
      "y": 3,
      "z": -8,
      "name": "Soil_Dirt"
    },
    {
      "x": 5,
      "y": 4,
      "z": -8,
      "name": "Soil_Dirt"
    },
    {
      "x": 5,
      "y": 5,
      "z": -8,
      "name": "Soil_Grass_Deep"
    },
    {
      "x": 5,
      "y": 8,
      "z": -8,
      "name": "Plant_Vine",
      "rotation": 3
    },
    {
      "x": 5,
      "y": 9,
      "z": -8,
      "name": "Wood_Oak_Trunk_Full"
    },
    {
      "x": 5,
      "y": 10,
      "z": -8,
      "name": "Wood_Oak_Trunk_Full"
    },
    {
      "x": 5,
      "y": 11,
      "z": -8,
      "name": "Wood_Oak_Trunk_Full"
    },
    {
      "x": 5,
      "y": 14,
      "z": -8,
      "name": "Wood_Oak_Trunk_Full"
    },
    {
      "x": 5,
      "y": 15,
      "z": -8,
      "name": "Wood_Oak_Trunk_Full"
    },
    {
      "x": 5,
      "y": 19,
      "z": -8,
      "name": "Wood_Oak_Trunk_Full"
    },
    {
      "x": 5,
      "y": 20,
      "z": -8,
      "name": "Plant_Leaves_Oak"
    },
    {
      "x": 5,
      "y": 21,
      "z": -8,
      "name": "Plant_Leaves_Oak"
    },
    {
      "x": 5,
      "y": 22,
      "z": -8,
      "name": "Plant_Leaves_Oak"
    },
    {
      "x": 5,
      "y": 23,
      "z": -8,
