{
  "version": 8,
  "blockIdVersion": 11,
  "anchorX": 1,
  "anchorY": 1,
  "anchorZ": -1,
  "blocks": [
    {
      "x": -7,
      "y": 0,
      "z": -2,
      "name": "Rock_Stone"
    },
    {
      "x": -7,
      "y": 1,
      "z": -2,
      "name": "Empty"
    },
    {
      "x": -7,
      "y": 0,
      "z": -1,
      "name": "Rock_Stone"
    },
    {
      "x": -7,
      "y": 1,
      "z": -1,
      "name": "Empty"
    },
    {
      "x": -6,
      "y": 0,
      "z": -4,
      "name": "Rock_Stone"
    },
    {
      "x": -6,
      "y": 1,
      "z": -4,
      "name": "Empty"
    },
    {
      "x": -6,
      "y": 0,
      "z": -3,
      "name": "Rock_Stone"
    },
    {
      "x": -6,
      "y": 1,
      "z": -3,
      "name": "Furniture_Crude_Torch",
      "rotation": 3
    },
    {
      "x": -6,
      "y": 0,
      "z": -2,
      "name": "Rock_Stone"
    },
    {
      "x": -6,
      "y": 1,
      "z": -2,
      "name": "Empty"
    },
    {
      "x": -6,
      "y": 0,
      "z": -1,
      "name": "Rock_Stone"
    },
    {
      "x": -6,
      "y": 1,
      "z": -1,
      "name": "Empty"
    },
    {
      "x": -5,
      "y": 0,
      "z": -6,
      "name": "Rock_Stone"
    },
    {
      "x": -5,
      "y": 1,
      "z": -6,
      "name": "Furniture_Crude_Torch",
      "rotation": 3
    },
    {
      "x": -5,
      "y": 0,
      "z": -5,
      "name": "Rock_Stone"
    },
    {
      "x": -5,
      "y": 1,
      "z": -5,
      "name": "Empty"
    },
    {
      "x": -5,
      "y": 0,
      "z": -4,
      "name": "Rock_Stone"
    },
    {
      "x": -5,
      "y": 1,
      "z": -4,
      "name": "Empty"
    },
    {
      "x": -5,
      "y": 0,
      "z": -3,
      "name": "Rock_Stone"
    },
    {
      "x": -5,
      "y": 1,
      "z": -3,
      "name": "Empty"
    },
    {
      "x": -5,
      "y": 0,
      "z": -2,
      "name": "Rock_Stone"
    },
    {
      "x": -5,
      "y": 1,
      "z": -2,
      "name": "Empty"
    },
    {
      "x": -5,
      "y": 0,
      "z": -1,
      "name": "Rock_Stone"
    },
    {
      "x": -5,
      "y": 1,
      "z": -1,
      "name": "Empty"
    },
    {
      "x": -4,
      "y": 0,
      "z": -7,
      "name": "Rock_Stone"
    },
    {
      "x": -4,
      "y": 1,
      "z": -7,
      "name": "Empty"
    },
    {
      "x": -4,
      "y": 0,
      "z": -6,
      "name": "Rock_Stone"
    },
    {
      "x": -4,
      "y": 1,
      "z": -6,
      "name": "Empty"
    },
    {
      "x": -4,
      "y": 0,
      "z": -5,
      "name": "Rock_Stone"
    },
    {
      "x": -4,
      "y": 1,
      "z": -5,
      "name": "Empty"
    },
    {
      "x": -4,
      "y": 0,
      "z": -4,
      "name": "Rock_Stone"
    },
    {
      "x": -4,
      "y": 1,
      "z": -4,
      "name": "Empty"
    },
    {
      "x": -4,
      "y": 0,
      "z": -3,
      "name": "Rock_Stone"
    },
    {
      "x": -4,
      "y": 1,
      "z": -3,
      "name": "Empty"
    },
    {
      "x": -4,
      "y": 0,
      "z": -2,
      "name": "Rock_Stone"
    },
    {
      "x": -4,
      "y": 1,
      "z": -2,
      "name": "Empty"
    },
    {
      "x": -4,
      "y": 0,
      "z": -1,
      "name": "Rock_Stone"
    },
    {
      "x": -4,
      "y": 1,
      "z": -1,
      "name": "Empty"
    },
    {
      "x": -3,
      "y": 0,
      "z": -7,
      "name": "Rock_Stone"
    },
    {
      "x": -3,
      "y": 1,
      "z": -7,
      "name": "Empty"
    },
    {
      "x": -3,
      "y": 0,
      "z": -6,
      "name": "Rock_Stone"
    },
    {
      "x": -3,
      "y": 1,
      "z": -6,
      "name": "Cloth_Roof_Leather_Vertical",
      "rotation": 3
    },
    {
      "x": -3,
      "y": 2,
      "z": -6,
      "name": "Cloth_Roof_Leather_Vertical",
      "rotation": 3
    },
    {
      "x": -3,
      "y": 0,
      "z": -5,
      "name": "Rock_Stone"
    },
    {
      "x": -3,
      "y": 1,
      "z": -5,
      "name": "Cloth_Roof_Leather_Vertical",
      "rotation": 3
    },
    {
      "x": -3,
      "y": 2,
      "z": -5,
      "name": "Cloth_Roof_Leather_Vertical",
      "rotation": 3
    },
    {
      "x": -3,
      "y": 0,
      "z": -4,
      "name": "Rock_Stone"
    },
    {
      "x": -3,
      "y": 1,
      "z": -4,
      "name": "Cloth_Roof_Leather_Vertical",
      "rotation": 3
    },
    {
      "x": -3,
      "y": 2,
      "z": -4,
      "name": "Cloth_Roof_Leather_Vertical",
      "rotation": 3
    },
    {
      "x": -3,
      "y": 0,
      "z": -3,
      "name": "Rock_Stone"
    },
    {
      "x": -3,
      "y": 1,
      "z": -3,
      "name": "Empty"
    },
    {
      "x": -3,
      "y": 0,
      "z": -2,
      "name": "Rock_Stone"
    },
    {
      "x": -3,
      "y": 1,
      "z": -2,
      "name": "Empty"
    },
    {
      "x": -3,
      "y": 0,
      "z": -1,
      "name": "Rock_Stone"
    },
    {
      "x": -3,
      "y": 1,
      "z": -1,
      "name": "Empty"
    },
    {
      "x": -2,
      "y": 0,
      "z": -8,
      "name": "Rock_Stone"
    },
    {
      "x": -2,
      "y": 1,
      "z": -8,
      "name": "Empty"
    },
    {
      "x": -2,
      "y": 0,
      "z": -7,
      "name": "Rock_Stone"
    },
    {
      "x": -2,
      "y": 1,
      "z": -7,
      "name": "Empty"
    },
    {
      "x": -2,
      "y": 0,
      "z": -6,
      "name": "Rock_Stone"
    },
    {
      "x": -2,
      "y": 1,
      "z": -6,
      "name": "Empty"
    },
    {
      "x": -2,
      "y": 2,
      "z": -6,
      "name": "Empty"
    },
    {
      "x": -2,
      "y": 3,
      "z": -6,
      "name": "*Cloth_Roof_Leather_State_Definitions_Corner_Left",
      "rotation": 2
    },
    {
      "x": -2,
      "y": 0,
      "z": -5,
      "name": "Rock_Stone"
    },
    {
      "x": -2,
      "y": 1,
      "z": -5,
      "name": "Empty"
    },
    {
      "x": -2,
      "y": 2,
      "z": -5,
      "name": "Empty"
    },
    {
      "x": -2,
      "y": 3,
      "z": -5,
      "name": "Cloth_Roof_Leather",
      "rotation": 3
    },
    {
      "x": -2,
      "y": 0,
      "z": -4,
      "name": "Rock_Stone"
    },
    {
      "x": -2,
      "y": 1,
      "z": -4,
      "name": "Furniture_Crude_Stool",
      "rotation": 2
    },
    {
      "x": -2,
      "y": 2,
      "z": -4,
      "name": "Empty"
    },
    {
      "x": -2,
      "y": 3,
      "z": -4,
      "name": "*Cloth_Roof_Leather_State_Definitions_Corner_Right"
    },
    {
      "x": -2,
      "y": 0,
      "z": -3,
      "name": "Rock_Stone"
    },
    {
      "x": -2,
      "y": 1,
      "z": -3,
      "name": "Cloth_Roof_Leather_Vertical"
    },
    {
      "x": -2,
      "y": 2,
      "z": -3,
      "name": "Cloth_Roof_Leather_Vertical"
    },
    {
      "x": -2,
      "y": 0,
      "z": -2,
      "name": "Rock_Stone"
    },
    {
      "x": -2,
      "y": 1,
      "z": -2,
      "name": "Empty"
    },
    {
      "x": -2,
      "y": 0,
      "z": -1,
      "name": "Rock_Stone"
    },
    {
      "x": -2,
      "y": 1,
      "z": -1,
      "name": "Empty"
    },
    {
      "x": -1,
      "y": 0,
      "z": -8,
      "name": "Rock_Stone"
    },
    {
      "x": -1,
      "y": 1,
      "z": -8,
      "name": "Furniture_Crude_Torch",
      "rotation": 2
    },
    {
      "x": -1,
      "y": 0,
      "z": -7,
      "name": "Rock_Stone"
    },
    {
      "x": -1,
      "y": 1,
      "z": -7,
      "name": "Furniture_Crude_Ladder",
      "rotation": 2
    },
    {
      "x": -1,
      "y": 2,
      "z": -7,
      "name": "Furniture_Crude_Ladder",
      "rotation": 2
    },
    {
      "x": -1,
      "y": 0,
      "z": -6,
      "name": "Rock_Stone"
    },
    {
      "x": -1,
      "y": 1,
      "z": -6,
      "name": "Empty"
    },
    {
      "x": -1,
      "y": 2,
      "z": -6,
      "name": "Empty"
    },
    {
      "x": -1,
      "y": 3,
      "z": -6,
      "name": "*Cloth_Roof_Leather_State_Definitions_Corner_Left",
      "rotation": 1
    },
    {
      "x": -1,
      "y": 0,
      "z": -5,
      "name": "Rock_Stone"
    },
    {
      "x": -1,
      "y": 1,
      "z": -5,
      "name": "Furniture_Crude_Bed",
      "filler": 992,
      "rotation": 2
    },
    {
      "x": -1,
      "y": 2,
      "z": -5,
      "name": "Empty"
    },
    {
      "x": -1,
      "y": 3,
      "z": -5,
      "name": "Cloth_Roof_Leather",
      "rotation": 1
    },
    {
      "x": -1,
      "y": 0,
      "z": -4,
      "name": "Rock_Stone"
    },
    {
      "x": -1,
      "y": 1,
      "z": -4,
      "name": "Furniture_Crude_Bed",
      "components": {
        "Components": {
          "PlacedByInteraction": {
            "WhoPlacedUuid": {
              "$binary": "9ZjLHQsUQaC73VAqONe4MQ==",
              "$type": "04"
            }
          },
          "RespawnBlock": {}
        }
      },
      "rotation": 2
    },
    {
      "x": -1,
      "y": 2,
      "z": -4,
      "name": "Empty"
    },
    {
      "x": -1,
      "y": 3,
      "z": -4,
      "name": "*Cloth_Roof_Leather_State_Definitions_Corner_Left"
    },
    {
      "x": -1,
      "y": 0,
      "z": -3,
      "name": "Rock_Stone"
    },
    {
      "x": -1,
      "y": 1,
      "z": -3,
      "name": "Cloth_Roof_Leather_Vertical"
    },
    {
      "x": -1,
      "y": 2,
      "z": -3,
      "name": "Cloth_Roof_Leather_Vertical"
    },
    {
      "x": -1,
      "y": 0,
      "z": -2,
      "name": "Rock_Stone"
    },
    {
      "x": -1,
      "y": 1,
      "z": -2,
      "name": "Empty"
    },
    {
      "x": -1,
      "y": 0,
      "z": -1,
      "name": "Rock_Stone"
    },
    {
      "x": -1,
      "y": 1,
      "z": -1,
      "name": "Empty"
    },
    {
      "x": 0,
      "y": 0,
      "z": -9,
      "name": "Rock_Stone"
    },
    {
      "x": 0,
      "y": 1,
      "z": -9,
      "name": "Empty"
    },
    {
      "x": 0,
      "y": 0,
      "z": -8,
      "name": "Rock_Stone"
    },
    {
      "x": 0,
      "y": 1,
      "z": -8,
      "name": "Empty"
    },
    {
      "x": 0,
      "y": 0,
      "z": -7,
      "name": "Rock_Stone"
    },
    {
      "x": 0,
      "y": 1,
      "z": -7,
      "name": "Empty"
    },
    {
      "x": 0,
      "y": 0,
      "z": -6,
      "name": "Rock_Stone"
    },
    {
      "x": 0,
      "y": 1,
      "z": -6,
      "name": "Cloth_Roof_Leather_Vertical",
      "rotation": 1
    },
    {
      "x": 0,
      "y": 2,
      "z": -6,
      "name": "Cloth_Roof_Leather_Vertical",
      "rotation": 1
    },
    {
      "x": 0,
      "y": 0,
      "z": -5,
      "name": "Rock_Stone"
    },
    {
      "x": 0,
      "y": 1,
      "z": -5,
      "name": "Cloth_Roof_Leather_Vertical",
      "rotation": 1
    },
    {
      "x": 0,
      "y": 2,
      "z": -5,
      "name": "Cloth_Roof_Leather_Vertical",
      "rotation": 1
    },
    {
      "x": 0,
      "y": 0,
      "z": -4,
      "name": "Rock_Stone"
    },
    {
      "x": 0,
      "y": 1,
      "z": -4,
      "name": "Cloth_Roof_Leather_Vertical",
      "rotation": 1
    },
    {
      "x": 0,
      "y": 2,
      "z": -4,
      "name": "Cloth_Roof_Leather_Vertical",
      "rotation": 1
    },
    {
      "x": 0,
      "y": 0,
      "z": -3,
      "name": "Rock_Stone"
    },
    {
      "x": 0,
      "y": 1,
      "z": -3,
      "name": "Empty"
    },
    {
      "x": 0,
      "y": 0,
      "z": -2,
      "name": "Rock_Stone"
    },
    {
      "x": 0,
      "y": 1,
      "z": -2,
      "name": "Empty"
    },
    {
      "x": 0,
      "y": 0,
      "z": -1,
      "name": "Rock_Stone"
    },
    {
      "x": 0,
      "y": 1,
      "z": -1,
      "name": "Empty"
    },
    {
      "x": 1,
      "y": 0,
      "z": -9,
      "name": "Rock_Stone"
    },
    {
      "x": 1,
      "y": 1,
      "z": -9,
      "name": "Empty"
    },
    {
      "x": 1,
      "y": 0,
      "z": -8,
      "name": "Rock_Stone"
    },
    {
      "x": 1,
      "y": 1,
      "z": -8,
      "name": "Empty"
    },
    {
      "x": 1,
      "y": 0,
      "z": -7,
      "name": "Rock_Stone"
    },
    {
      "x": 1,
      "y": 1,
      "z": -7,
      "name": "Empty"
    },
    {
      "x": 1,
      "y": 0,
      "z": -6,
      "name": "Rock_Stone"
    },
    {
      "x": 1,
      "y": 1,
      "z": -6,
      "name": "Empty"
    },
    {
      "x": 1,
      "y": 0,
      "z": -5,
      "name": "Rock_Stone"
    },
    {
      "x": 1,
      "y": 1,
      "z": -5,
      "name": "Empty"
    },
    {
      "x": 1,
      "y": 0,
      "z": -4,
      "name": "Rock_Stone"
    },
    {
      "x": 1,
      "y": 1,
      "z": -4,
      "name": "Empty"
    },
    {
      "x": 1,
      "y": 0,
      "z": -3,
      "name": "Rock_Stone"
    },
    {
      "x": 1,
      "y": 1,
      "z": -3,
      "name": "Empty"
    },
    {
      "x": 1,
      "y": 0,
      "z": -2,
      "name": "Rock_Stone"
    },
    {
      "x": 1,
      "y": 1,
      "z": -2,
      "name": "Empty"
    },
    {
      "x": 1,
      "y": 0,
      "z": -1,
      "name": "Rock_Stone"
    },
    {
      "x": 1,
      "y": 1,
      "z": -1,
      "name": "Empty"
    }
  ],
  "entities": [
    {
      "Components": {
        "Nameplate": {
          "Text": "Vana_Goblin_Camp"
        },
        "HiddenFromAdventurePlayer": {},
        "SpawnMarkerComponent": {
          "SpawnMarker": "Vana_Goblin_Camp",
          "RespawnTime": 0.0,
          "SpawnCount": 0,
          "NPCReferences": [],
          "PersistedFlock": {},
          "SpawnPosition": {
            "X": 0.0,
            "Y": 0.0,
            "Z": 0.0
          }
        },
        "Transform": {
          "Position": {
            "X": -3.560492992401123,
            "Y": 1.0,
            "Z": -2.40411376953125
          },
          "Rotation": {
            "Pitch": 0.0,
            "Yaw": 12.442770957946777,
            "Roll": 0.0
          }
        },
        "Intangible": {},
        "PrefabCopyable": {},
        "Model": {
          "Model": {
            "Id": "NPC_Spawn_Marker",
            "Scale": 1.0,
            "Static": false
          }
        },
        "UUID": {
          "UUID": {
            "$binary": "01oX9gdQN0yUyWfA+S8BrA==",
            "$type": "04"
          }
        }
      }
    }
  ]
}