{
  "version": 8,
  "blockIdVersion": 11,
  "anchorX": 1,
  "anchorY": 0,
  "anchorZ": -1,
  "blocks": [
    {
      "x": 0,
      "y": 8,
      "z": -4,
      "name": "Plant_Leaves_Ash",
      "support": 15
    },
    {
      "x": 0,
      "y": 7,
      "z": -3,
      "name": "Plant_Leaves_Ash",
      "support": 15
    },
    {
      "x": 0,
      "y": 8,
      "z": -3,
      "name": "Plant_Leaves_Ash",
      "support": 15
    },
    {
      "x": 0,
      "y": 4,
      "z": -2,
      "name": "Plant_Leaves_Ash",
      "support": 15
    },
    {
      "x": 0,
      "y": 5,
      "z": -2,
      "name": "Plant_Leaves_Ash",
      "support": 15
    },
    {
      "x": 0,
      "y": 6,
      "z": -2,
      "name": "Plant_Leaves_Ash",
      "support": 15
    },
    {
      "x": 0,
      "y": 7,
      "z": -2,
      "name": "Plant_Leaves_Ash",
      "support": 15
    },
    {
      "x": 0,
      "y": 3,
      "z": -1,
      "name": "Plant_Leaves_Ash",
      "support": 15
    },
    {
      "x": 0,
      "y": 4,
      "z": -1,
      "name": "Plant_Leaves_Ash",
      "support": 15
    },
    {
      "x": 0,
      "y": 5,
      "z": -1,
      "name": "Plant_Leaves_Ash",
      "support": 15
    },
    {
      "x": 0,
      "y": 6,
      "z": -1,
      "name": "Plant_Leaves_Ash",
      "support": 15
    },
    {
      "x": 1,
      "y": 7,
      "z": -4,
      "name": "Plant_Leaves_Ash",
      "support": 15
    },
    {
      "x": 1,
      "y": 8,
      "z": -4,
      "name": "Plant_Leaves_Ash",
      "support": 15
    },
    {
      "x": 1,
      "y": 6,
      "z": -3,
      "name": "Wood_Ash_Branch_Corner",
      "support": 15,
      "rotation": 2
    },
    {
      "x": 1,
      "y": 7,
      "z": -3,
      "name": "Wood_Ash_Branch_Long",
      "support": 15
    },
    {
      "x": 1,
      "y": 8,
      "z": -3,
      "name": "Plant_Leaves_Ash",
      "support": 15
    },
    {
      "x": 1,
      "y": 9,
      "z": -3,
      "name": "Plant_Leaves_Ash",
      "support": 15
    },
    {
      "x": 1,
      "y": 3,
      "z": -2,
      "name": "Wood_Ash_Branch_Corner",
      "support": 15,
      "rotation": 2
    },
    {
      "x": 1,
      "y": 4,
      "z": -2,
      "name": "Wood_Ash_Branch_Long",
      "support": 15
    },
    {
      "x": 1,
      "y": 5,
      "z": -2,
      "name": "Wood_Ash_Branch_Long",
      "support": 15
    },
    {
      "x": 1,
      "y": 6,
      "z": -2,
      "name": "Wood_Ash_Branch_Corner",
      "support": 15,
      "rotation": 10
    },
    {
      "x": 1,
      "y": 7,
      "z": -2,
      "name": "Plant_Leaves_Ash",
      "support": 15
    },
    {
      "x": 1,
      "y": 8,
      "z": -2,
      "name": "Plant_Leaves_Ash",
      "support": 15
    },
    {
      "x": 1,
      "y": 0,
      "z": -1,
      "name": "Wood_Ash_Branch_Long",
      "support": 15
    },
    {
      "x": 1,
      "y": 1,
      "z": -1,
      "name": "Wood_Ash_Branch_Long",
      "support": 15
    },
    {
      "x": 1,
      "y": 2,
      "z": -1,
      "name": "Wood_Ash_Branch_Long",
      "support": 15
    },
    {
      "x": 1,
      "y": 3,
      "z": -1,
      "name": "Wood_Ash_Branch_Corner",
      "support": 15,
      "rotation": 10
    },
    {
      "x": 1,
      "y": 4,
      "z": -1,
      "name": "Plant_Leaves_Ash",
      "support": 15
    },
    {
      "x": 1,
      "y": 5,
      "z": -1,
      "name": "Plant_Leaves_Ash",
      "support": 15
    },
    {
      "x": 1,
      "y": 6,
      "z": -1,
      "name": "Plant_Leaves_Ash",
      "support": 15
    },
    {
      "x": 1,
      "y": 7,
      "z": -1,
      "name": "Plant_Leaves_Ash",
      "support": 15
    },
    {
      "x": 1,
      "y": 2,
      "z": 0,
      "name": "Plant_Leaves_Ash",
      "support": 15
    },
    {
      "x": 1,
      "y": 3,
      "z": 0,
      "name": "Plant_Leaves_Ash",
      "support": 15
    },
    {
      "x": 1,
      "y": 4,
      "z": 0,
      "name": "Plant_Leaves_Ash",
      "support": 15
    },
    {
      "x": 1,
      "y": 5,
      "z": 0,
      "name": "Plant_Leaves_Ash",
      "support": 15
    },
    {
      "x": 1,
      "y": 6,
      "z": 0,
      "name": "Plant_Leaves_Ash",
      "support": 15
    },
    {
      "x": 2,
      "y": 7,
      "z": -4,
      "name": "Plant_Leaves_Ash",
      "support": 15
    },
    {
      "x": 2,
      "y": 7,
      "z": -3,
      "name": "Plant_Leaves_Ash",
      "support": 15
    },
    {
      "x": 2,
      "y": 8,
      "z": -3,
      "name": "Plant_Leaves_Ash",
      "support": 15
    },
    {
      "x": 2,
      "y": 4,
      "z": -2,
      "name": "Plant_Leaves_Ash",
      "support": 15
    },
    {
      "x": 2,
      "y": 5,
      "z": -2,
      "name": "Plant_Leaves_Ash",
      "support": 15
    },
    {
      "x": 2,
      "y": 6,
      "z": -2,
      "name": "Plant_Leaves_Ash",
      "support": 15
    },
    {
      "x": 2,
      "y": 7,
      "z": -2,
      "name": "Plant_Leaves_Ash",
      "support": 15
    },
    {
      "x": 2,
      "y": 2,
      "z": -1,
      "name": "Plant_Leaves_Ash",
      "support": 15
    },
    {
      "x": 2,
      "y": 3,
      "z": -1,
      "name": "Plant_Leaves_Ash",
      "support": 15
    },
    {
      "x": 2,
      "y": 4,
      "z": -1,
      "name": "Plant_Leaves_Ash",
      "support": 15
    },
    {
      "x": 2,
      "y": 5,
      "z": -1,
      "name": "Plant_Leaves_Ash",
      "support": 15
    },
    {
      "x": 2,
      "y": 6,
      "z": -1,
      "name": "Plant_Leaves_Ash",
      "support": 15
    },
    {
      "x": 2,
      "y": 7,
      "z": -1,
      "name": "Plant_Leaves_Ash",
      "support": 15
    }
  ]
}