{
  "version": 8,
  "blockIdVersion": 11,
  "anchorX": 1,
  "anchorY": 1,
  "anchorZ": -1,
  "blocks": [
    {
      "x": -7,
      "y": 18,
      "z": -8,
      "name": "Plant_Leaves_Ash",
      "support": 15
    },
    {
      "x": -7,
      "y": 17,
      "z": -7,
      "name": "Plant_Leaves_Ash",
      "support": 15
    },
    {
      "x": -7,
      "y": 18,
      "z": -7,
      "name": "Plant_Leaves_Ash",
      "support": 15
    },
    {
      "x": -7,
      "y": 19,
      "z": -7,
      "name": "Plant_Leaves_Ash",
      "support": 15
    },
    {
      "x": -7,
      "y": 18,
      "z": -6,
      "name": "Plant_Leaves_Ash",
      "support": 15
    },
    {
      "x": -7,
      "y": 16,
      "z": -4,
      "name": "Plant_Leaves_Ash",
      "support": 15
    },
    {
      "x": -7,
      "y": 11,
      "z": -2,
      "name": "Plant_Leaves_Ash",
      "support": 15
    },
    {
      "x": -6,
      "y": 16,
      "z": -10,
      "name": "Plant_Leaves_Ash",
      "support": 15
    },
    {
      "x": -6,
      "y": 17,
      "z": -10,
      "name": "Plant_Leaves_Ash",
      "support": 15
    },
    {
      "x": -6,
      "y": 17,
      "z": -8,
      "name": "Plant_Leaves_Ash",
      "support": 15
    },
    {
      "x": -6,
      "y": 18,
      "z": -8,
      "name": "Plant_Leaves_Ash",
      "support": 15
    },
    {
      "x": -6,
      "y": 19,
      "z": -8,
      "name": "Plant_Leaves_Ash",
      "support": 15
    },
    {
      "x": -6,
      "y": 16,
      "z": -7,
      "name": "Wood_Ash_Branch_Corner",
      "support": 15,
      "rotation": 3
    },
    {
      "x": -6,
      "y": 17,
      "z": -7,
      "name": "Wood_Ash_Branch_Long",
      "support": 15
    },
    {
      "x": -6,
      "y": 18,
      "z": -7,
      "name": "Wood_Ash_Branch_Long",
      "support": 15
    },
    {
      "x": -6,
      "y": 19,
      "z": -7,
      "name": "Plant_Leaves_Ash",
      "support": 15
    },
    {
      "x": -6,
      "y": 20,
      "z": -7,
      "name": "Plant_Leaves_Ash",
      "support": 15
    },
    {
      "x": -6,
      "y": 17,
      "z": -6,
      "name": "Plant_Leaves_Ash",
      "support": 15
    },
    {
      "x": -6,
      "y": 18,
      "z": -6,
      "name": "Plant_Leaves_Ash",
      "support": 15
    },
    {
      "x": -6,
      "y": 19,
      "z": -6,
      "name": "Plant_Leaves_Ash",
      "support": 15
    },
    {
      "x": -6,
      "y": 16,
      "z": -5,
      "name": "Plant_Leaves_Ash",
      "support": 15
    },
    {
      "x": -6,
      "y": 16,
      "z": -4,
      "name": "Plant_Leaves_Ash",
      "support": 15
    },
    {
      "x": -6,
      "y": 17,
      "z": -4,
      "name": "Plant_Leaves_Ash",
      "support": 15
    },
    {
      "x": -6,
      "y": 11,
      "z": -3,
      "name": "Plant_Leaves_Ash",
      "support": 15
    },
    {
      "x": -6,
      "y": 16,
      "z": -3,
      "name": "Plant_Leaves_Ash",
      "support": 15
    },
    {
      "x": -6,
      "y": 10,
      "z": -2,
      "name": "Plant_Leaves_Ash",
      "support": 15
    },
    {
      "x": -6,
      "y": 11,
      "z": -2,
      "name": "Plant_Leaves_Ash",
      "support": 15
    },
    {
      "x": -6,
      "y": 12,
      "z": -2,
      "name": "Plant_Leaves_Ash",
      "support": 15
    },
    {
      "x": -6,
      "y": 11,
      "z": -1,
      "name": "Plant_Leaves_Ash",
      "support": 15
    },
    {
      "x": -5,
      "y": 16,
      "z": -11,
      "name": "Plant_Leaves_Ash",
      "support": 15
    },
    {
      "x": -5,
      "y": 17,
      "z": -11,
      "name": "Plant_Leaves_Ash",
      "support": 15
    },
    {
      "x": -5,
      "y": 16,
      "z": -10,
      "name": "Wood_Ash_Branch_Corner",
      "support": 15,
      "rotation": 3
    },
    {
      "x": -5,
      "y": 17,
      "z": -10,
      "name": "Plant_Leaves_Ash",
      "support": 15
    },
    {
      "x": -5,
      "y": 18,
      "z": -10,
      "name": "Plant_Leaves_Ash",
      "support": 15
    },
    {
      "x": -5,
      "y": 16,
      "z": -9,
      "name": "Plant_Leaves_Ash",
      "support": 15
    },
    {
      "x": -5,
      "y": 17,
      "z": -9,
      "name": "Plant_Leaves_Ash",
      "support": 15
    },
    {
      "x": -5,
      "y": 18,
      "z": -8,
      "name": "Plant_Leaves_Ash",
      "support": 15
    },
    {
      "x": -5,
      "y": 15,
      "z": -7,
      "name": "Wood_Ash_Branch_Corner",
      "support": 15,
      "rotation": 3
    },
    {
      "x": -5,
      "y": 16,
      "z": -7,
      "name": "Wood_Ash_Branch_Corner",
      "support": 15,
      "rotation": 11
    },
    {
      "x": -5,
      "y": 17,
      "z": -7,
      "name": "Plant_Leaves_Ash",
      "support": 15
    },
    {
      "x": -5,
      "y": 18,
      "z": -7,
      "name": "Plant_Leaves_Ash",
      "support": 15
    },
    {
      "x": -5,
      "y": 19,
      "z": -7,
      "name": "Plant_Leaves_Ash",
      "support": 15
    },
    {
      "x": -5,
      "y": 16,
      "z": -6,
      "name": "Plant_Leaves_Ash",
      "support": 15
    },
    {
      "x": -5,
      "y": 17,
      "z": -6,
      "name": "Plant_Leaves_Ash",
      "support": 15
    },
    {
      "x": -5,
      "y": 16,
      "z": -5,
      "name": "Plant_Leaves_Ash",
      "support": 15
    },
    {
      "x": -5,
      "y": 17,
      "z": -5,
      "name": "Plant_Leaves_Ash",
      "support": 15
    },
    {
      "x": -5,
      "y": 11,
      "z": -4,
      "name": "Plant_Leaves_Ash",
      "support": 15
    },
    {
      "x": -5,
      "y": 16,
      "z": -4,
      "name": "Wood_Ash_Branch_Long",
      "support": 15,
      "rotation": 5
    },
    {
      "x": -5,
      "y": 17,
      "z": -4,
      "name": "Plant_Leaves_Ash",
      "support": 15
    },
    {
      "x": -5,
      "y": 11,
      "z": -3,
      "name": "Plant_Leaves_Ash",
      "support": 15
    },
    {
      "x": -5,
      "y": 12,
      "z": -3,
      "name": "Plant_Leaves_Ash",
      "support": 15
    },
    {
      "x": -5,
      "y": 16,
      "z": -3,
      "name": "Plant_Leaves_Ash",
      "support": 15
    },
    {
      "x": -5,
      "y": 17,
      "z": -3,
      "name": "Plant_Leaves_Ash",
      "support": 15
    },
    {
      "x": -5,
      "y": 10,
      "z": -2,
      "name": "Plant_Leaves_Ash",
      "support": 15
    },
    {
      "x": -5,
      "y": 11,
      "z": -2,
      "name": "Wood_Ash_Branch_Long",
      "support": 15,
      "rotation": 5
    },
    {
      "x": -5,
      "y": 12,
      "z": -2,
      "name": "Plant_Leaves_Ash",
      "support": 15
    },
    {
      "x": -5,
      "y": 16,
      "z": -2,
      "name": "Plant_Leaves_Ash",
      "support": 15
    },
    {
      "x": -5,
      "y": 11,
      "z": -1,
      "name": "Plant_Leaves_Ash",
      "support": 15
    },
    {
      "x": -5,
      "y": 12,
      "z": -1,
      "name": "Plant_Leaves_Ash",
      "support": 15
    },
    {
      "x": -5,
      "y": 11,
      "z": 0,
      "name": "Plant_Leaves_Ash",
      "support": 15
    },
    {
      "x": -4,
      "y": 16,
      "z": -11,
      "name": "Plant_Leaves_Ash",
      "support": 15
    },
    {
      "x": -4,
      "y": 16,
      "z": -10,
      "name": "Wood_Ash_Branch_Long",
      "support": 15,
      "rotation": 5
    },
    {
      "x": -4,
      "y": 17,
      "z": -10,
      "name": "Plant_Leaves_Ash",
      "support": 15
    },
    {
      "x": -4,
      "y": 16,
      "z": -9,
      "name": "Plant_Leaves_Ash",
      "support": 15
    },
    {
      "x": -4,
      "y": 15,
      "z": -7,
      "name": "Wood_Ash_Branch_Long",
      "support": 15,
      "rotation": 5
    },
    {
      "x": -4,
      "y": 17,
      "z": -7,
      "name": "Plant_Leaves_Ash",
      "support": 15
    },
    {
      "x": -4,
      "y": 16,
      "z": -5,
      "name": "Plant_Leaves_Ash",
      "support": 15
    },
    {
      "x": -4,
      "y": 16,
      "z": -4,
      "name": "Wood_Ash_Branch_Long",
      "support": 15,
      "rotation": 5
    },
    {
      "x": -4,
      "y": 17,
      "z": -4,
      "name": "Plant_Leaves_Ash",
      "support": 15
    },
    {
      "x": -4,
      "y": 11,
      "z": -3,
      "name": "Plant_Leaves_Ash",
      "support": 15
    },
    {
      "x": -4,
      "y": 12,
      "z": -3,
      "name": "Plant_Leaves_Ash",
      "support": 15
    },
    {
      "x": -4,
      "y": 16,
      "z": -3,
      "name": "Plant_Leaves_Ash",
      "support": 15
    },
    {
      "x": -4,
      "y": 11,
      "z": -2,
      "name": "Wood_Ash_Branch_Long",
      "support": 15,
      "rotation": 5
    },
    {
      "x": -4,
      "y": 12,
      "z": -2,
      "name": "Plant_Leaves_Ash",
      "support": 15
    },
    {
      "x": -4,
      "y": 13,
      "z": -2,
      "name": "Plant_Leaves_Ash",
      "support": 15
    },
    {
      "x": -4,
      "y": 11,
      "z": -1,
      "name": "Plant_Leaves_Ash",
      "support": 15
    },
    {
      "x": -4,
      "y": 12,
      "z": -1,
      "name": "Plant_Leaves_Ash",
      "support": 15
    },
    {
      "x": -4,
      "y": 11,
      "z": 0,
      "name": "Plant_Leaves_Ash",
      "support": 15
    },
    {
      "x": -3,
      "y": 17,
      "z": -13,
      "name": "Plant_Leaves_Ash",
      "support": 15
    },
    {
      "x": -3,
      "y": 17,
      "z": -12,
      "name": "Plant_Leaves_Ash",
      "support": 15
    },
    {
      "x": -3,
      "y": 18,
      "z": -12,
      "name": "Plant_Leaves_Ash",
      "support": 15
    },
    {
      "x": -3,
      "y": 17,
      "z": -11,
      "name": "Plant_Leaves_Ash",
      "support": 15
    },
    {
      "x": -3,
      "y": 15,
      "z": -10,
      "name": "Wood_Ash_Branch_Corner",
      "support": 15,
      "rotation": 2
    },
    {
      "x": -3,
      "y": 16,
      "z": -10,
      "name": "Wood_Ash_Branch_Corner",
      "support": 15,
      "rotation": 11
    },
    {
      "x": -3,
      "y": 17,
      "z": -10,
      "name": "Plant_Leaves_Ash",
      "support": 15
    },
    {
      "x": -3,
      "y": 15,
      "z": -9,
      "name": "Wood_Ash_Branch_Long",
      "support": 15,
      "rotation": 4
    },
    {
      "x": -3,
      "y": 16,
      "z": -9,
      "name": "Plant_Leaves_Ash",
      "support": 15
    },
    {
      "x": -3,
      "y": 15,
      "z": -8,
      "name": "Wood_Ash_Branch_Long",
      "support": 15,
      "rotation": 4
    },
    {
      "x": -3,
      "y": 16,
      "z": -8,
      "name": "Plant_Leaves_Ash",
      "support": 15
    },
    {
      "x": -3,
      "y": 17,
      "z": -8,
      "name": "Plant_Leaves_Ash",
      "support": 15
    },
    {
      "x": -3,
      "y": 15,
      "z": -7,
      "name": "Wood_Ash_Trunk_Full",
      "support": 15
    },
    {
      "x": -3,
      "y": 17,
      "z": -7,
      "name": "Plant_Leaves_Ash",
      "support": 15
    },
    {
      "x": -3,
      "y": 18,
      "z": -7,
      "name": "Plant_Leaves_Ash",
      "support": 15
    },
    {
      "x": -3,
      "y": 15,
      "z": -6,
      "name": "Wood_Ash_Branch_Long",
      "support": 15,
      "rotation": 4
    },
    {
      "x": -3,
      "y": 17,
      "z": -6,
      "name": "Plant_Leaves_Ash",
      "support": 15
    },
    {
      "x": -3,
      "y": 15,
      "z": -5,
      "name": "Wood_Ash_Branch_Long",
      "support": 15,
      "rotation": 4
    },
    {
      "x": -3,
      "y": 16,
      "z": -5,
      "name": "Plant_Leaves_Ash",
      "support": 15
    },
    {
      "x": -3,
      "y": 15,
      "z": -4,
      "name": "Wood_Ash_Branch_Corner",
      "support": 15
    },
    {
      "x": -3,
      "y": 16,
      "z": -4,
      "name": "Wood_Ash_Branch_Corner",
      "support": 15,
      "rotation": 11
    },
    {
      "x": -3,
      "y": 17,
      "z": -4,
      "name": "Plant_Leaves_Ash",
      "support": 15
    },
    {
      "x": -3,
      "y": 12,
      "z": -3,
      "name": "Plant_Leaves_Ash",
      "support": 15
    },
    {
      "x": -3,
      "y": 13,
      "z": -3,
      "name": "Plant_Leaves_Ash",
      "support": 15
    },
    {
      "x": -3,
      "y": 16,
      "z": -3,
      "name": "Plant_Leaves_Ash",
      "support": 15
    },
    {
      "x": -3,
      "y": 10,
      "z": -2,
      "name": "Wood_Ash_Trunk_Full",
      "support": 15
    },
    {
      "x": -3,
      "y": 11,
      "z": -2,
      "name": "Wood_Ash_Trunk_Full",
      "support": 15
    },
    {
      "x": -3,
      "y": 12,
      "z": -2,
      "name": "Wood_Ash_Branch_Long",
      "support": 15
    },
    {
      "x": -3,
      "y": 13,
      "z": -2,
      "name": "Plant_Leaves_Ash",
      "support": 15
    },
    {
      "x": -3,
      "y": 14,
      "z": -2,
      "name": "Plant_Leaves_Ash",
      "support": 15
    },
    {
      "x": -3,
      "y": 11,
      "z": -1,
      "name": "Plant_Leaves_Ash",
      "support": 15
    },
    {
      "x": -3,
      "y": 12,
      "z": -1,
      "name": "Plant_Leaves_Ash",
      "support": 15
    },
    {
      "x": -3,
      "y": 13,
      "z": -1,
      "name": "Plant_Leaves_Ash",
      "support": 15
    },
    {
      "x": -3,
      "y": 10,
      "z": 1,
      "name": "Plant_Leaves_Ash",
      "support": 15
    },
    {
      "x": -3,
      "y": 11,
      "z": 1,
      "name": "Plant_Leaves_Ash",
      "support": 15
    },
    {
      "x": -2,
      "y": 17,
      "z": -13,
      "name": "Plant_Leaves_Ash",
      "support": 15
    },
    {
      "x": -2,
      "y": 18,
      "z": -13,
      "name": "Plant_Leaves_Ash",
      "support": 15
    },
    {
      "x": -2,
      "y": 17,
      "z": -12,
      "name": "Wood_Ash_Branch_Long",
      "support": 15,
      "rotation": 5
    },
    {
      "x": -2,
      "y": 18,
      "z": -12,
      "name": "Plant_Leaves_Ash",
      "support": 15
    },
    {
      "x": -2,
      "y": 17,
      "z": -11,
      "name": "Plant_Leaves_Ash",
      "support": 15
    },
    {
      "x": -2,
      "y": 16,
      "z": -10,
      "name": "Plant_Leaves_Ash",
      "support": 15
    },
    {
      "x": -2,
      "y": 17,
      "z": -8,
      "name": "Plant_Leaves_Ash",
      "support": 15
    },
    {
      "x": -2,
      "y": 18,
      "z": -8,
      "name": "Plant_Leaves_Ash",
      "support": 15
    },
    {
      "x": -2,
      "y": 13,
      "z": -7,
      "name": "Wood_Ash_Trunk_Full",
      "support": 15
    },
    {
      "x": -2,
      "y": 14,
      "z": -7,
      "name": "Wood_Ash_Trunk",
      "support": 15
    },
    {
      "x": -2,
      "y": 15,
      "z": -7,
      "name": "Wood_Ash_Trunk_Full",
      "support": 15
    },
    {
      "x": -2,
      "y": 16,
      "z": -7,
      "name": "Wood_Ash_Branch_Long",
      "support": 15
    },
    {
      "x": -2,
      "y": 17,
      "z": -7,
      "name": "Wood_Ash_Branch_Long",
      "support": 15
    },
    {
      "x": -2,
      "y": 18,
      "z": -7,
      "name": "Plant_Leaves_Ash",
      "support": 15
    },
    {
      "x": -2,
      "y": 19,
      "z": -7,
      "name": "Plant_Leaves_Ash",
      "support": 15
    },
    {
      "x": -2,
      "y": 16,
      "z": -6,
      "name": "Plant_Leaves_Ash",
      "support": 15
    },
    {
      "x": -2,
      "y": 17,
      "z": -6,
      "name": "Plant_Leaves_Ash",
      "support": 15
    },
    {
      "x": -2,
      "y": 18,
      "z": -6,
      "name": "Plant_Leaves_Ash",
      "support": 15
    },
    {
      "x": -2,
      "y": 16,
      "z": -4,
      "name": "Plant_Leaves_Ash",
      "support": 15
    },
    {
      "x": -2,
      "y": 8,
      "z": -3,
      "name": "Wood_Ash_Trunk_Full",
      "support": 15
    },
    {
      "x": -2,
      "y": 9,
      "z": -3,
      "name": "Wood_Ash_Trunk_Full",
      "support": 15
    },
    {
      "x": -2,
      "y": 9,
      "z": -2,
      "name": "Wood_Ash_Trunk_Full",
      "support": 15
    },
    {
      "x": -2,
      "y": 10,
      "z": -2,
      "name": "Wood_Ash_Trunk_Full",
      "support": 15
    },
    {
      "x": -2,
      "y": 12,
      "z": -2,
      "name": "Plant_Leaves_Ash",
      "support": 15
    },
    {
      "x": -2,
      "y": 13,
      "z": -2,
      "name": "Plant_Leaves_Ash",
      "support": 15
    },
    {
      "x": -2,
      "y": 9,
      "z": -1,
      "name": "Wood_Ash_Branch_Long",
      "support": 15,
      "rotation": 4
    },
    {
      "x": -2,
      "y": 9,
      "z": 0,
      "name": "Wood_Ash_Branch_Long",
      "support": 15,
      "rotation": 4
    },
    {
      "x": -2,
      "y": 10,
      "z": 0,
      "name": "Plant_Leaves_Ash",
      "support": 15
    },
    {
      "x": -2,
      "y": 9,
      "z": 1,
      "name": "Wood_Ash_Branch_Corner",
      "support": 15
    },
    {
      "x": -2,
      "y": 10,
      "z": 1,
      "name": "Wood_Ash_Branch_Corner",
      "support": 15,
      "rotation": 9
    },
    {
      "x": -2,
      "y": 11,
      "z": 1,
      "name": "Plant_Leaves_Ash",
      "support": 15
    },
    {
      "x": -2,
      "y": 12,
      "z": 1,
      "name": "Plant_Leaves_Ash",
      "support": 15
    },
    {
      "x": -2,
      "y": 10,
      "z": 2,
      "name": "Plant_Leaves_Ash",
      "support": 15
    },
    {
      "x": -2,
      "y": 11,
      "z": 2,
      "name": "Plant_Leaves_Ash",
      "support": 15
    },
    {
      "x": -1,
      "y": 17,
      "z": -13,
      "name": "Plant_Leaves_Ash",
      "support": 15
    },
    {
      "x": -1,
      "y": 15,
      "z": -12,
      "name": "Plant_Leaves_Ash",
      "support": 15
    },
    {
      "x": -1,
      "y": 16,
      "z": -12,
      "name": "Wood_Ash_Branch_Corner",
      "support": 15,
      "rotation": 2
    },
    {
      "x": -1,
      "y": 17,
      "z": -12,
      "name": "Wood_Ash_Branch_Corner",
      "support": 15,
      "rotation": 11
    },
    {
      "x": -1,
      "y": 18,
      "z": -12,
      "name": "Plant_Leaves_Ash",
      "support": 15
    },
    {
      "x": -1,
      "y": 16,
      "z": -11,
      "name": "Wood_Ash_Branch_Long",
      "support": 15,
      "rotation": 4
    },
    {
      "x": -1,
      "y": 17,
      "z": -11,
      "name": "Plant_Leaves_Ash",
      "support": 15
    },
    {
      "x": -1,
      "y": 15,
      "z": -10,
      "name": "Wood_Ash_Branch_Corner",
      "support": 15,
      "rotation": 3
    },
    {
      "x": -1,
      "y": 16,
      "z": -10,
      "name": "Wood_Ash_Branch_Corner",
      "support": 15,
      "rotation": 10
    },
    {
      "x": -1,
      "y": 17,
      "z": -10,
      "name": "Plant_Leaves_Ash",
      "support": 15
    },
    {
      "x": -1,
      "y": 15,
      "z": -9,
      "name": "Plant_Leaves_Ash",
      "support": 15
    },
    {
      "x": -1,
      "y": 16,
      "z": -9,
      "name": "Plant_Leaves_Ash",
      "support": 15
    },
    {
      "x": -1,
      "y": 12,
      "z": -7,
      "name": "Wood_Ash_Trunk_Full",
      "support": 15
    },
    {
      "x": -1,
      "y": 13,
      "z": -7,
      "name": "Wood_Ash_Trunk_Full",
      "support": 15
    },
    {
      "x": -1,
      "y": 17,
      "z": -7,
      "name": "Plant_Leaves_Ash",
      "support": 15
    },
    {
      "x": -1,
      "y": 18,
      "z": -7,
      "name": "Plant_Leaves_Ash",
      "support": 15
    },
    {
      "x": -1,
      "y": 17,
      "z": -6,
      "name": "Plant_Leaves_Ash",
      "support": 15
    },
    {
      "x": -1,
      "y": 16,
      "z": -4,
      "name": "Plant_Leaves_Ash",
      "support": 15
    },
    {
      "x": -1,
      "y": 8,
      "z": -3,
      "name": "Wood_Ash_Trunk_Full",
      "support": 15
    },
    {
      "x": -1,
      "y": 15,
      "z": -3,
      "name": "Plant_Leaves_Ash",
      "support": 15
    },
    {
      "x": -1,
      "y": 16,
      "z": -3,
      "name": "Plant_Leaves_Ash",
      "support": 15
    },
    {
      "x": -1,
      "y": 17,
      "z": -3,
      "name": "Plant_Leaves_Ash",
      "support": 15
    },
    {
      "x": -1,
      "y": 16,
      "z": -2,
      "name": "Plant_Leaves_Ash",
      "support": 15
    },
    {
      "x": -1,
      "y": 10,
      "z": 0,
      "name": "Plant_Leaves_Ash",
      "support": 15
    },
    {
      "x": -1,
      "y": 11,
      "z": 0,
      "name": "Plant_Leaves_Ash",
      "support": 15
    },
    {
      "x": -1,
      "y": 10,
      "z": 1,
      "name": "Wood_Ash_Branch_Corner",
      "support": 15,
      "rotation": 1
    },
    {
      "x": -1,
      "y": 11,
      "z": 1,
      "name": "Plant_Leaves_Ash",
      "support": 15
    },
    {
      "x": -1,
      "y": 12,
      "z": 1,
      "name": "Plant_Leaves_Ash",
      "support": 15
    },
    {
      "x": -1,
      "y": 11,
      "z": 2,
      "name": "Plant_Leaves_Ash",
      "support": 15
    },
    {
      "x": 0,
      "y": 15,
      "z": -13,
      "name": "Plant_Leaves_Ash",
      "support": 15
    },
    {
      "x": 0,
      "y": 16,
      "z": -13,
      "name": "Plant_Leaves_Ash",
      "support": 15
    },
    {
      "x": 0,
      "y": 15,
      "z": -12,
      "name": "Plant_Leaves_Ash",
      "support": 15
    },
    {
      "x": 0,
      "y": 16,
      "z": -12,
      "name": "Plant_Leaves_Ash",
      "support": 15
    },
    {
      "x": 0,
      "y": 17,
      "z": -12,
      "name": "Plant_Leaves_Ash",
      "support": 15
    },
    {
      "x": 0,
      "y": 17,
      "z": -11,
      "name": "Plant_Leaves_Ash",
      "support": 15
    },
    {
      "x": 0,
      "y": 18,
      "z": -11,
      "name": "Plant_Leaves_Ash",
      "support": 15
    },
    {
      "x": 0,
      "y": 19,
      "z": -11,
      "name": "Plant_Leaves_Ash",
      "support": 15
    },
    {
      "x": 0,
      "y": 15,
      "z": -10,
      "name": "Wood_Ash_Branch_Long",
      "support": 15,
      "rotation": 5
    },
    {
      "x": 0,
      "y": 16,
      "z": -10,
      "name": "Plant_Leaves_Ash",
      "support": 15
    },
    {
      "x": 0,
      "y": 17,
      "z": -10,
      "name": "Plant_Leaves_Ash",
      "support": 15
    },
    {
      "x": 0,
      "y": 15,
      "z": -9,
      "name": "Plant_Leaves_Ash",
      "support": 15
    },
    {
      "x": 0,
      "y": 12,
      "z": -7,
      "name": "Wood_Ash_Trunk_Full",
      "support": 15
    },
    {
      "x": 0,
      "y": 10,
      "z": -6,
      "name": "Wood_Ash_Trunk_Full",
      "support": 15
    },
    {
      "x": 0,
      "y": 11,
      "z": -6,
      "name": "Wood_Ash_Trunk_Full",
      "support": 15
    },
    {
      "x": 0,
      "y": 15,
      "z": -5,
      "name": "Plant_Leaves_Ash",
      "support": 15
    },
    {
      "x": 0,
      "y": 15,
      "z": -4,
      "name": "Plant_Leaves_Ash",
      "support": 15
    },
    {
      "x": 0,
      "y": 16,
      "z": -4,
      "name": "Plant_Leaves_Ash",
      "support": 15
    },
    {
      "x": 0,
      "y": 17,
      "z": -4,
      "name": "Plant_Leaves_Ash",
      "support": 15
    },
    {
      "x": 0,
      "y": 8,
      "z": -3,
      "name": "Wood_Ash_Trunk_Full",
      "support": 15
    },
    {
      "x": 0,
      "y": 14,
      "z": -3,
      "name": "Wood_Ash_Branch_Corner",
      "support": 15,
      "rotation": 3
    },
    {
      "x": 0,
      "y": 15,
      "z": -3,
      "name": "Wood_Ash_Branch_Long",
      "support": 15
    },
    {
      "x": 0,
      "y": 16,
      "z": -3,
      "name": "Wood_Ash_Branch_Long",
      "support": 15
    },
    {
      "x": 0,
      "y": 17,
      "z": -3,
      "name": "Plant_Leaves_Ash",
      "support": 15
    },
    {
      "x": 0,
      "y": 18,
      "z": -3,
      "name": "Plant_Leaves_Ash",
      "support": 15
    },
    {
      "x": 0,
      "y": 15,
      "z": -2,
      "name": "Plant_Leaves_Ash",
      "support": 15
    },
    {
      "x": 0,
      "y": 16,
      "z": -2,
      "name": "Plant_Leaves_Ash",
      "support": 15
    },
    {
      "x": 0,
      "y": 17,
      "z": -2,
      "name": "Plant_Leaves_Ash",
      "support": 15
    },
    {
      "x": 0,
      "y": 10,
      "z": 1,
      "name": "Plant_Leaves_Ash",
      "support": 15
    },
    {
      "x": 0,
      "y": 11,
      "z": 1,
      "name": "Plant_Leaves_Ash",
      "support": 15
    },
    {
      "x": 0,
      "y": 15,
      "z": 1,
      "name": "Plant_Leaves_Ash",
      "support": 15
    },
    {
      "x": 1,
      "y": 15,
      "z": -14,
      "name": "Plant_Leaves_Ash",
      "support": 15
    },
    {
      "x": 1,
      "y": 15,
      "z": -13,
      "name": "Plant_Leaves_Ash",
      "support": 15
    },
    {
      "x": 1,
      "y": 16,
      "z": -13,
      "name": "Plant_Leaves_Ash",
      "support": 15
    },
    {
      "x": 1,
      "y": 15,
      "z": -12,
      "name": "Wood_Ash_Branch_Long",
      "support": 15,
      "rotation": 4
    },
    {
      "x": 1,
      "y": 16,
      "z": -12,
      "name": "Plant_Leaves_Ash",
      "support": 15
    },
    {
      "x": 1,
      "y": 17,
      "z": -12,
      "name": "Plant_Leaves_Ash",
      "support": 15
    },
    {
      "x": 1,
      "y": 18,
      "z": -12,
      "name": "Plant_Leaves_Ash",
      "support": 15
    },
    {
      "x": 1,
      "y": 19,
      "z": -12,
      "name": "Plant_Leaves_Ash",
      "support": 15
    },
    {
      "x": 1,
      "y": 15,
      "z": -11,
      "name": "Wood_Ash_Branch_Long",
      "support": 15,
      "rotation": 4
    },
    {
      "x": 1,
      "y": 17,
      "z": -11,
      "name": "Wood_Ash_Branch_Corner",
      "support": 15,
      "rotation": 2
    },
    {
      "x": 1,
      "y": 18,
      "z": -11,
      "name": "Wood_Ash_Branch_Long",
      "support": 15
    },
    {
      "x": 1,
      "y": 19,
      "z": -11,
      "name": "Plant_Leaves_Ash",
      "support": 15
    },
    {
      "x": 1,
      "y": 20,
      "z": -11,
      "name": "Plant_Leaves_Ash",
      "support": 15
    },
    {
      "x": 1,
      "y": 14,
      "z": -10,
      "name": "Wood_Ash_Trunk_Full",
      "support": 15
    },
    {
      "x": 1,
      "y": 15,
      "z": -10,
      "name": "Wood_Ash_Trunk_Full",
      "support": 15
    },
    {
      "x": 1,
      "y": 16,
      "z": -10,
      "name": "Wood_Ash_Branch_Long",
      "support": 15
    },
    {
      "x": 1,
      "y": 17,
      "z": -10,
      "name": "Wood_Ash_Branch_Corner",
      "support": 15,
      "rotation": 10
    },
    {
      "x": 1,
      "y": 18,
      "z": -10,
      "name": "Plant_Leaves_Ash",
      "support": 15
    },
    {
      "x": 1,
      "y": 19,
      "z": -10,
      "name": "Plant_Leaves_Ash",
      "support": 15
    },
    {
      "x": 1,
      "y": 13,
      "z": -9,
      "name": "Wood_Ash_Trunk_Full",
      "support": 15
    },
    {
      "x": 1,
      "y": 14,
      "z": -9,
      "name": "Wood_Ash_Trunk_Full",
      "support": 15
    },
    {
      "x": 1,
      "y": 16,
      "z": -9,
      "name": "Plant_Leaves_Ash",
      "support": 15
    },
    {
      "x": 1,
      "y": 17,
      "z": -9,
      "name": "Plant_Leaves_Ash",
      "support": 15
    },
    {
      "x": 1,
      "y": 12,
      "z": -8,
      "name": "Wood_Ash_Trunk_Full",
      "support": 15
    },
    {
      "x": 1,
      "y": 13,
      "z": -8,
      "name": "Wood_Ash_Trunk_Full",
      "support": 15
    },
    {
      "x": 1,
      "y": 16,
      "z": -8,
      "name": "Plant_Leaves_Ash",
      "support": 15
    },
    {
      "x": 1,
      "y": 12,
      "z": -7,
      "name": "Wood_Ash_Trunk_Full",
      "support": 15
    },
    {
      "x": 1,
      "y": 15,
      "z": -7,
      "name": "Plant_Leaves_Ash",
      "support": 15
    },
    {
      "x": 1,
      "y": 16,
      "z": -7,
      "name": "Plant_Leaves_Ash",
      "support": 15
    },
    {
      "x": 1,
      "y": 17,
      "z": -7,
      "name": "Plant_Leaves_Ash",
      "support": 15
    },
    {
      "x": 1,
      "y": 11,
      "z": -6,
      "name": "Wood_Ash_Trunk_Full",
      "support": 15
    },
    {
      "x": 1,
      "y": 12,
      "z": -6,
      "name": "Wood_Ash_Trunk_Full",
      "support": 15
    },
    {
      "x": 1,
      "y": 15,
      "z": -6,
      "name": "Plant_Leaves_Ash",
      "support": 15
    },
    {
      "x": 1,
      "y": 16,
      "z": -6,
      "name": "Plant_Leaves_Ash",
      "support": 15
    },
    {
      "x": 1,
      "y": 10,
      "z": -5,
      "name": "Wood_Ash_Trunk_Full",
      "support": 15
    },
    {
      "x": 1,
      "y": 11,
      "z": -5,
      "name": "Wood_Ash_Trunk_Full",
      "support": 15
    },
    {
      "x": 1,
      "y": 15,
      "z": -5,
      "name": "Plant_Leaves_Ash",
      "support": 15
    },
    {
      "x": 1,
      "y": 7,
      "z": -4,
      "name": "Wood_Ash_Trunk_Full",
      "support": 15
    },
    {
      "x": 1,
      "y": 8,
      "z": -4,
      "name": "Wood_Ash_Trunk",
      "support": 15
    },
    {
      "x": 1,
      "y": 9,
      "z": -4,
      "name": "Wood_Ash_Trunk",
      "support": 15
    },
    {
      "x": 1,
      "y": 10,
      "z": -4,
      "name": "Wood_Ash_Trunk_Full",
      "support": 15
    },
    {
      "x": 1,
      "y": 15,
      "z": -4,
      "name": "Plant_Leaves_Ash",
      "support": 15
    },
    {
      "x": 1,
      "y": 16,
      "z": -4,
      "name": "Plant_Leaves_Ash",
      "support": 15
    },
    {
      "x": 1,
      "y": 6,
      "z": -3,
      "name": "Wood_Ash_Trunk_Full",
      "support": 15
    },
    {
      "x": 1,
      "y": 7,
      "z": -3,
      "name": "Wood_Ash_Trunk",
      "support": 15
    },
    {
      "x": 1,
      "y": 8,
      "z": -3,
      "name": "Wood_Ash_Trunk",
      "support": 15
    },
    {
      "x": 1,
      "y": 9,
      "z": -3,
      "name": "Wood_Ash_Trunk_Full",
      "support": 15
    },
    {
      "x": 1,
      "y": 14,
      "z": -3,
      "name": "Wood_Ash_Branch_Long",
      "support": 15,
      "rotation": 5
    },
    {
      "x": 1,
      "y": 15,
      "z": -3,
      "name": "Plant_Leaves_Ash",
      "support": 15
    },
    {
      "x": 1,
      "y": 16,
      "z": -3,
      "name": "Plant_Leaves_Ash",
      "support": 15
    },
    {
      "x": 1,
      "y": 17,
      "z": -3,
      "name": "Plant_Leaves_Ash",
      "support": 15
    },
    {
      "x": 1,
      "y": 0,
      "z": -2,
      "name": "Wood_Ash_Trunk",
      "support": 15
    },
    {
      "x": 1,
      "y": 1,
      "z": -2,
      "name": "Wood_Ash_Trunk",
      "support": 15
    },
    {
      "x": 1,
      "y": 2,
      "z": -2,
      "name": "Wood_Ash_Trunk",
      "support": 15
    },
    {
      "x": 1,
      "y": 3,
      "z": -2,
      "name": "Wood_Ash_Trunk",
      "support": 15
    },
    {
      "x": 1,
      "y": 4,
      "z": -2,
      "name": "Wood_Ash_Trunk",
      "support": 15
    },
    {
      "x": 1,
      "y": 5,
      "z": -2,
      "name": "Wood_Ash_Trunk",
      "support": 15
    },
    {
      "x": 1,
      "y": 6,
      "z": -2,
      "name": "Wood_Ash_Trunk",
      "support": 15
    },
    {
      "x": 1,
      "y": 7,
      "z": -2,
      "name": "Wood_Ash_Trunk_Full",
      "support": 15
    },
    {
      "x": 1,
      "y": 16,
      "z": -2,
      "name": "Plant_Leaves_Ash",
      "support": 15
    },
    {
      "x": 1,
      "y": 0,
      "z": -1,
      "name": "Wood_Ash_Trunk",
      "support": 15
    },
    {
      "x": 1,
      "y": 1,
      "z": -1,
      "name": "Wood_Ash_Trunk",
      "support": 15
    },
    {
      "x": 1,
      "y": 2,
      "z": -1,
      "name": "Wood_Ash_Trunk",
      "support": 15
    },
    {
      "x": 1,
      "y": 3,
      "z": -1,
      "name": "Wood_Ash_Trunk",
      "support": 15
    },
    {
      "x": 1,
      "y": 4,
      "z": -1,
      "name": "Wood_Ash_Trunk",
      "support": 15
    },
    {
      "x": 1,
      "y": 5,
      "z": -1,
      "name": "Wood_Ash_Trunk",
      "support": 15
    },
    {
      "x": 1,
      "y": 6,
      "z": -1,
      "name": "Wood_Ash_Trunk_Full",
      "support": 15
    },
    {
      "x": 1,
      "y": 0,
      "z": 0,
      "name": "Wood_Ash_Trunk",
      "support": 15
    },
    {
      "x": 1,
      "y": 1,
      "z": 0,
      "name": "Wood_Ash_Trunk",
      "support": 15
    },
    {
      "x": 1,
      "y": 2,
      "z": 0,
      "name": "Wood_Ash_Trunk_Full",
      "support": 15
    },
    {
      "x": 1,
      "y": 15,
      "z": 0,
      "name": "Plant_Leaves_Ash",
      "support": 15
    },
    {
      "x": 1,
      "y": 14,
      "z": 1,
      "name": "Plant_Leaves_Ash",
      "support": 15
    },
    {
      "x": 1,
      "y": 15,
      "z": 1,
      "name": "Plant_Leaves_Ash",
      "support": 15
    },
    {
      "x": 1,
      "y": 15,
      "z": 2,
      "name": "Plant_Leaves_Ash",
      "support": 15
    },
    {
      "x": 2,
      "y": 15,
      "z": -13,
      "name": "Plant_Leaves_Ash",
      "support": 15
    },
    {
      "x": 2,
      "y": 16,
      "z": -13,
      "name": "Plant_Leaves_Ash",
      "support": 15
    },
    {
      "x": 2,
      "y": 15,
      "z": -12,
      "name": "Plant_Leaves_Ash",
      "support": 15
    },
    {
      "x": 2,
      "y": 16,
      "z": -12,
      "name": "Plant_Leaves_Ash",
      "support": 15
    },
    {
      "x": 2,
      "y": 16,
      "z": -11,
      "name": "Plant_Leaves_Ash",
      "support": 15
    },
    {
      "x": 2,
      "y": 17,
      "z": -11,
      "name": "Plant_Leaves_Ash",
      "support": 15
    },
    {
      "x": 2,
      "y": 18,
      "z": -11,
      "name": "Plant_Leaves_Ash",
      "support": 15
    },
    {
      "x": 2,
      "y": 19,
      "z": -11,
      "name": "Plant_Leaves_Ash",
      "support": 15
    },
    {
      "x": 2,
      "y": 14,
      "z": -10,
      "name": "Wood_Ash_Branch_Long",
      "support": 15,
      "rotation": 5
    },
    {
      "x": 2,
      "y": 15,
      "z": -10,
      "name": "Plant_Leaves_Ash",
      "support": 15
    },
    {
      "x": 2,
      "y": 17,
      "z": -10,
      "name": "Plant_Leaves_Ash",
      "support": 15
    },
    {
      "x": 2,
      "y": 17,
      "z": -9,
      "name": "Plant_Leaves_Ash",
      "support": 15
    },
    {
      "x": 2,
      "y": 16,
      "z": -8,
      "name": "Plant_Leaves_Ash",
      "support": 15
    },
    {
      "x": 2,
      "y": 17,
      "z": -8,
      "name": "Plant_Leaves_Ash",
      "support": 15
    },
    {
      "x": 2,
      "y": 12,
      "z": -7,
      "name": "Wood_Ash_Trunk_Full",
      "support": 15
    },
    {
      "x": 2,
      "y": 13,
      "z": -7,
      "name": "Wood_Ash_Trunk_Full",
      "support": 15
    },
    {
      "x": 2,
      "y": 14,
      "z": -7,
      "name": "Wood_Ash_Branch_Long",
      "support": 15
    },
    {
      "x": 2,
      "y": 15,
      "z": -7,
      "name": "Wood_Ash_Branch_Long",
      "support": 15
    },
    {
      "x": 2,
      "y": 16,
      "z": -7,
      "name": "Wood_Ash_Branch_Long",
      "support": 15
    },
    {
      "x": 2,
      "y": 17,
      "z": -7,
      "name": "Plant_Leaves_Ash",
      "support": 15
    },
    {
      "x": 2,
      "y": 18,
      "z": -7,
      "name": "Plant_Leaves_Ash",
      "support": 15
    },
    {
      "x": 2,
      "y": 15,
      "z": -6,
      "name": "Plant_Leaves_Ash",
      "support": 15
    },
    {
      "x": 2,
      "y": 16,
      "z": -6,
      "name": "Plant_Leaves_Ash",
      "support": 15
    },
    {
      "x": 2,
      "y": 17,
      "z": -6,
      "name": "Plant_Leaves_Ash",
      "support": 15
    },
    {
      "x": 2,
      "y": 11,
      "z": -5,
      "name": "Wood_Ash_Trunk_Full",
      "support": 15
    },
    {
      "x": 2,
      "y": 15,
      "z": -5,
      "name": "Plant_Leaves_Ash",
      "support": 15
    },
    {
      "x": 2,
      "y": 11,
      "z": -4,
      "name": "Wood_Ash_Trunk_Full",
      "support": 15
    },
    {
      "x": 2,
      "y": 12,
      "z": -4,
      "name": "Wood_Ash_Trunk_Full",
      "support": 15
    },
    {
      "x": 2,
      "y": 14,
      "z": -3,
      "name": "Wood_Ash_Branch_Long",
      "support": 15,
      "rotation": 5
    },
    {
      "x": 2,
      "y": 16,
      "z": -3,
      "name": "Plant_Leaves_Ash",
      "support": 15
    },
    {
      "x": 2,
      "y": 0,
      "z": -2,
      "name": "Wood_Ash_Trunk",
      "support": 15
    },
    {
      "x": 2,
      "y": 1,
      "z": -2,
      "name": "Wood_Ash_Trunk",
      "support": 15
    },
    {
      "x": 2,
      "y": 2,
      "z": -2,
      "name": "Wood_Ash_Trunk_Full",
      "support": 15
    },
    {
      "x": 2,
      "y": 0,
      "z": -1,
      "name": "Wood_Ash_Trunk",
      "support": 15
    },
    {
      "x": 2,
      "y": 1,
      "z": -1,
      "name": "Wood_Ash_Trunk_Full",
      "support": 15
    },
    {
      "x": 2,
      "y": 14,
      "z": 0,
      "name": "Wood_Ash_Branch_Corner",
      "support": 15,
      "rotation": 3
    },
    {
      "x": 2,
      "y": 15,
      "z": 0,
      "name": "Wood_Ash_Branch_Corner",
      "support": 15,
      "rotation": 8
    },
    {
      "x": 2,
      "y": 16,
      "z": 0,
      "name": "Plant_Leaves_Ash",
      "support": 15
    },
    {
      "x": 2,
      "y": 14,
      "z": 1,
      "name": "Plant_Leaves_Ash",
      "support": 15
    },
    {
      "x": 2,
      "y": 15,
      "z": 1,
      "name": "Wood_Ash_Branch_Long",
      "support": 15,
      "rotation": 4
    },
    {
      "x": 2,
      "y": 16,
      "z": 1,
      "name": "Plant_Leaves_Ash",
      "support": 15
    },
    {
      "x": 2,
      "y": 14,
      "z": 2,
      "name": "Plant_Leaves_Ash",
      "support": 15
    },
    {
      "x": 2,
      "y": 15,
      "z": 2,
      "name": "Plant_Leaves_Ash",
      "support": 15
    },
    {
      "x": 2,
      "y": 16,
      "z": 2,
      "name": "Plant_Leaves_Ash",
      "support": 15
    },
    {
      "x": 2,
      "y": 15,
      "z": 3,
      "name": "Plant_Leaves_Ash",
      "support": 15
    },
    {
      "x": 3,
      "y": 15,
      "z": -12,
      "name": "Plant_Leaves_Ash",
      "support": 15
    },
    {
      "x": 3,
      "y": 16,
      "z": -12,
      "name": "Plant_Leaves_Ash",
      "support": 15
    },
    {
      "x": 3,
      "y": 15,
      "z": -11,
      "name": "Wood_Ash_Branch_Corner",
      "support": 15,
      "rotation": 2
    },
    {
      "x": 3,
      "y": 16,
      "z": -11,
      "name": "Wood_Ash_Branch_Corner",
      "support": 15,
      "rotation": 9
    },
    {
      "x": 3,
      "y": 17,
      "z": -11,
      "name": "Plant_Leaves_Ash",
      "support": 15
    },
    {
      "x": 3,
      "y": 14,
      "z": -10,
      "name": "Wood_Ash_Branch_Corner",
      "support": 15,
      "rotation": 1
    },
    {
      "x": 3,
      "y": 15,
      "z": -10,
      "name": "Wood_Ash_Branch_Corner",
      "support": 15,
      "rotation": 10
    },
    {
      "x": 3,
      "y": 16,
      "z": -10,
      "name": "Plant_Leaves_Ash",
      "support": 15
    },
    {
      "x": 3,
      "y": 17,
      "z": -10,
      "name": "Plant_Leaves_Ash",
      "support": 15
    },
    {
      "x": 3,
      "y": 17,
      "z": -9,
      "name": "Plant_Leaves_Ash",
      "support": 15
    },
    {
      "x": 3,
      "y": 16,
      "z": -8,
      "name": "Plant_Leaves_Ash",
      "support": 15
    },
    {
      "x": 3,
      "y": 17,
      "z": -8,
      "name": "Plant_Leaves_Ash",
      "support": 15
    },
    {
      "x": 3,
      "y": 13,
      "z": -7,
      "name": "Wood_Ash_Trunk_Full",
      "support": 15
    },
    {
      "x": 3,
      "y": 15,
      "z": -7,
      "name": "Plant_Leaves_Ash",
      "support": 15
    },
    {
      "x": 3,
      "y": 16,
      "z": -7,
      "name": "Plant_Leaves_Ash",
      "support": 15
    },
    {
      "x": 3,
      "y": 17,
      "z": -7,
      "name": "Plant_Leaves_Ash",
      "support": 15
    },
    {
      "x": 3,
      "y": 15,
      "z": -6,
      "name": "Plant_Leaves_Ash",
      "support": 15
    },
    {
      "x": 3,
      "y": 16,
      "z": -6,
      "name": "Plant_Leaves_Ash",
      "support": 15
    },
    {
      "x": 3,
      "y": 12,
      "z": -4,
      "name": "Wood_Ash_Trunk_Full",
      "support": 15
    },
    {
      "x": 3,
      "y": 13,
      "z": -4,
      "name": "Wood_Ash_Trunk_Full",
      "support": 15
    },
    {
      "x": 3,
      "y": 15,
      "z": -4,
      "name": "Plant_Leaves_Ash",
      "support": 15
    },
    {
      "x": 3,
      "y": 16,
      "z": -4,
      "name": "Plant_Leaves_Ash",
      "support": 15
    },
    {
      "x": 3,
      "y": 13,
      "z": -3,
      "name": "Wood_Ash_Trunk_Full",
      "support": 15
    },
    {
      "x": 3,
      "y": 14,
      "z": -3,
      "name": "Wood_Ash_Trunk_Full",
      "support": 15
    },
    {
      "x": 3,
      "y": 15,
      "z": -3,
      "name": "Wood_Ash_Branch_Long",
      "support": 15
    },
    {
      "x": 3,
      "y": 16,
      "z": -3,
      "name": "Plant_Leaves_Ash",
      "support": 15
    },
    {
      "x": 3,
      "y": 17,
      "z": -3,
      "name": "Plant_Leaves_Ash",
      "support": 15
    },
    {
      "x": 3,
      "y": 13,
      "z": -2,
      "name": "Wood_Ash_Branch_Long",
      "support": 15,
      "rotation": 4
    },
    {
      "x": 3,
      "y": 16,
      "z": -2,
      "name": "Plant_Leaves_Ash",
      "support": 15
    },
    {
      "x": 3,
      "y": 13,
      "z": -1,
      "name": "Wood_Ash_Branch_Long",
      "support": 15,
      "rotation": 4
    },
    {
      "x": 3,
      "y": 13,
      "z": 0,
      "name": "Wood_Ash_Branch_Corner",
      "support": 15
    },
    {
      "x": 3,
      "y": 14,
      "z": 0,
      "name": "Wood_Ash_Branch_Corner",
      "support": 15,
      "rotation": 11
    },
    {
      "x": 3,
      "y": 15,
      "z": 0,
      "name": "Plant_Leaves_Ash",
      "support": 15
    },
    {
      "x": 3,
      "y": 15,
      "z": 1,
      "name": "Plant_Leaves_Ash",
      "support": 15
    },
    {
      "x": 3,
      "y": 16,
      "z": 1,
      "name": "Plant_Leaves_Ash",
      "support": 15
    },
    {
      "x": 3,
      "y": 15,
      "z": 2,
      "name": "Plant_Leaves_Ash",
      "support": 15
    },
    {
      "x": 4,
      "y": 16,
      "z": -12,
      "name": "Plant_Leaves_Ash",
      "support": 15
    },
    {
      "x": 4,
      "y": 16,
      "z": -11,
      "name": "Wood_Ash_Branch_Corner",
      "support": 15,
      "rotation": 1
    },
    {
      "x": 4,
      "y": 17,
      "z": -11,
      "name": "Plant_Leaves_Ash",
      "support": 15
    },
    {
      "x": 4,
      "y": 17,
      "z": -10,
      "name": "Plant_Leaves_Ash",
      "support": 15
    },
    {
      "x": 4,
      "y": 16,
      "z": -9,
      "name": "Plant_Leaves_Ash",
      "support": 15
    },
    {
      "x": 4,
      "y": 17,
      "z": -9,
      "name": "Plant_Leaves_Ash",
      "support": 15
    },
    {
      "x": 4,
      "y": 13,
      "z": -8,
      "name": "Wood_Ash_Trunk_Full",
      "support": 15
    },
    {
      "x": 4,
      "y": 14,
      "z": -8,
      "name": "Wood_Ash_Trunk_Full",
      "support": 15
    },
    {
      "x": 4,
      "y": 15,
      "z": -8,
      "name": "Plant_Leaves_Ash",
      "support": 15
    },
    {
      "x": 4,
      "y": 16,
      "z": -8,
      "name": "Plant_Leaves_Ash",
      "support": 15
    },
    {
      "x": 4,
      "y": 17,
      "z": -8,
      "name": "Plant_Leaves_Ash",
      "support": 15
    },
    {
      "x": 4,
      "y": 18,
      "z": -8,
      "name": "Plant_Leaves_Ash",
      "support": 15
    },
    {
      "x": 4,
      "y": 13,
      "z": -7,
      "name": "Wood_Ash_Trunk_Full",
      "support": 15
    },
    {
      "x": 4,
      "y": 14,
      "z": -7,
      "name": "Plant_Leaves_Ash",
      "support": 15
    },
    {
      "x": 4,
      "y": 16,
      "z": -7,
      "name": "Plant_Leaves_Ash",
      "support": 15
    },
    {
      "x": 4,
      "y": 17,
      "z": -7,
      "name": "Plant_Leaves_Ash",
      "support": 15
    },
    {
      "x": 4,
      "y": 14,
      "z": -3,
      "name": "Wood_Ash_Branch_Long",
      "support": 15,
      "rotation": 5
    },
    {
      "x": 4,
      "y": 15,
      "z": -3,
      "name": "Plant_Leaves_Ash",
      "support": 15
    },
    {
      "x": 4,
      "y": 16,
      "z": -3,
      "name": "Plant_Leaves_Ash",
      "support": 15
    },
    {
      "x": 5,
      "y": 16,
      "z": -11,
      "name": "Plant_Leaves_Ash",
      "support": 15
    },
    {
      "x": 5,
      "y": 16,
      "z": -10,
      "name": "Plant_Leaves_Ash",
      "support": 15
    },
    {
      "x": 5,
      "y": 15,
      "z": -9,
      "name": "Plant_Leaves_Ash",
      "support": 15
    },
    {
      "x": 5,
      "y": 16,
      "z": -9,
      "name": "Plant_Leaves_Ash",
      "support": 15
    },
    {
      "x": 5,
      "y": 17,
      "z": -9,
      "name": "Plant_Leaves_Ash",
      "support": 15
    },
    {
      "x": 5,
      "y": 18,
      "z": -9,
      "name": "Plant_Leaves_Ash",
      "support": 15
    },
    {
      "x": 5,
      "y": 14,
      "z": -8,
      "name": "Wood_Ash_Trunk_Full",
      "support": 15
    },
    {
      "x": 5,
      "y": 15,
      "z": -8,
      "name": "Wood_Ash_Trunk_Full",
      "support": 15
    },
    {
      "x": 5,
      "y": 16,
      "z": -8,
      "name": "Wood_Ash_Branch_Long",
      "support": 15
    },
    {
      "x": 5,
      "y": 17,
      "z": -8,
      "name": "Wood_Ash_Branch_Long",
      "support": 15
    },
    {
      "x": 5,
      "y": 18,
      "z": -8,
      "name": "Plant_Leaves_Ash",
      "support": 15
    },
    {
      "x": 5,
      "y": 13,
      "z": -7,
      "name": "Wood_Ash_Branch_Long",
      "support": 15,
      "rotation": 5
    },
    {
      "x": 5,
      "y": 14,
      "z": -7,
      "name": "Plant_Leaves_Ash",
      "support": 15
    },
    {
      "x": 5,
      "y": 15,
      "z": -7,
      "name": "Plant_Leaves_Ash",
      "support": 15
    },
    {
      "x": 5,
      "y": 16,
      "z": -7,
      "name": "Plant_Leaves_Ash",
      "support": 15
    },
    {
      "x": 5,
      "y": 17,
      "z": -7,
      "name": "Plant_Leaves_Ash",
      "support": 15
    },
    {
      "x": 5,
      "y": 18,
      "z": -7,
      "name": "Plant_Leaves_Ash",
      "support": 15
    },
    {
      "x": 5,
      "y": 16,
      "z": -6,
      "name": "Plant_Leaves_Ash",
      "support": 15
    },
    {
      "x": 5,
      "y": 14,
      "z": -3,
      "name": "Wood_Ash_Branch_Long",
      "support": 15,
      "rotation": 5
    },
    {
      "x": 5,
      "y": 15,
      "z": -3,
      "name": "Plant_Leaves_Ash",
      "support": 15
    },
    {
      "x": 5,
      "y": 15,
      "z": -2,
      "name": "Plant_Leaves_Ash",
      "support": 15
    },
    {
      "x": 5,
      "y": 16,
      "z": -2,
      "name": "Plant_Leaves_Ash",
      "support": 15
    },
    {
      "x": 5,
      "y": 15,
      "z": -1,
      "name": "Plant_Leaves_Ash",
      "support": 15
    },
    {
      "x": 6,
      "y": 15,
      "z": -9,
      "name": "Plant_Leaves_Ash",
      "support": 15
    },
    {
      "x": 6,
      "y": 16,
      "z": -9,
      "name": "Plant_Leaves_Ash",
      "support": 15
    },
    {
      "x": 6,
      "y": 17,
      "z": -9,
      "name": "Plant_Leaves_Ash",
      "support": 15
    },
    {
      "x": 6,
      "y": 13,
      "z": -8,
      "name": "Plant_Leaves_Ash",
      "support": 15
    },
    {
      "x": 6,
      "y": 15,
      "z": -8,
      "name": "Wood_Ash_Branch_Long",
      "support": 15,
      "rotation": 5
    },
    {
      "x": 6,
      "y": 16,
      "z": -8,
      "name": "Plant_Leaves_Ash",
      "support": 15
    },
    {
      "x": 6,
      "y": 17,
      "z": -8,
      "name": "Plant_Leaves_Ash",
      "support": 15
    },
    {
      "x": 6,
      "y": 18,
      "z": -8,
      "name": "Plant_Leaves_Ash",
      "support": 15
    },
    {
      "x": 6,
      "y": 13,
      "z": -7,
      "name": "Wood_Ash_Branch_Long",
      "support": 15,
      "rotation": 5
    },
    {
      "x": 6,
      "y": 14,
      "z": -7,
      "name": "Plant_Leaves_Ash",
      "support": 15
    },
    {
      "x": 6,
      "y": 15,
      "z": -7,
      "name": "Plant_Leaves_Ash",
      "support": 15
    },
    {
      "x": 6,
      "y": 16,
      "z": -7,
      "name": "Plant_Leaves_Ash",
      "support": 15
    },
    {
      "x": 6,
      "y": 17,
      "z": -7,
      "name": "Plant_Leaves_Ash",
      "support": 15
    },
    {
      "x": 6,
      "y": 13,
      "z": -6,
      "name": "Plant_Leaves_Ash",
      "support": 15
    },
    {
      "x": 6,
      "y": 14,
      "z": -6,
      "name": "Plant_Leaves_Ash",
      "support": 15
    },
    {
      "x": 6,
      "y": 13,
      "z": -5,
      "name": "Plant_Leaves_Ash",
      "support": 15
    },
    {
      "x": 6,
      "y": 15,
      "z": -4,
      "name": "Plant_Leaves_Ash",
      "support": 15
    },
    {
      "x": 6,
      "y": 14,
      "z": -3,
      "name": "Wood_Ash_Branch_Corner",
      "support": 15,
      "rotation": 1
    },
    {
      "x": 6,
      "y": 15,
      "z": -3,
      "name": "Wood_Ash_Branch_Corner",
      "support": 15,
      "rotation": 8
    },
    {
      "x": 6,
      "y": 16,
      "z": -3,
      "name": "Plant_Leaves_Ash",
      "support": 15
    },
    {
      "x": 6,
      "y": 15,
      "z": -2,
      "name": "Wood_Ash_Branch_Long",
      "support": 15,
      "rotation": 4
    },
    {
      "x": 6,
      "y": 16,
      "z": -2,
      "name": "Plant_Leaves_Ash",
      "support": 15
    },
    {
      "x": 6,
      "y": 15,
      "z": -1,
      "name": "Plant_Leaves_Ash",
      "support": 15
    },
    {
      "x": 6,
      "y": 16,
      "z": -1,
      "name": "Plant_Leaves_Ash",
      "support": 15
    },
    {
      "x": 6,
      "y": 15,
      "z": 0,
      "name": "Plant_Leaves_Ash",
      "support": 15
    },
    {
      "x": 7,
      "y": 15,
      "z": -9,
      "name": "Plant_Leaves_Ash",
      "support": 15
    },
    {
      "x": 7,
      "y": 16,
      "z": -9,
      "name": "Plant_Leaves_Ash",
      "support": 15
    },
    {
      "x": 7,
      "y": 13,
      "z": -8,
      "name": "Plant_Leaves_Ash",
      "support": 15
    },
    {
      "x": 7,
      "y": 15,
      "z": -8,
      "name": "Wood_Ash_Branch_Long",
      "support": 15,
      "rotation": 5
    },
    {
      "x": 7,
      "y": 16,
      "z": -8,
      "name": "Plant_Leaves_Ash",
      "support": 15
    },
    {
      "x": 7,
      "y": 13,
      "z": -7,
      "name": "Plant_Leaves_Ash",
      "support": 15
    },
    {
      "x": 7,
      "y": 14,
      "z": -7,
      "name": "Plant_Leaves_Ash",
      "support": 15
    },
    {
      "x": 7,
      "y": 15,
      "z": -7,
      "name": "Plant_Leaves_Ash",
      "support": 15
    },
    {
      "x": 7,
      "y": 16,
      "z": -7,
      "name": "Plant_Leaves_Ash",
      "support": 15
    },
    {
      "x": 7,
      "y": 13,
      "z": -6,
      "name": "Plant_Leaves_Ash",
      "support": 15
    },
    {
      "x": 7,
      "y": 14,
      "z": -6,
      "name": "Plant_Leaves_Ash",
      "support": 15
    },
    {
      "x": 7,
      "y": 13,
      "z": -5,
      "name": "Plant_Leaves_Ash",
      "support": 15
    },
    {
      "x": 7,
      "y": 15,
      "z": -3,
      "name": "Plant_Leaves_Ash",
      "support": 15
    },
    {
      "x": 7,
      "y": 16,
      "z": -3,
      "name": "Plant_Leaves_Ash",
      "support": 15
    },
    {
      "x": 7,
      "y": 15,
      "z": -2,
      "name": "Plant_Leaves_Ash",
      "support": 15
    },
    {
      "x": 7,
      "y": 16,
      "z": -2,
      "name": "Plant_Leaves_Ash",
      "support": 15
    },
    {
      "x": 7,
      "y": 15,
      "z": -1,
      "name": "Plant_Leaves_Ash",
      "support": 15
    },
    {
      "x": 8,
      "y": 15,
      "z": -9,
      "name": "Plant_Leaves_Ash",
      "support": 15
    },
    {
      "x": 8,
      "y": 15,
      "z": -8,
      "name": "Plant_Leaves_Ash",
      "support": 15
    },
    {
      "x": 8,
      "y": 16,
      "z": -8,
      "name": "Plant_Leaves_Ash",
      "support": 15
    },
    {
      "x": 8,
      "y": 15,
      "z": -7,
      "name": "Plant_Leaves_Ash",
      "support": 15
    },
    {
      "x": 8,
      "y": 15,
      "z": -2,
      "name": "Plant_Leaves_Ash",
      "support": 15
    }
  ]
}