{
  "version": 8,
  "blockIdVersion": 11,
  "anchorX": 1,
  "anchorY": 7,
  "anchorZ": -4,
  "blocks": [
    {
      "x": -3,
      "y": 4,
      "z": -4,
      "name": "Wood_Oak_Trunk"
    },
    {
      "x": -3,
      "y": 5,
      "z": -4,
      "name": "Wood_Oak_Trunk_Full"
    },
    {
      "x": -3,
      "y": 6,
      "z": -4,
      "name": "Soil_Grass_Deep"
    },
    {
      "x": -3,
      "y": 7,
      "z": -4,
      "name": "Plant_Grass_Sharp"
    },
    {
      "x": -3,
      "y": 11,
      "z": -4,
      "name": "Furniture_Kweebec_Platform"
    },
    {
      "x": -3,
      "y": 12,
      "z": -4,
      "name": "Plant_Moss_Rug_Green"
    },
    {
      "x": -3,
      "y": 4,
      "z": -3,
      "name": "Soil_Dirt"
    },
    {
      "x": -3,
      "y": 5,
      "z": -3,
      "name": "Soil_Dirt"
    },
    {
      "x": -3,
      "y": 6,
      "z": -3,
      "name": "Soil_Leaves"
    },
    {
      "x": -3,
      "y": 7,
      "z": -3,
      "name": "Plant_Grass_Sharp_Tall"
    },
    {
      "x": -3,
      "y": 8,
      "z": -3,
      "name": "Plant_Grass_Sharp_Tall",
      "filler": 1024
    },
    {
      "x": -3,
      "y": 11,
      "z": -3,
      "name": "Furniture_Kweebec_Platform"
    },
    {
      "x": -3,
      "y": 5,
      "z": -2,
      "name": "Soil_Dirt"
    },
    {
      "x": -3,
      "y": 6,
      "z": -2,
      "name": "Soil_Leaves"
    },
    {
      "x": -3,
      "y": 4,
      "z": -1,
      "name": "Wood_Oak_Trunk_Full"
    },
    {
      "x": -3,
      "y": 5,
      "z": -1,
      "name": "Soil_Dirt"
    },
    {
      "x": -3,
      "y": 6,
      "z": -1,
      "name": "Soil_Leaves"
    },
    {
      "x": -2,
      "y": 6,
      "z": -7,
      "name": "Soil_Grass_Deep"
    },
    {
      "x": -2,
      "y": 7,
      "z": -7,
      "name": "Wood_Oak_Branch_Corner",
      "rotation": 9
    },
    {
      "x": -2,
      "y": 4,
      "z": -6,
      "name": "Soil_Dirt"
    },
    {
      "x": -2,
      "y": 5,
      "z": -6,
      "name": "Soil_Dirt"
    },
    {
      "x": -2,
      "y": 6,
      "z": -6,
      "name": "Soil_Grass_Deep"
    },
    {
      "x": -2,
      "y": 7,
      "z": -6,
      "name": "Plant_Grass_Sharp"
    },
    {
      "x": -2,
      "y": 4,
      "z": -5,
      "name": "Soil_Dirt"
    },
    {
      "x": -2,
      "y": 5,
      "z": -5,
      "name": "Soil_Dirt"
    },
    {
      "x": -2,
      "y": 6,
      "z": -5,
      "name": "Soil_Grass_Deep"
    },
    {
      "x": -2,
      "y": 7,
      "z": -5,
      "name": "Furniture_Kweebec_Shelf",
      "rotation": 3
    },
    {
      "x": -2,
      "y": 10,
      "z": -5,
      "name": "Wood_Oak_Branch_Long",
      "rotation": 4
    },
    {
      "x": -2,
      "y": 11,
      "z": -5,
      "name": "Furniture_Kweebec_Platform"
    },
    {
      "x": -2,
      "y": 12,
      "z": -5,
      "name": "Plant_Moss_Rug_Green"
    },
    {
      "x": -2,
      "y": 3,
      "z": -4,
      "name": "Soil_Dirt"
    },
    {
      "x": -2,
      "y": 4,
      "z": -4,
      "name": "Soil_Dirt"
    },
    {
      "x": -2,
      "y": 5,
      "z": -4,
      "name": "Wood_Oak_Trunk"
    },
    {
      "x": -2,
      "y": 6,
      "z": -4,
      "name": "Wood_Oak_Trunk"
    },
    {
      "x": -2,
      "y": 7,
      "z": -4,
      "name": "Wood_Oak_Trunk"
    },
    {
      "x": -2,
      "y": 8,
      "z": -4,
      "name": "Wood_Oak_Trunk"
    },
    {
      "x": -2,
      "y": 9,
      "z": -4,
      "name": "Wood_Oak_Trunk"
    },
    {
      "x": -2,
      "y": 10,
      "z": -4,
      "name": "Wood_Oak_Trunk"
    },
    {
      "x": -2,
      "y": 11,
      "z": -4,
      "name": "Wood_Oak_Trunk_Full"
    },
    {
      "x": -2,
      "y": 12,
      "z": -4,
      "name": "Plant_Moss_Rug_Green"
    },
    {
      "x": -2,
      "y": 3,
      "z": -3,
      "name": "Soil_Dirt"
    },
    {
      "x": -2,
      "y": 4,
      "z": -3,
      "name": "Soil_Dirt"
    },
    {
      "x": -2,
      "y": 5,
      "z": -3,
      "name": "Wood_Oak_Trunk",
      "rotation": 4
    },
    {
      "x": -2,
      "y": 6,
      "z": -3,
      "name": "Soil_Grass_Deep"
    },
    {
      "x": -2,
      "y": 7,
      "z": -3,
      "name": "Plant_Grass_Sharp"
    },
    {
      "x": -2,
      "y": 11,
      "z": -3,
      "name": "Furniture_Kweebec_Platform"
    },
    {
      "x": -2,
      "y": 12,
      "z": -3,
      "name": "Plant_Moss_Rug_Green"
    },
    {
      "x": -2,
      "y": 4,
      "z": -2,
      "name": "Wood_Oak_Trunk_Full"
    },
    {
      "x": -2,
      "y": 5,
      "z": -2,
      "name": "Wood_Oak_Trunk_Full"
    },
    {
      "x": -2,
      "y": 6,
      "z": -2,
      "name": "Soil_Leaves"
    },
    {
      "x": -2,
      "y": 7,
      "z": -2,
      "name": "Wood_Oak_Branch_Corner",
      "rotation": 3
    },
    {
      "x": -2,
      "y": 8,
      "z": -2,
      "name": "Plant_Flower_Bushy_Green",
      "components": {
        "Components": {
          "FarmingBlock": {}
        }
      }
    },
    {
      "x": -2,
      "y": 11,
      "z": -2,
      "name": "Furniture_Kweebec_Platform"
    },
    {
      "x": -2,
      "y": 4,
      "z": -1,
      "name": "Wood_Oak_Trunk_Full"
    },
    {
      "x": -2,
      "y": 5,
      "z": -1,
      "name": "Soil_Dirt"
    },
    {
      "x": -2,
      "y": 6,
      "z": -1,
      "name": "Soil_Leaves"
    },
    {
      "x": -1,
      "y": 5,
      "z": -7,
      "name": "Soil_Dirt"
    },
    {
      "x": -1,
      "y": 6,
      "z": -7,
      "name": "Soil_Dirt"
    },
    {
      "x": -1,
      "y": 7,
      "z": -7,
      "name": "Wood_Oak_Trunk",
      "rotation": 4
    },
    {
      "x": -1,
      "y": 3,
      "z": -6,
      "name": "Soil_Dirt"
    },
    {
      "x": -1,
      "y": 4,
      "z": -6,
      "name": "Soil_Dirt"
    },
    {
      "x": -1,
      "y": 5,
      "z": -6,
      "name": "Soil_Dirt"
    },
    {
      "x": -1,
      "y": 6,
      "z": -6,
      "name": "Soil_Dirt"
    },
    {
      "x": -1,
      "y": 7,
      "z": -6,
      "name": "Wood_Oak_Trunk",
      "rotation": 4
    },
    {
      "x": -1,
      "y": 8,
      "z": -6,
      "name": "*Plant_Crop_Pumpkin_Block_State_Definitions_StageFinal"
    },
    {
      "x": -1,
      "y": 3,
      "z": -5,
      "name": "Soil_Dirt"
    },
    {
      "x": -1,
      "y": 4,
      "z": -5,
      "name": "Soil_Dirt"
    },
    {
      "x": -1,
      "y": 5,
      "z": -5,
      "name": "Soil_Dirt"
    },
    {
      "x": -1,
      "y": 6,
      "z": -5,
      "name": "Soil_Dirt"
    },
    {
      "x": -1,
      "y": 7,
      "z": -5,
      "name": "Wood_Oak_Trunk",
      "rotation": 4
    },
    {
      "x": -1,
      "y": 8,
      "z": -5,
      "name": "*Plant_Crop_Pumpkin_Block_State_Definitions_Stage2",
      "components": {
        "Components": {
          "FarmingBlock": {
            "GrowthProgress": 2.0,
            "LastTickGameTime": "0001-01-01T12:00:00Z"
          }
        }
      }
    },
    {
      "x": -1,
      "y": 11,
      "z": -5,
      "name": "Furniture_Kweebec_Platform"
    },
    {
      "x": -1,
      "y": 3,
      "z": -4,
      "name": "Soil_Dirt"
    },
    {
      "x": -1,
      "y": 4,
      "z": -4,
      "name": "Soil_Dirt"
    },
    {
      "x": -1,
      "y": 5,
      "z": -4,
      "name": "Soil_Dirt"
    },
    {
      "x": -1,
      "y": 6,
      "z": -4,
      "name": "Soil_Dirt"
    },
    {
      "x": -1,
      "y": 7,
      "z": -4,
      "name": "Wood_Oak_Trunk",
      "rotation": 4
    },
    {
      "x": -1,
      "y": 11,
      "z": -4,
      "name": "Furniture_Kweebec_Platform"
    },
    {
      "x": -1,
      "y": 12,
      "z": -4,
      "name": "Plant_Moss_Rug_Green"
    },
    {
      "x": -1,
      "y": 3,
      "z": -3,
      "name": "Soil_Dirt"
    },
    {
      "x": -1,
      "y": 4,
      "z": -3,
      "name": "Soil_Dirt"
    },
    {
      "x": -1,
      "y": 5,
      "z": -3,
      "name": "Soil_Dirt"
    },
    {
      "x": -1,
      "y": 6,
      "z": -3,
      "name": "Soil_Dirt"
    },
    {
      "x": -1,
      "y": 7,
      "z": -3,
      "name": "Soil_Clay_Brick_Half"
    },
    {
      "x": -1,
      "y": 11,
      "z": -3,
      "name": "Furniture_Kweebec_Platform"
    },
    {
      "x": -1,
      "y": 12,
      "z": -3,
      "name": "Plant_Moss_Rug_Green"
    },
    {
      "x": -1,
      "y": 3,
      "z": -2,
      "name": "Soil_Dirt"
    },
    {
      "x": -1,
      "y": 4,
      "z": -2,
      "name": "Soil_Dirt"
    },
    {
      "x": -1,
      "y": 5,
      "z": -2,
      "name": "Soil_Dirt"
    },
    {
      "x": -1,
      "y": 6,
      "z": -2,
      "name": "Soil_Dirt"
    },
    {
      "x": -1,
      "y": 7,
      "z": -2,
      "name": "Wood_Oak_Trunk",
      "rotation": 5
    },
    {
      "x": -1,
      "y": 11,
      "z": -2,
      "name": "Furniture_Kweebec_Platform"
    },
    {
      "x": -1,
      "y": 4,
      "z": -1,
      "name": "Soil_Dirt"
    },
    {
      "x": -1,
      "y": 5,
      "z": -1,
      "name": "Soil_Dirt"
    },
    {
      "x": -1,
      "y": 6,
      "z": -1,
      "name": "Soil_Leaves"
    },
    {
      "x": -1,
      "y": 7,
      "z": -1,
      "name": "Plant_Grass_Sharp"
    },
    {
      "x": 0,
      "y": 5,
      "z": -7,
      "name": "Soil_Dirt"
    },
    {
      "x": 0,
      "y": 6,
      "z": -7,
      "name": "Soil_Leaves"
    },
    {
      "x": 0,
      "y": 7,
      "z": -7,
      "name": "Furniture_Kweebec_Shelf",
      "rotation": 2
    },
    {
      "x": 0,
      "y": 3,
      "z": -6,
      "name": "Soil_Dirt"
    },
    {
      "x": 0,
      "y": 4,
      "z": -6,
      "name": "Soil_Dirt"
    },
    {
      "x": 0,
      "y": 5,
      "z": -6,
      "name": "Soil_Dirt"
    },
    {
      "x": 0,
      "y": 6,
      "z": -6,
      "name": "Soil_Dirt"
    },
    {
      "x": 0,
      "y": 7,
      "z": -6,
      "name": "Wood_Oak_Trunk",
      "rotation": 5
    },
    {
      "x": 0,
      "y": 3,
      "z": -5,
      "name": "Soil_Dirt"
    },
    {
      "x": 0,
      "y": 4,
      "z": -5,
      "name": "Soil_Dirt"
    },
    {
      "x": 0,
      "y": 5,
      "z": -5,
      "name": "Soil_Dirt"
    },
    {
      "x": 0,
      "y": 6,
      "z": -5,
      "name": "Soil_Dirt"
    },
    {
      "x": 0,
      "y": 7,
      "z": -5,
      "name": "Soil_Clay_Brick_Half"
    },
    {
      "x": 0,
      "y": 3,
      "z": -4,
      "name": "Soil_Dirt"
    },
    {
      "x": 0,
      "y": 4,
      "z": -4,
      "name": "Soil_Dirt"
    },
    {
      "x": 0,
      "y": 5,
      "z": -4,
      "name": "Soil_Dirt"
    },
    {
      "x": 0,
      "y": 6,
      "z": -4,
      "name": "Soil_Dirt"
    },
    {
      "x": 0,
      "y": 7,
      "z": -4,
      "name": "Soil_Clay_Brick_Half"
    },
    {
      "x": 0,
      "y": 11,
      "z": -4,
      "name": "Furniture_Kweebec_Platform"
    },
    {
      "x": 0,
      "y": 3,
      "z": -3,
      "name": "Soil_Dirt"
    },
    {
      "x": 0,
      "y": 4,
      "z": -3,
      "name": "Soil_Dirt"
    },
    {
      "x": 0,
      "y": 5,
      "z": -3,
      "name": "Soil_Dirt"
    },
    {
      "x": 0,
      "y": 6,
      "z": -3,
      "name": "Soil_Dirt"
    },
    {
      "x": 0,
      "y": 7,
      "z": -3,
      "name": "Soil_Clay_Brick_Half"
    },
    {
      "x": 0,
      "y": 11,
      "z": -3,
      "name": "Furniture_Kweebec_Platform"
    },
    {
      "x": 0,
      "y": 12,
      "z": -3,
      "name": "Plant_Moss_Rug_Green"
    },
    {
      "x": 0,
      "y": 3,
      "z": -2,
      "name": "Soil_Dirt"
    },
    {
      "x": 0,
      "y": 4,
      "z": -2,
      "name": "Soil_Dirt"
    },
    {
      "x": 0,
      "y": 5,
      "z": -2,
      "name": "Soil_Dirt"
    },
    {
      "x": 0,
      "y": 6,
      "z": -2,
      "name": "Soil_Dirt"
    },
    {
      "x": 0,
      "y": 7,
      "z": -2,
      "name": "Wood_Oak_Trunk",
      "rotation": 5
    },
    {
      "x": 0,
      "y": 8,
      "z": -2,
      "name": "*Plant_Crop_Pumpkin_Block_State_Definitions_Stage2",
      "components": {
        "Components": {
          "FarmingBlock": {
            "GrowthProgress": 2.0,
            "LastTickGameTime": "0001-01-01T12:00:00Z"
          }
        }
      }
    },
    {
      "x": 0,
      "y": 11,
      "z": -2,
      "name": "Furniture_Kweebec_Platform"
    },
    {
      "x": 0,
      "y": 4,
      "z": -1,
      "name": "Soil_Dirt"
    },
    {
      "x": 0,
      "y": 5,
      "z": -1,
      "name": "Soil_Dirt"
    },
    {
      "x": 0,
      "y": 6,
      "z": -1,
      "name": "Soil_Grass_Deep"
    },
    {
      "x": 0,
      "y": 7,
      "z": -1,
      "name": "Furniture_Kweebec_Shelf"
    },
    {
      "x": 0,
      "y": 11,
      "z": -1,
      "name": "Furniture_Kweebec_Platform"
    },
    {
      "x": 1,
      "y": 4,
      "z": -7,
      "name": "Soil_Dirt"
    },
    {
      "x": 1,
      "y": 5,
      "z": -7,
      "name": "Soil_Dirt"
    },
    {
      "x": 1,
      "y": 6,
      "z": -7,
      "name": "Soil_Leaves"
    },
    {
      "x": 1,
      "y": 7,
      "z": -7,
      "name": "Furniture_Kweebec_Shelf",
      "rotation": 2
    },
    {
      "x": 1,
      "y": 3,
      "z": -6,
      "name": "Soil_Dirt"
    },
    {
      "x": 1,
      "y": 4,
      "z": -6,
      "name": "Soil_Dirt"
    },
    {
      "x": 1,
      "y": 5,
      "z": -6,
      "name": "Soil_Dirt"
    },
    {
      "x": 1,
      "y": 6,
      "z": -6,
      "name": "Soil_Dirt"
    },
    {
      "x": 1,
      "y": 7,
      "z": -6,
      "name": "Wood_Oak_Trunk",
      "rotation": 5
    },
    {
      "x": 1,
      "y": 3,
      "z": -5,
      "name": "Soil_Dirt"
    },
    {
      "x": 1,
      "y": 4,
      "z": -5,
      "name": "Soil_Dirt"
    },
    {
      "x": 1,
      "y": 5,
      "z": -5,
      "name": "Soil_Dirt"
    },
    {
      "x": 1,
      "y": 6,
      "z": -5,
      "name": "Soil_Dirt"
    },
    {
      "x": 1,
      "y": 7,
      "z": -5,
      "name": "Soil_Clay_Brick_Half"
    },
    {
      "x": 1,
      "y": 3,
      "z": -4,
      "name": "Soil_Dirt"
    },
    {
      "x": 1,
      "y": 4,
      "z": -4,
      "name": "Soil_Dirt"
    },
    {
      "x": 1,
      "y": 5,
      "z": -4,
      "name": "Soil_Dirt"
    },
    {
      "x": 1,
      "y": 6,
      "z": -4,
      "name": "Soil_Dirt"
    },
    {
      "x": 1,
      "y": 7,
      "z": -4,
      "name": "Block_Spawner_Block",
      "components": {
        "Components": {
          "BlockSpawner": {
            "BlockSpawnerId": "Zone1_Kweebec_Tier1"
          }
        }
      },
      "rotation": 1
    },
    {
      "x": 1,
      "y": 11,
      "z": -4,
      "name": "Furniture_Kweebec_Platform"
    },
    {
      "x": 1,
      "y": 3,
      "z": -3,
      "name": "Soil_Dirt"
    },
    {
      "x": 1,
      "y": 4,
      "z": -3,
      "name": "Soil_Dirt"
    },
    {
      "x": 1,
      "y": 5,
      "z": -3,
      "name": "Soil_Dirt"
    },
    {
      "x": 1,
      "y": 6,
      "z": -3,
      "name": "Soil_Dirt"
    },
    {
      "x": 1,
      "y": 7,
      "z": -3,
      "name": "Soil_Clay_Brick_Half"
    },
    {
      "x": 1,
      "y": 11,
      "z": -3,
      "name": "Furniture_Kweebec_Platform"
    },
    {
      "x": 1,
      "y": 3,
      "z": -2,
      "name": "Soil_Dirt"
    },
    {
      "x": 1,
      "y": 4,
      "z": -2,
      "name": "Soil_Dirt"
    },
    {
      "x": 1,
      "y": 5,
      "z": -2,
      "name": "Soil_Dirt"
    },
    {
      "x": 1,
      "y": 6,
      "z": -2,
      "name": "Soil_Dirt"
    },
    {
      "x": 1,
      "y": 7,
      "z": -2,
      "name": "Wood_Oak_Trunk",
      "rotation": 5
    },
    {
      "x": 1,
      "y": 8,
      "z": -2,
      "name": "*Plant_Crop_Pumpkin_Block_State_Definitions_Stage2",
      "components": {
        "Components": {
          "FarmingBlock": {
            "GrowthProgress": 2.0,
            "LastTickGameTime": "0001-01-01T12:00:00Z"
          }
        }
      }
    },
    {
      "x": 1,
      "y": 11,
      "z": -2,
      "name": "Furniture_Kweebec_Platform"
    },
    {
      "x": 1,
      "y": 4,
      "z": -1,
      "name": "Soil_Pathway"
    },
    {
      "x": 1,
      "y": 5,
      "z": -1,
      "name": "Soil_Dirt"
    },
    {
      "x": 1,
      "y": 6,
      "z": -1,
      "name": "Soil_Grass_Deep"
    },
    {
      "x": 1,
      "y": 7,
      "z": -1,
      "name": "Furniture_Kweebec_Shelf"
    },
    {
      "x": 1,
      "y": 11,
      "z": -1,
      "name": "Furniture_Kweebec_Platform"
    },
    {
      "x": 1,
      "y": 12,
      "z": -1,
      "name": "Plant_Moss_Rug_Green"
    },
    {
      "x": 2,
      "y": 4,
      "z": -7,
      "name": "Soil_Dirt"
    },
    {
      "x": 2,
      "y": 5,
      "z": -7,
      "name": "Soil_Dirt"
    },
    {
      "x": 2,
      "y": 6,
      "z": -7,
      "name": "Soil_Grass_Deep"
    },
    {
      "x": 2,
      "y": 7,
      "z": -7,
      "name": "Plant_Grass_Sharp"
    },
    {
      "x": 2,
      "y": 11,
      "z": -7,
      "name": "Furniture_Kweebec_Lantern"
    },
    {
      "x": 2,
      "y": 12,
      "z": -7,
      "name": "Wood_Oak_Branch_Corner",
      "rotation": 8
    },
    {
      "x": 2,
      "y": 4,
      "z": -6,
      "name": "Soil_Dirt"
    },
    {
      "x": 2,
      "y": 5,
      "z": -6,
      "name": "Soil_Dirt"
    },
    {
      "x": 2,
      "y": 6,
      "z": -6,
      "name": "Soil_Dirt"
    },
    {
      "x": 2,
      "y": 7,
      "z": -6,
      "name": "Wood_Oak_Trunk",
      "rotation": 5
    },
    {
      "x": 2,
      "y": 8,
      "z": -6,
      "name": "*Plant_Crop_Pumpkin_Block_State_Definitions_Stage2",
      "components": {
        "Components": {
          "FarmingBlock": {
            "GrowthProgress": 2.0,
            "LastTickGameTime": "0001-01-01T12:00:00Z"
          }
        }
      }
    },
    {
      "x": 2,
      "y": 11,
      "z": -6,
      "name": "Wood_Oak_Branch_Corner",
      "rotation": 3
    },
    {
      "x": 2,
      "y": 12,
      "z": -6,
      "name": "Wood_Oak_Branch_Corner",
      "rotation": 10
    },
    {
      "x": 2,
      "y": 3,
      "z": -5,
      "name": "Soil_Dirt"
    },
    {
      "x": 2,
      "y": 4,
      "z": -5,
      "name": "Soil_Dirt"
    },
    {
      "x": 2,
      "y": 5,
      "z": -5,
      "name": "Soil_Dirt"
    },
    {
      "x": 2,
      "y": 6,
      "z": -5,
      "name": "Soil_Dirt"
    },
    {
      "x": 2,
      "y": 7,
      "z": -5,
      "name": "Soil_Clay_Brick_Half"
    },
    {
      "x": 2,
      "y": 3,
      "z": -4,
      "name": "Soil_Dirt"
    },
    {
      "x": 2,
      "y": 4,
      "z": -4,
      "name": "Soil_Dirt"
    },
    {
      "x": 2,
      "y": 5,
      "z": -4,
      "name": "Soil_Dirt"
    },
    {
      "x": 2,
      "y": 6,
      "z": -4,
      "name": "Soil_Dirt"
    },
    {
      "x": 2,
      "y": 7,
      "z": -4,
      "name": "Soil_Clay_Brick_Half"
    },
    {
      "x": 2,
      "y": 3,
      "z": -3,
      "name": "Soil_Dirt"
    },
    {
      "x": 2,
      "y": 4,
      "z": -3,
      "name": "Soil_Dirt"
    },
    {
      "x": 2,
      "y": 5,
      "z": -3,
      "name": "Soil_Dirt"
    },
    {
      "x": 2,
      "y": 6,
      "z": -3,
      "name": "Soil_Dirt"
    },
    {
      "x": 2,
      "y": 7,
      "z": -3,
      "name": "Soil_Clay_Brick_Half"
    },
    {
      "x": 2,
      "y": 4,
      "z": -2,
      "name": "Soil_Dirt"
    },
    {
      "x": 2,
      "y": 5,
      "z": -2,
      "name": "Soil_Dirt"
    },
    {
      "x": 2,
      "y": 6,
      "z": -2,
      "name": "Soil_Dirt"
    },
    {
      "x": 2,
      "y": 7,
      "z": -2,
      "name": "Soil_Clay_Brick_Half"
    },
    {
      "x": 2,
      "y": 10,
      "z": -2,
      "name": "Wood_Oak_Trunk_Full"
    },
    {
      "x": 2,
      "y": 11,
      "z": -2,
      "name": "Wood_Oak_Trunk"
    },
    {
      "x": 2,
      "y": 12,
      "z": -2,
      "name": "Wood_Oak_Trunk"
    },
    {
      "x": 2,
      "y": 5,
      "z": -1,
      "name": "Wood_Oak_Trunk"
    },
    {
      "x": 2,
      "y": 6,
      "z": -1,
      "name": "Wood_Oak_Trunk"
    },
    {
      "x": 2,
      "y": 7,
      "z": -1,
      "name": "Wood_Oak_Trunk"
    },
    {
      "x": 2,
      "y": 8,
      "z": -1,
      "name": "Wood_Oak_Trunk"
    },
    {
      "x": 2,
      "y": 9,
      "z": -1,
      "name": "Wood_Oak_Trunk"
    },
    {
      "x": 2,
      "y": 10,
      "z": -1,
      "name": "Wood_Oak_Trunk_Full"
    },
    {
      "x": 3,
      "y": 5,
      "z": -7,
      "name": "Soil_Dirt"
    },
    {
      "x": 3,
      "y": 6,
      "z": -7,
      "name": "Soil_Grass_Deep"
    },
    {
      "x": 3,
      "y": 7,
      "z": -7,
      "name": "Wood_Oak_Branch_Short",
      "rotation": 2
    },
    {
      "x": 3,
      "y": 4,
      "z": -6,
      "name": "Soil_Dirt"
    },
    {
      "x": 3,
      "y": 5,
      "z": -6,
      "name": "Soil_Dirt"
    },
    {
      "x": 3,
      "y": 6,
      "z": -6,
      "name": "Soil_Dirt"
    },
    {
      "x": 3,
      "y": 7,
      "z": -6,
      "name": "Wood_Oak_Trunk_Full"
    },
    {
      "x": 3,
      "y": 8,
      "z": -6,
      "name": "Wood_Oak_Trunk_Full"
    },
    {
      "x": 3,
      "y": 9,
      "z": -6,
      "name": "Wood_Oak_Branch_Long"
    },
    {
      "x": 3,
      "y": 10,
      "z": -6,
      "name": "Wood_Oak_Branch_Long"
    },
    {
      "x": 3,
      "y": 11,
      "z": -6,
      "name": "Wood_Oak_Branch_Corner",
      "rotation": 11
    },
    {
      "x": 3,
      "y": 4,
      "z": -5,
      "name": "Soil_Dirt"
    },
    {
      "x": 3,
      "y": 5,
      "z": -5,
      "name": "Soil_Dirt"
    },
    {
      "x": 3,
      "y": 6,
      "z": -5,
      "name": "Soil_Dirt"
    },
    {
      "x": 3,
      "y": 7,
      "z": -5,
      "name": "Wood_Oak_Trunk",
      "rotation": 4
    },
    {
      "x": 3,
      "y": 8,
      "z": -5,
      "name": "Wood_Oak_Branch_Corner"
    },
    {
      "x": 3,
      "y": 9,
      "z": -5,
      "name": "Wood_Oak_Branch_Long"
    },
    {
      "x": 3,
      "y": 10,
      "z": -5,
      "name": "Plant_Flower_Bushy_Green",
      "components": {
        "Components": {
          "FarmingBlock": {}
        }
      }
    },
    {
      "x": 3,
      "y": 4,
      "z": -4,
      "name": "Soil_Dirt"
    },
    {
      "x": 3,
      "y": 5,
      "z": -4,
      "name": "Soil_Dirt"
    },
    {
      "x": 3,
      "y": 6,
      "z": -4,
      "name": "Soil_Dirt"
    },
    {
      "x": 3,
      "y": 7,
      "z": -4,
      "name": "Soil_Clay_Brick_Half"
    },
    {
      "x": 3,
      "y": 4,
      "z": -3,
      "name": "Soil_Pathway"
    },
    {
      "x": 3,
      "y": 5,
      "z": -3,
      "name": "Soil_Dirt"
    },
    {
      "x": 3,
      "y": 6,
      "z": -3,
      "name": "Soil_Leaves"
    },
    {
      "x": 3,
      "y": 5,
      "z": -2,
      "name": "Soil_Dirt"
    },
    {
      "x": 3,
      "y": 6,
      "z": -2,
      "name": "Soil_Leaves"
    },
    {
      "x": 3,
      "y": 6,
      "z": -1,
      "name": "Soil_Leaves"
    },
    {
      "x": 3,
      "y": 7,
      "z": -1,
      "name": "Plant_Grass_Sharp_Tall"
    },
    {
      "x": 3,
      "y": 8,
      "z": -1,
      "name": "Plant_Grass_Sharp_Tall",
      "filler": 1024
    },
    {
      "x": 3,
      "y": 10,
      "z": -1,
      "name": "Wood_Oak_Branch_Corner",
      "rotation": 1
    },
    {
      "x": 4,
      "y": 4,
      "z": -4,
      "name": "Soil_Pathway"
    },
    {
      "x": 4,
      "y": 6,
      "z": -4,
      "name": "Soil_Leaves"
    },
    {
      "x": 4,
      "y": 7,
      "z": -4,
      "name": "Plant_Grass_Sharp_Tall"
    },
    {
      "x": 4,
      "y": 8,
      "z": -4,
      "name": "Plant_Grass_Sharp_Tall",
      "filler": 1024
    },
    {
      "x": 4,
      "y": 6,
      "z": -3,
      "name": "Soil_Leaves"
    },
    {
      "x": 4,
      "y": 7,
      "z": -3,
      "name": "Plant_Grass_Sharp"
    }
  ],
  "entities": [
    {
      "Components": {
        "Nameplate": {
          "Text": "Kweebec_Merchant"
        },
        "HiddenFromAdventurePlayer": {},
        "SpawnMarkerComponent": {
          "SpawnMarker": "Kweebec_Merchant",
          "RespawnTime": 0.0,
          "SpawnCount": 0,
          "NPCReferences": [],
          "PersistedFlock": {},
          "SpawnPosition": {
            "X": 0.0,
            "Y": 0.0,
            "Z": 0.0
          }
        },
        "Transform": {
          "Position": {
            "X": 3.7090530395507812,
            "Y": 7.209564208984375,
            "Z": -2.1590576171875
          },
          "Rotation": {
            "Pitch": 0.0,
            "Yaw": -1.5042080879211426,
            "Roll": 0.0
          }
        },
        "Intangible": {},
        "PrefabCopyable": {},
        "Model": {
          "Model": {
            "Id": "NPC_Spawn_Marker",
            "Scale": 1.0,
            "Static": false
          }
        },
        "UUID": {
          "UUID": {
            "$binary": "j7XIyD9MPYOQGnDtR5hOsg==",
            "$type": "04"
          }
        }
      }
    }
  ]
}