{
  "version": 8,
  "blockIdVersion": 11,
  "anchorX": 1,
  "anchorY": 5,
  "anchorZ": -4,
  "blocks": [
    {
      "x": -7,
      "y": 4,
      "z": -14,
      "name": "Rock_Stone_Brick"
    },
    {
      "x": -7,
      "y": 4,
      "z": -13,
      "name": "Rock_Stone_Brick"
    },
    {
      "x": -7,
      "y": 4,
      "z": -12,
      "name": "Rock_Stone_Brick"
    },
    {
      "x": -7,
      "y": 4,
      "z": -11,
      "name": "Rock_Stone_Brick"
    },
    {
      "x": -7,
      "y": 4,
      "z": -10,
      "name": "Rock_Stone_Brick"
    },
    {
      "x": -7,
      "y": 4,
      "z": -9,
      "name": "Rock_Stone_Brick"
    },
    {
      "x": -7,
      "y": 4,
      "z": -8,
      "name": "Rock_Stone_Brick"
    },
    {
      "x": -6,
      "y": 4,
      "z": -15,
      "name": "Rock_Stone_Brick"
    },
    {
      "x": -6,
      "y": 4,
      "z": -14,
      "name": "Rock_Stone_Brick"
    },
    {
      "x": -6,
      "y": 4,
      "z": -13,
      "name": "Rock_Stone_Brick"
    },
    {
      "x": -6,
      "y": 4,
      "z": -12,
      "name": "Rock_Stone_Brick"
    },
    {
      "x": -6,
      "y": 4,
      "z": -11,
      "name": "Rock_Stone_Brick"
    },
    {
      "x": -6,
      "y": 4,
      "z": -10,
      "name": "Rock_Stone_Brick"
    },
    {
      "x": -6,
      "y": 4,
      "z": -9,
      "name": "Rock_Stone_Brick"
    },
    {
      "x": -6,
      "y": 4,
      "z": -8,
      "name": "Rock_Stone_Brick"
    },
    {
      "x": -6,
      "y": 4,
      "z": -7,
      "name": "Rock_Stone_Brick"
    },
    {
      "x": -5,
      "y": 4,
      "z": -16,
      "name": "Rock_Stone_Brick"
    },
    {
      "x": -5,
      "y": 4,
      "z": -15,
      "name": "Rock_Stone_Brick"
    },
    {
      "x": -5,
      "y": 4,
      "z": -14,
      "name": "Rock_Stone_Brick"
    },
    {
      "x": -5,
      "y": 4,
      "z": -13,
      "name": "Rock_Stone_Brick"
    },
    {
      "x": -5,
      "y": 5,
      "z": -13,
      "name": "Furniture_Castle_Bench",
      "filler": 992,
      "rotation": 3
    },
    {
      "x": -5,
      "y": 4,
      "z": -12,
      "name": "Rock_Stone_Brick"
    },
    {
      "x": -5,
      "y": 5,
      "z": -12,
      "name": "Furniture_Castle_Bench",
      "rotation": 3
    },
    {
      "x": -5,
      "y": 4,
      "z": -11,
      "name": "Rock_Stone_Brick"
    },
    {
      "x": -5,
      "y": 5,
      "z": -11,
      "name": "Furniture_Village_Brazier"
    },
    {
      "x": -5,
      "y": 4,
      "z": -10,
      "name": "Rock_Stone_Brick"
    },
    {
      "x": -5,
      "y": 5,
      "z": -10,
      "name": "Furniture_Castle_Bench",
      "filler": 992,
      "rotation": 3
    },
    {
      "x": -5,
      "y": 4,
      "z": -9,
      "name": "Rock_Stone_Brick"
    },
    {
      "x": -5,
      "y": 5,
      "z": -9,
      "name": "Furniture_Castle_Bench",
      "rotation": 3
    },
    {
      "x": -5,
      "y": 4,
      "z": -8,
      "name": "Rock_Stone_Brick"
    },
    {
      "x": -5,
      "y": 4,
      "z": -7,
      "name": "Rock_Stone_Brick"
    },
    {
      "x": -5,
      "y": 4,
      "z": -6,
      "name": "Rock_Stone_Brick"
    },
    {
      "x": -4,
      "y": 4,
      "z": -17,
      "name": "Rock_Stone_Brick"
    },
    {
      "x": -4,
      "y": 4,
      "z": -16,
      "name": "Rock_Stone_Brick"
    },
    {
      "x": -4,
      "y": 4,
      "z": -15,
      "name": "Rock_Stone_Brick"
    },
    {
      "x": -4,
      "y": 4,
      "z": -14,
      "name": "Soil_Grass_Deep"
    },
    {
      "x": -4,
      "y": 5,
      "z": -14,
      "name": "Plant_Fern_Forest"
    },
    {
      "x": -4,
      "y": 4,
      "z": -13,
      "name": "Soil_Grass_Deep"
    },
    {
      "x": -4,
      "y": 5,
      "z": -13,
      "name": "Plant_Flower_Flax_White"
    },
    {
      "x": -4,
      "y": 4,
      "z": -12,
      "name": "Soil_Grass_Deep"
    },
    {
      "x": -4,
      "y": 5,
      "z": -12,
      "name": "Plant_Flower_Common_Violet"
    },
    {
      "x": -4,
      "y": 4,
      "z": -11,
      "name": "Soil_Grass_Deep"
    },
    {
      "x": -4,
      "y": 5,
      "z": -11,
      "name": "Plant_Fern_Forest"
    },
    {
      "x": -4,
      "y": 4,
      "z": -10,
      "name": "Soil_Grass_Deep"
    },
    {
      "x": -4,
      "y": 5,
      "z": -10,
      "name": "Plant_Flower_Common_Purple"
    },
    {
      "x": -4,
      "y": 4,
      "z": -9,
      "name": "Soil_Grass_Deep"
    },
    {
      "x": -4,
      "y": 5,
      "z": -9,
      "name": "Plant_Fern_Forest"
    },
    {
      "x": -4,
      "y": 4,
      "z": -8,
      "name": "Soil_Grass_Deep"
    },
    {
      "x": -4,
      "y": 5,
      "z": -8,
      "name": "Plant_Flower_Orchid_Pink"
    },
    {
      "x": -4,
      "y": 4,
      "z": -7,
      "name": "Rock_Stone_Brick"
    },
    {
      "x": -4,
      "y": 4,
      "z": -6,
      "name": "Rock_Stone_Brick"
    },
    {
      "x": -4,
      "y": 4,
      "z": -5,
      "name": "Rock_Stone_Brick"
    },
    {
      "x": -3,
      "y": 4,
      "z": -18,
      "name": "Rock_Stone_Brick"
    },
    {
      "x": -3,
      "y": 4,
      "z": -17,
      "name": "Rock_Stone_Brick"
    },
    {
      "x": -3,
      "y": 4,
      "z": -16,
      "name": "Rock_Stone_Brick"
    },
    {
      "x": -3,
      "y": 4,
      "z": -15,
      "name": "Soil_Grass_Deep"
    },
    {
      "x": -3,
      "y": 5,
      "z": -15,
      "name": "Plant_Fern_Forest"
    },
    {
      "x": -3,
      "y": 4,
      "z": -14,
      "name": "Soil_Grass_Deep"
    },
    {
      "x": -3,
      "y": 5,
      "z": -14,
      "name": "Plant_Flower_Flax_White"
    },
    {
      "x": -3,
      "y": 4,
      "z": -13,
      "name": "Soil_Grass_Deep"
    },
    {
      "x": -3,
      "y": 5,
      "z": -13,
      "name": "Plant_Flower_Common_Violet"
    },
    {
      "x": -3,
      "y": 4,
      "z": -12,
      "name": "Soil_Grass_Deep"
    },
    {
      "x": -3,
      "y": 5,
      "z": -12,
      "name": "Plant_Fern_Forest"
    },
    {
      "x": -3,
      "y": 4,
      "z": -11,
      "name": "Soil_Grass_Deep"
    },
    {
      "x": -3,
      "y": 5,
      "z": -11,
      "name": "Plant_Flower_Common_Purple"
    },
    {
      "x": -3,
      "y": 4,
      "z": -10,
      "name": "Soil_Grass_Deep"
    },
    {
      "x": -3,
      "y": 5,
      "z": -10,
      "name": "Plant_Flower_Flax_White"
    },
    {
      "x": -3,
      "y": 4,
      "z": -9,
      "name": "Soil_Grass_Deep"
    },
    {
      "x": -3,
      "y": 5,
      "z": -9,
      "name": "Plant_Flower_Orchid_Pink"
    },
    {
      "x": -3,
      "y": 4,
      "z": -8,
      "name": "Soil_Grass_Deep"
    },
    {
      "x": -3,
      "y": 5,
      "z": -8,
      "name": "Plant_Flower_Flax_White"
    },
    {
      "x": -3,
      "y": 4,
      "z": -7,
      "name": "Soil_Grass_Deep"
    },
    {
      "x": -3,
      "y": 5,
      "z": -7,
      "name": "Plant_Fern_Forest"
    },
    {
      "x": -3,
      "y": 4,
      "z": -6,
      "name": "Rock_Stone_Brick"
    },
    {
      "x": -3,
      "y": 4,
      "z": -5,
      "name": "Rock_Stone_Brick"
    },
    {
      "x": -3,
      "y": 4,
      "z": -4,
      "name": "Rock_Stone_Brick"
    },
    {
      "x": -2,
      "y": 4,
      "z": -19,
      "name": "Rock_Stone_Brick"
    },
    {
      "x": -2,
      "y": 4,
      "z": -18,
      "name": "Rock_Stone_Brick"
    },
    {
      "x": -2,
      "y": 4,
      "z": -17,
      "name": "Rock_Stone_Brick"
    },
    {
      "x": -2,
      "y": 4,
      "z": -16,
      "name": "Soil_Grass_Deep"
    },
    {
      "x": -2,
      "y": 5,
      "z": -16,
      "name": "Plant_Flower_Common_White2"
    },
    {
      "x": -2,
      "y": 4,
      "z": -15,
      "name": "Soil_Grass_Deep"
    },
    {
      "x": -2,
      "y": 5,
      "z": -15,
      "name": "Plant_Flower_Flax_White"
    },
    {
      "x": -2,
      "y": 4,
      "z": -14,
      "name": "Soil_Grass_Deep"
    },
    {
      "x": -2,
      "y": 5,
      "z": -14,
      "name": "Plant_Flower_Orchid_White"
    },
    {
      "x": -2,
      "y": 4,
      "z": -13,
      "name": "Rock_Stone_Brick"
    },
    {
      "x": -2,
      "y": 4,
      "z": -12,
      "name": "Rock_Stone_Brick"
    },
    {
      "x": -2,
      "y": 4,
      "z": -11,
      "name": "Rock_Stone_Brick"
    },
    {
      "x": -2,
      "y": 4,
      "z": -10,
      "name": "Rock_Stone_Brick"
    },
    {
      "x": -2,
      "y": 4,
      "z": -9,
      "name": "Rock_Stone_Brick"
    },
    {
      "x": -2,
      "y": 4,
      "z": -8,
      "name": "Soil_Grass_Deep"
    },
    {
      "x": -2,
      "y": 5,
      "z": -8,
      "name": "Plant_Flower_Orchid_Pink"
    },
    {
      "x": -2,
      "y": 4,
      "z": -7,
      "name": "Soil_Grass_Deep"
    },
    {
      "x": -2,
      "y": 5,
      "z": -7,
      "name": "Plant_Flower_Common_Pink2"
    },
    {
      "x": -2,
      "y": 4,
      "z": -6,
      "name": "Soil_Grass_Deep"
    },
    {
      "x": -2,
      "y": 5,
      "z": -6,
      "name": "Plant_Fern_Forest"
    },
    {
      "x": -2,
      "y": 4,
      "z": -5,
      "name": "Rock_Stone_Brick"
    },
    {
      "x": -2,
      "y": 4,
      "z": -4,
      "name": "Rock_Stone_Brick"
    },
    {
      "x": -2,
      "y": 4,
      "z": -3,
      "name": "Rock_Stone_Brick"
    },
    {
      "x": -1,
      "y": 4,
      "z": -19,
      "name": "Rock_Stone_Brick"
    },
    {
      "x": -1,
      "y": 4,
      "z": -18,
      "name": "Rock_Stone_Brick"
    },
    {
      "x": -1,
      "y": 4,
      "z": -17,
      "name": "Rock_Stone_Brick"
    },
    {
      "x": -1,
      "y": 5,
      "z": -17,
      "name": "Furniture_Castle_Bench",
      "rotation": 2
    },
    {
      "x": -1,
      "y": 4,
      "z": -16,
      "name": "Soil_Grass_Deep"
    },
    {
      "x": -1,
      "y": 5,
      "z": -16,
      "name": "Plant_Fern_Forest"
    },
    {
      "x": -1,
      "y": 4,
      "z": -15,
      "name": "Soil_Grass_Deep"
    },
    {
      "x": -1,
      "y": 5,
      "z": -15,
      "name": "Plant_Flower_Common_White2"
    },
    {
      "x": -1,
      "y": 4,
      "z": -14,
      "name": "Rock_Stone_Brick"
    },
    {
      "x": -1,
      "y": 4,
      "z": -13,
      "name": "Rock_Stone_Brick"
    },
    {
      "x": -1,
      "y": 4,
      "z": -12,
      "name": "Rock_Stone_Brick"
    },
    {
      "x": -1,
      "y": 4,
      "z": -11,
      "name": "Rock_Stone_Brick"
    },
    {
      "x": -1,
      "y": 4,
      "z": -10,
      "name": "Rock_Stone_Brick"
    },
    {
      "x": -1,
      "y": 4,
      "z": -9,
      "name": "Rock_Stone_Brick"
    },
    {
      "x": -1,
      "y": 4,
      "z": -8,
      "name": "Rock_Stone_Brick"
    },
    {
      "x": -1,
      "y": 4,
      "z": -7,
      "name": "Soil_Grass_Deep"
    },
    {
      "x": -1,
      "y": 5,
      "z": -7,
      "name": "Plant_Fern_Forest"
    },
    {
      "x": -1,
      "y": 4,
      "z": -6,
      "name": "Soil_Grass_Deep"
    },
    {
      "x": -1,
      "y": 5,
      "z": -6,
      "name": "Plant_Flower_Common_Pink2"
    },
    {
      "x": -1,
      "y": 4,
      "z": -5,
      "name": "Rock_Stone_Brick"
    },
    {
      "x": -1,
      "y": 4,
      "z": -4,
      "name": "Rock_Stone_Brick"
    },
    {
      "x": -1,
      "y": 4,
      "z": -3,
      "name": "Rock_Stone_Brick"
    },
    {
      "x": -1,
      "y": 4,
      "z": -2,
      "name": "Rock_Stone_Brick"
    },
    {
      "x": -1,
      "y": 5,
      "z": -2,
      "name": "Furniture_Village_Brazier"
    },
    {
      "x": -1,
      "y": 4,
      "z": -1,
      "name": "Rock_Stone_Brick"
    },
    {
      "x": -1,
      "y": 5,
      "z": -1,
      "name": "Rock_Stone_Brick_Pillar_Base"
    },
    {
      "x": -1,
      "y": 6,
      "z": -1,
      "name": "Rock_Stone_Brick_Pillar_Middle"
    },
    {
      "x": -1,
      "y": 7,
      "z": -1,
      "name": "Rock_Stone_Brick_Pillar_Middle"
    },
    {
      "x": -1,
      "y": 8,
      "z": -1,
      "name": "Rock_Stone_Brick_Pillar_Base",
      "rotation": 8
    },
    {
      "x": -1,
      "y": 4,
      "z": 0,
      "name": "Rock_Stone_Brick"
    },
    {
      "x": -1,
      "y": 5,
      "z": 0,
      "name": "Rock_Stone_Brick"
    },
    {
      "x": -1,
      "y": 4,
      "z": 1,
      "name": "Rock_Stone_Brick"
    },
    {
      "x": -1,
      "y": 5,
      "z": 1,
      "name": "Rock_Stone_Brick"
    },
    {
      "x": -1,
      "y": 6,
      "z": 1,
      "name": "Rock_Stone_Brick_Half"
    },
    {
      "x": -1,
      "y": 4,
      "z": 2,
      "name": "Rock_Stone_Brick"
    },
    {
      "x": -1,
      "y": 5,
      "z": 2,
      "name": "Rock_Stone_Brick"
    },
    {
      "x": -1,
      "y": 6,
      "z": 2,
      "name": "Rock_Stone_Brick"
    },
    {
      "x": -1,
      "y": 4,
      "z": 3,
      "name": "Rock_Stone_Brick"
    },
    {
      "x": -1,
      "y": 5,
      "z": 3,
      "name": "Rock_Stone_Brick"
    },
    {
      "x": -1,
      "y": 6,
      "z": 3,
      "name": "Rock_Stone_Brick"
    },
    {
      "x": -1,
      "y": 7,
      "z": 3,
      "name": "Rock_Stone_Brick_Pillar_Base"
    },
    {
      "x": -1,
      "y": 8,
      "z": 3,
      "name": "Rock_Stone_Brick_Pillar_Middle"
    },
    {
      "x": -1,
      "y": 9,
      "z": 3,
      "name": "Rock_Stone_Brick_Pillar_Middle"
    },
    {
      "x": -1,
      "y": 10,
      "z": 3,
      "name": "Rock_Stone_Brick_Pillar_Base",
      "rotation": 8
    },
    {
      "x": -1,
      "y": 4,
      "z": 4,
      "name": "Rock_Stone_Brick"
    },
    {
      "x": -1,
      "y": 5,
      "z": 4,
      "name": "Rock_Stone_Brick"
    },
    {
      "x": -1,
      "y": 6,
      "z": 4,
      "name": "Rock_Stone_Brick"
    },
    {
      "x": -1,
      "y": 7,
      "z": 4,
      "name": "Rock_Stone_Brick"
    },
    {
      "x": -1,
      "y": 4,
      "z": 5,
      "name": "Rock_Stone_Brick"
    },
    {
      "x": -1,
      "y": 5,
      "z": 5,
      "name": "Rock_Stone_Brick"
    },
    {
      "x": -1,
      "y": 6,
      "z": 5,
      "name": "Rock_Stone_Brick"
    },
    {
      "x": -1,
      "y": 7,
      "z": 5,
      "name": "Rock_Stone_Brick"
    },
    {
      "x": -1,
      "y": 4,
      "z": 6,
      "name": "Rock_Stone_Brick"
    },
    {
      "x": -1,
      "y": 5,
      "z": 6,
      "name": "Rock_Stone_Brick"
    },
    {
      "x": -1,
      "y": 6,
      "z": 6,
      "name": "Rock_Stone_Brick"
    },
    {
      "x": -1,
      "y": 7,
      "z": 6,
      "name": "Rock_Stone_Brick"
    },
    {
      "x": -1,
      "y": 4,
      "z": 7,
      "name": "Rock_Stone_Brick"
    },
    {
      "x": -1,
      "y": 5,
      "z": 7,
      "name": "Rock_Stone_Brick"
    },
    {
      "x": -1,
      "y": 6,
      "z": 7,
      "name": "Rock_Stone_Brick"
    },
    {
      "x": -1,
      "y": 7,
      "z": 7,
      "name": "Rock_Stone_Brick"
    },
    {
      "x": -1,
      "y": 4,
      "z": 8,
      "name": "Rock_Stone_Brick"
    },
    {
      "x": -1,
      "y": 5,
      "z": 8,
      "name": "Rock_Stone_Brick"
    },
    {
      "x": -1,
      "y": 6,
      "z": 8,
      "name": "Rock_Stone_Brick"
    },
    {
      "x": -1,
      "y": 7,
      "z": 8,
      "name": "Rock_Stone_Brick"
    },
    {
      "x": 0,
      "y": 4,
      "z": -19,
      "name": "Rock_Stone_Brick"
    },
    {
      "x": 0,
      "y": 4,
      "z": -18,
      "name": "Rock_Stone_Brick"
    },
    {
      "x": 0,
      "y": 4,
      "z": -17,
      "name": "Rock_Stone_Brick"
    },
    {
      "x": 0,
      "y": 5,
      "z": -17,
      "name": "Furniture_Castle_Bench",
      "filler": 1,
      "rotation": 2
    },
    {
      "x": 0,
      "y": 4,
      "z": -16,
      "name": "Soil_Grass_Deep"
    },
    {
      "x": 0,
      "y": 5,
      "z": -16,
      "name": "Plant_Flower_Common_White2"
    },
    {
      "x": 0,
      "y": 4,
      "z": -15,
      "name": "Soil_Grass_Deep"
    },
    {
      "x": 0,
      "y": 5,
      "z": -15,
      "name": "Plant_Flower_Orchid_White"
    },
    {
      "x": 0,
      "y": 4,
      "z": -14,
      "name": "Rock_Stone_Brick"
    },
    {
      "x": 0,
      "y": 4,
      "z": -13,
      "name": "Rock_Stone_Brick"
    },
    {
      "x": 0,
      "y": 3,
      "z": -12,
      "name": "Rock_Stone_Brick_Smooth"
    },
    {
      "x": 0,
      "y": 3,
      "z": -11,
      "name": "Rock_Stone_Brick_Smooth"
    },
    {
      "x": 0,
      "y": 3,
      "z": -10,
      "name": "Rock_Stone_Brick_Smooth"
    },
    {
      "x": 0,
      "y": 4,
      "z": -9,
      "name": "Rock_Stone_Brick"
    },
    {
      "x": 0,
      "y": 4,
      "z": -8,
      "name": "Rock_Stone_Brick"
    },
    {
      "x": 0,
      "y": 4,
      "z": -7,
      "name": "Rock_Stone_Brick"
    },
    {
      "x": 0,
      "y": 4,
      "z": -6,
      "name": "Rock_Stone_Brick"
    },
    {
      "x": 0,
      "y": 4,
      "z": -5,
      "name": "Rock_Stone_Brick"
    },
    {
      "x": 0,
      "y": 4,
      "z": -4,
      "name": "Rock_Stone_Brick"
    },
    {
      "x": 0,
      "y": 4,
      "z": -3,
      "name": "Rock_Stone_Brick"
    },
    {
      "x": 0,
      "y": 4,
      "z": -2,
      "name": "Rock_Stone_Brick"
    },
    {
      "x": 0,
      "y": 4,
      "z": -1,
      "name": "Rock_Stone_Brick"
    },
    {
      "x": 0,
      "y": 5,
      "z": -1,
      "name": "Rock_Stone_Brick_Half"
    },
    {
      "x": 0,
      "y": 4,
      "z": 0,
      "name": "Rock_Stone_Brick"
    },
    {
      "x": 0,
      "y": 5,
      "z": 0,
      "name": "Rock_Stone_Brick"
    },
    {
      "x": 0,
      "y": 4,
      "z": 1,
      "name": "Rock_Stone_Brick"
    },
    {
      "x": 0,
      "y": 5,
      "z": 1,
      "name": "Rock_Stone_Brick"
    },
    {
      "x": 0,
      "y": 6,
      "z": 1,
      "name": "Rock_Stone_Brick_Half"
    },
    {
      "x": 0,
      "y": 4,
      "z": 2,
      "name": "Rock_Stone_Brick"
    },
    {
      "x": 0,
      "y": 5,
      "z": 2,
      "name": "Rock_Stone_Brick"
    },
    {
      "x": 0,
      "y": 6,
      "z": 2,
      "name": "Rock_Stone_Brick"
    },
    {
      "x": 0,
      "y": 4,
      "z": 3,
      "name": "Rock_Stone_Brick"
    },
    {
      "x": 0,
      "y": 5,
      "z": 3,
      "name": "Rock_Stone_Brick"
    },
    {
      "x": 0,
      "y": 6,
      "z": 3,
      "name": "Rock_Stone_Brick"
    },
    {
      "x": 0,
      "y": 7,
      "z": 3,
      "name": "Rock_Stone_Brick_Half"
    },
    {
      "x": 0,
      "y": 4,
      "z": 4,
      "name": "Rock_Stone_Brick"
    },
    {
      "x": 0,
      "y": 5,
      "z": 4,
      "name": "Rock_Stone_Brick"
    },
    {
      "x": 0,
      "y": 6,
      "z": 4,
      "name": "Rock_Stone_Brick"
    },
    {
      "x": 0,
      "y": 7,
      "z": 4,
      "name": "Rock_Stone_Brick"
    },
    {
      "x": 0,
      "y": 4,
      "z": 5,
      "name": "Rock_Stone_Brick"
    },
    {
      "x": 0,
      "y": 5,
      "z": 5,
      "name": "Rock_Stone_Brick"
    },
    {
      "x": 0,
      "y": 6,
      "z": 5,
      "name": "Rock_Stone_Brick"
    },
    {
      "x": 0,
      "y": 7,
      "z": 5,
      "name": "Rock_Stone_Brick"
    },
    {
      "x": 0,
      "y": 8,
      "z": 5,
      "name": "Forgotten_Temple_Portal_Exit",
      "filler": 1023,
      "rotation": 2
    },
    {
      "x": 0,
      "y": 4,
      "z": 6,
      "name": "Rock_Stone_Brick"
    },
    {
      "x": 0,
      "y": 5,
      "z": 6,
      "name": "Rock_Stone_Brick"
    },
    {
      "x": 0,
      "y": 6,
      "z": 6,
      "name": "Rock_Stone_Brick"
    },
    {
      "x": 0,
      "y": 7,
      "z": 6,
      "name": "Rock_Stone_Brick"
    },
    {
      "x": 0,
      "y": 8,
      "z": 6,
      "name": "Forgotten_Temple_Portal_Exit",
      "filler": 31,
      "rotation": 2
    },
    {
      "x": 0,
      "y": 4,
      "z": 7,
      "name": "Rock_Stone_Brick"
    },
    {
      "x": 0,
      "y": 5,
      "z": 7,
      "name": "Rock_Stone_Brick"
    },
    {
      "x": 0,
      "y": 6,
      "z": 7,
      "name": "Rock_Stone_Brick"
    },
    {
      "x": 0,
      "y": 7,
      "z": 7,
      "name": "Rock_Stone_Brick"
    },
    {
      "x": 0,
      "y": 8,
      "z": 7,
      "name": "Forgotten_Temple_Portal_Exit",
      "filler": 63,
      "rotation": 2
    },
    {
      "x": 0,
      "y": 4,
      "z": 8,
      "name": "Rock_Stone_Brick"
    },
    {
      "x": 0,
      "y": 5,
      "z": 8,
      "name": "Rock_Stone_Brick"
    },
    {
      "x": 0,
      "y": 6,
      "z": 8,
      "name": "Rock_Stone_Brick"
    },
    {
      "x": 0,
      "y": 7,
      "z": 8,
      "name": "Rock_Stone_Brick"
    },
    {
      "x": 1,
      "y": 4,
      "z": -19,
      "name": "Rock_Stone_Brick"
    },
    {
      "x": 1,
      "y": 4,
      "z": -18,
      "name": "Rock_Stone_Brick"
    },
    {
      "x": 1,
      "y": 4,
      "z": -17,
      "name": "Rock_Stone_Brick"
    },
    {
      "x": 1,
      "y": 5,
      "z": -17,
      "name": "Furniture_Village_Brazier"
    },
    {
      "x": 1,
      "y": 4,
      "z": -16,
      "name": "Soil_Grass_Deep"
    },
    {
      "x": 1,
      "y": 5,
      "z": -16,
      "name": "Plant_Fern_Forest"
    },
    {
      "x": 1,
      "y": 4,
      "z": -15,
      "name": "Soil_Grass_Deep"
    },
    {
      "x": 1,
      "y": 5,
      "z": -15,
      "name": "Plant_Flower_Orchid_Red"
    },
    {
      "x": 1,
      "y": 4,
      "z": -14,
      "name": "Rock_Stone_Brick"
    },
    {
      "x": 1,
      "y": 4,
      "z": -13,
      "name": "Rock_Stone_Brick"
    },
    {
      "x": 1,
      "y": 3,
      "z": -12,
      "name": "Rock_Stone_Brick_Smooth"
    },
    {
      "x": 1,
      "y": 3,
      "z": -11,
      "name": "Rock_Stone_Brick_Smooth"
    },
    {
      "x": 1,
      "y": 4,
      "z": -11,
      "name": "Rock_Stone_Brick_Smooth"
    },
    {
      "x": 1,
      "y": 5,
      "z": -11,
      "name": "Furniture_Temple_Light_Statue"
    },
    {
      "x": 1,
      "y": 6,
      "z": -11,
      "name": "Furniture_Temple_Light_Statue",
      "filler": 1024
    },
    {
      "x": 1,
      "y": 7,
      "z": -11,
      "name": "Furniture_Temple_Light_Statue",
      "filler": 2048
    },
    {
      "x": 1,
      "y": 3,
      "z": -10,
      "name": "Rock_Stone_Brick_Smooth"
    },
    {
      "x": 1,
      "y": 4,
      "z": -9,
      "name": "Rock_Stone_Brick"
    },
    {
      "x": 1,
      "y": 4,
      "z": -8,
      "name": "Rock_Stone_Brick"
    },
    {
      "x": 1,
      "y": 4,
      "z": -7,
      "name": "Rock_Stone_Brick"
    },
    {
      "x": 1,
      "y": 4,
      "z": -6,
      "name": "Rock_Stone_Brick"
    },
    {
      "x": 1,
      "y": 4,
      "z": -5,
      "name": "Rock_Stone_Brick"
    },
    {
      "x": 1,
      "y": 4,
      "z": -4,
      "name": "Rock_Stone_Brick"
    },
    {
      "x": 1,
      "y": 5,
      "z": -4,
      "name": "Empty"
    },
    {
      "x": 1,
      "y": 4,
      "z": -3,
      "name": "Rock_Stone_Brick"
    },
    {
      "x": 1,
      "y": 4,
      "z": -2,
      "name": "Rock_Stone_Brick"
    },
    {
      "x": 1,
      "y": 4,
      "z": -1,
      "name": "Rock_Stone_Brick"
    },
    {
      "x": 1,
      "y": 5,
      "z": -1,
      "name": "Rock_Stone_Brick_Half"
    },
    {
      "x": 1,
      "y": 4,
      "z": 0,
      "name": "Rock_Stone_Brick"
    },
    {
      "x": 1,
      "y": 5,
      "z": 0,
      "name": "Rock_Stone_Brick"
    },
    {
      "x": 1,
      "y": 4,
      "z": 1,
      "name": "Rock_Stone_Brick"
    },
    {
      "x": 1,
      "y": 5,
      "z": 1,
      "name": "Rock_Stone_Brick"
    },
    {
      "x": 1,
      "y": 6,
      "z": 1,
      "name": "Rock_Stone_Brick_Half"
    },
    {
      "x": 1,
      "y": 4,
      "z": 2,
      "name": "Rock_Stone_Brick"
    },
    {
      "x": 1,
      "y": 5,
      "z": 2,
      "name": "Rock_Stone_Brick"
    },
    {
      "x": 1,
      "y": 6,
      "z": 2,
      "name": "Rock_Stone_Brick"
    },
    {
      "x": 1,
      "y": 4,
      "z": 3,
      "name": "Rock_Stone_Brick"
    },
    {
      "x": 1,
      "y": 5,
      "z": 3,
      "name": "Rock_Stone_Brick"
    },
    {
      "x": 1,
      "y": 6,
      "z": 3,
      "name": "Rock_Stone_Brick"
    },
    {
      "x": 1,
      "y": 7,
      "z": 3,
      "name": "Rock_Stone_Brick_Half"
    },
    {
      "x": 1,
      "y": 4,
      "z": 4,
      "name": "Rock_Stone_Brick"
    },
    {
      "x": 1,
      "y": 5,
      "z": 4,
      "name": "Rock_Stone_Brick"
    },
    {
      "x": 1,
      "y": 6,
      "z": 4,
      "name": "Rock_Stone_Brick"
    },
    {
      "x": 1,
      "y": 7,
      "z": 4,
      "name": "Rock_Stone_Brick"
    },
    {
      "x": 1,
      "y": 4,
      "z": 5,
      "name": "Rock_Stone_Brick"
    },
    {
      "x": 1,
      "y": 5,
      "z": 5,
      "name": "Rock_Stone_Brick"
    },
    {
      "x": 1,
      "y": 6,
      "z": 5,
      "name": "Rock_Stone_Brick"
    },
    {
      "x": 1,
      "y": 7,
      "z": 5,
      "name": "Rock_Stone_Brick"
    },
    {
      "x": 1,
      "y": 8,
      "z": 5,
      "name": "Forgotten_Temple_Portal_Exit",
      "filler": 992,
      "rotation": 2
    },
    {
      "x": 1,
      "y": 4,
      "z": 6,
      "name": "Rock_Stone_Brick"
    },
    {
      "x": 1,
      "y": 5,
      "z": 6,
      "name": "Rock_Stone_Brick"
    },
    {
      "x": 1,
      "y": 6,
      "z": 6,
      "name": "Rock_Stone_Brick"
    },
    {
      "x": 1,
      "y": 7,
      "z": 6,
      "name": "Rock_Stone_Brick"
    },
    {
      "x": 1,
      "y": 8,
      "z": 6,
      "name": "Forgotten_Temple_Portal_Exit",
      "rotation": 2
    },
    {
      "x": 1,
      "y": 4,
      "z": 7,
      "name": "Rock_Stone_Brick"
    },
    {
      "x": 1,
      "y": 5,
      "z": 7,
      "name": "Rock_Stone_Brick"
    },
    {
      "x": 1,
      "y": 6,
      "z": 7,
      "name": "Rock_Stone_Brick"
    },
    {
      "x": 1,
      "y": 7,
      "z": 7,
      "name": "Rock_Stone_Brick"
    },
    {
      "x": 1,
      "y": 8,
      "z": 7,
      "name": "Forgotten_Temple_Portal_Exit",
      "filler": 32,
      "rotation": 2
    },
    {
      "x": 1,
      "y": 4,
      "z": 8,
      "name": "Rock_Stone_Brick"
    },
    {
      "x": 1,
      "y": 5,
      "z": 8,
      "name": "Rock_Stone_Brick"
    },
    {
      "x": 1,
      "y": 6,
      "z": 8,
      "name": "Rock_Stone_Brick"
    },
    {
      "x": 1,
      "y": 7,
      "z": 8,
      "name": "Rock_Stone_Brick"
    },
    {
      "x": 2,
      "y": 4,
      "z": -19,
      "name": "Rock_Stone_Brick"
    },
    {
      "x": 2,
      "y": 4,
      "z": -18,
      "name": "Rock_Stone_Brick"
    },
    {
      "x": 2,
      "y": 4,
      "z": -17,
      "name": "Rock_Stone_Brick"
    },
    {
      "x": 2,
      "y": 5,
      "z": -17,
      "name": "Furniture_Castle_Bench",
      "rotation": 2
    },
    {
      "x": 2,
      "y": 4,
      "z": -16,
      "name": "Soil_Grass_Deep"
    },
    {
      "x": 2,
      "y": 5,
      "z": -16,
      "name": "Plant_Flower_Orchid_Red"
    },
    {
      "x": 2,
      "y": 4,
      "z": -15,
      "name": "Soil_Grass_Deep"
    },
    {
      "x": 2,
      "y": 5,
      "z": -15,
      "name": "Plant_Flower_Flax_White"
    },
    {
      "x": 2,
      "y": 4,
      "z": -14,
      "name": "Rock_Stone_Brick"
    },
    {
      "x": 2,
      "y": 4,
      "z": -13,
      "name": "Rock_Stone_Brick"
    },
    {
      "x": 2,
      "y": 3,
      "z": -12,
      "name": "Rock_Stone_Brick_Smooth"
    },
    {
      "x": 2,
      "y": 3,
      "z": -11,
      "name": "Rock_Stone_Brick_Smooth"
    },
    {
      "x": 2,
      "y": 3,
      "z": -10,
      "name": "Rock_Stone_Brick_Smooth"
    },
    {
      "x": 2,
      "y": 4,
      "z": -9,
      "name": "Rock_Stone_Brick"
    },
    {
      "x": 2,
      "y": 4,
      "z": -8,
      "name": "Rock_Stone_Brick"
    },
    {
      "x": 2,
      "y": 4,
      "z": -7,
      "name": "Rock_Stone_Brick"
    },
    {
      "x": 2,
      "y": 4,
      "z": -6,
      "name": "Rock_Stone_Brick"
    },
    {
      "x": 2,
      "y": 4,
      "z": -5,
      "name": "Rock_Stone_Brick"
    },
    {
      "x": 2,
      "y": 4,
      "z": -4,
      "name": "Rock_Stone_Brick"
    },
    {
      "x": 2,
      "y": 4,
      "z": -3,
      "name": "Rock_Stone_Brick"
    },
    {
      "x": 2,
      "y": 4,
      "z": -2,
      "name": "Rock_Stone_Brick"
    },
    {
      "x": 2,
      "y": 4,
      "z": -1,
      "name": "Rock_Stone_Brick"
    },
    {
      "x": 2,
      "y": 5,
      "z": -1,
      "name": "Rock_Stone_Brick_Half"
    },
    {
      "x": 2,
      "y": 4,
      "z": 0,
      "name": "Rock_Stone_Brick"
    },
    {
      "x": 2,
      "y": 5,
      "z": 0,
      "name": "Rock_Stone_Brick"
    },
    {
      "x": 2,
      "y": 4,
      "z": 1,
      "name": "Rock_Stone_Brick"
    },
    {
      "x": 2,
      "y": 5,
      "z": 1,
      "name": "Rock_Stone_Brick"
    },
    {
      "x": 2,
      "y": 6,
      "z": 1,
      "name": "Rock_Stone_Brick_Half"
    },
    {
      "x": 2,
      "y": 4,
      "z": 2,
      "name": "Rock_Stone_Brick"
    },
    {
      "x": 2,
      "y": 5,
      "z": 2,
      "name": "Rock_Stone_Brick"
    },
    {
      "x": 2,
      "y": 6,
      "z": 2,
      "name": "Rock_Stone_Brick"
    },
    {
      "x": 2,
      "y": 4,
      "z": 3,
      "name": "Rock_Stone_Brick"
    },
    {
      "x": 2,
      "y": 5,
      "z": 3,
      "name": "Rock_Stone_Brick"
    },
    {
      "x": 2,
      "y": 6,
      "z": 3,
      "name": "Rock_Stone_Brick"
    },
    {
      "x": 2,
      "y": 7,
      "z": 3,
      "name": "Rock_Stone_Brick_Half"
    },
    {
      "x": 2,
      "y": 4,
      "z": 4,
      "name": "Rock_Stone_Brick"
    },
    {
      "x": 2,
      "y": 5,
      "z": 4,
      "name": "Rock_Stone_Brick"
    },
    {
      "x": 2,
      "y": 6,
      "z": 4,
      "name": "Rock_Stone_Brick"
    },
    {
      "x": 2,
      "y": 7,
      "z": 4,
      "name": "Rock_Stone_Brick"
    },
    {
      "x": 2,
      "y": 4,
      "z": 5,
      "name": "Rock_Stone_Brick"
    },
    {
      "x": 2,
      "y": 5,
      "z": 5,
      "name": "Rock_Stone_Brick"
    },
    {
      "x": 2,
      "y": 6,
      "z": 5,
      "name": "Rock_Stone_Brick"
    },
    {
      "x": 2,
      "y": 7,
      "z": 5,
      "name": "Rock_Stone_Brick"
    },
    {
      "x": 2,
      "y": 8,
      "z": 5,
      "name": "Forgotten_Temple_Portal_Exit",
      "filler": 993,
      "rotation": 2
    },
    {
      "x": 2,
      "y": 4,
      "z": 6,
      "name": "Rock_Stone_Brick"
    },
    {
      "x": 2,
      "y": 5,
      "z": 6,
      "name": "Rock_Stone_Brick"
    },
    {
      "x": 2,
      "y": 6,
      "z": 6,
      "name": "Rock_Stone_Brick"
    },
    {
      "x": 2,
      "y": 7,
      "z": 6,
      "name": "Rock_Stone_Brick"
    },
    {
      "x": 2,
      "y": 8,
      "z": 6,
      "name": "Forgotten_Temple_Portal_Exit",
      "filler": 1,
      "rotation": 2
    },
    {
      "x": 2,
      "y": 4,
      "z": 7,
      "name": "Rock_Stone_Brick"
    },
    {
      "x": 2,
      "y": 5,
      "z": 7,
      "name": "Rock_Stone_Brick"
    },
    {
      "x": 2,
      "y": 6,
      "z": 7,
      "name": "Rock_Stone_Brick"
    },
    {
      "x": 2,
      "y": 7,
      "z": 7,
      "name": "Rock_Stone_Brick"
    },
    {
      "x": 2,
      "y": 8,
      "z": 7,
      "name": "Forgotten_Temple_Portal_Exit",
      "filler": 33,
      "rotation": 2
    },
    {
      "x": 2,
      "y": 4,
      "z": 8,
      "name": "Rock_Stone_Brick"
    },
    {
      "x": 2,
      "y": 5,
      "z": 8,
      "name": "Rock_Stone_Brick"
    },
    {
      "x": 2,
      "y": 6,
      "z": 8,
      "name": "Rock_Stone_Brick"
    },
    {
      "x": 2,
      "y": 7,
      "z": 8,
      "name": "Rock_Stone_Brick"
    },
    {
      "x": 3,
      "y": 4,
      "z": -19,
      "name": "Rock_Stone_Brick"
    },
    {
      "x": 3,
      "y": 4,
      "z": -18,
      "name": "Rock_Stone_Brick"
    },
    {
      "x": 3,
      "y": 4,
      "z": -17,
      "name": "Rock_Stone_Brick"
    },
    {
      "x": 3,
      "y": 5,
      "z": -17,
      "name": "Furniture_Castle_Bench",
      "filler": 1,
      "rotation": 2
    },
    {
      "x": 3,
      "y": 4,
      "z": -16,
      "name": "Soil_Grass_Deep"
    },
    {
      "x": 3,
      "y": 5,
      "z": -16,
      "name": "Plant_Fern_Forest"
    },
    {
      "x": 3,
      "y": 4,
      "z": -15,
      "name": "Soil_Grass_Deep"
    },
    {
      "x": 3,
      "y": 5,
      "z": -15,
      "name": "Plant_Flower_Common_Red2"
    },
    {
      "x": 3,
      "y": 4,
      "z": -14,
      "name": "Rock_Stone_Brick"
    },
    {
      "x": 3,
      "y": 4,
      "z": -13,
      "name": "Rock_Stone_Brick"
    },
    {
      "x": 3,
      "y": 4,
      "z": -12,
      "name": "Rock_Stone_Brick"
    },
    {
      "x": 3,
      "y": 4,
      "z": -11,
      "name": "Rock_Stone_Brick"
    },
    {
      "x": 3,
      "y": 4,
      "z": -10,
      "name": "Rock_Stone_Brick"
    },
    {
      "x": 3,
      "y": 4,
      "z": -9,
      "name": "Rock_Stone_Brick"
    },
    {
      "x": 3,
      "y": 4,
      "z": -8,
      "name": "Rock_Stone_Brick"
    },
    {
      "x": 3,
      "y": 4,
      "z": -7,
      "name": "Soil_Grass_Deep"
    },
    {
      "x": 3,
      "y": 5,
      "z": -7,
      "name": "Plant_Fern_Forest"
    },
    {
      "x": 3,
      "y": 4,
      "z": -6,
      "name": "Soil_Grass_Deep"
    },
    {
      "x": 3,
      "y": 5,
      "z": -6,
      "name": "Plant_Flower_Common_Orange"
    },
    {
      "x": 3,
      "y": 4,
      "z": -5,
      "name": "Rock_Stone_Brick"
    },
    {
      "x": 3,
      "y": 4,
      "z": -4,
      "name": "Rock_Stone_Brick"
    },
    {
      "x": 3,
      "y": 4,
      "z": -3,
      "name": "Rock_Stone_Brick"
    },
    {
      "x": 3,
      "y": 4,
      "z": -2,
      "name": "Rock_Stone_Brick"
    },
    {
      "x": 3,
      "y": 5,
      "z": -2,
      "name": "Furniture_Village_Brazier"
    },
    {
      "x": 3,
      "y": 4,
      "z": -1,
      "name": "Rock_Stone_Brick"
    },
    {
      "x": 3,
      "y": 5,
      "z": -1,
      "name": "Rock_Stone_Brick_Pillar_Base"
    },
    {
      "x": 3,
      "y": 6,
      "z": -1,
      "name": "Rock_Stone_Brick_Pillar_Middle"
    },
    {
      "x": 3,
      "y": 7,
      "z": -1,
      "name": "Rock_Stone_Brick_Pillar_Middle"
    },
    {
      "x": 3,
      "y": 8,
      "z": -1,
      "name": "Rock_Stone_Brick_Pillar_Base",
      "rotation": 8
    },
    {
      "x": 3,
      "y": 4,
      "z": 0,
      "name": "Rock_Stone_Brick"
    },
    {
      "x": 3,
      "y": 5,
      "z": 0,
      "name": "Rock_Stone_Brick"
    },
    {
      "x": 3,
      "y": 4,
      "z": 1,
      "name": "Rock_Stone_Brick"
    },
    {
      "x": 3,
      "y": 5,
      "z": 1,
      "name": "Rock_Stone_Brick"
    },
    {
      "x": 3,
      "y": 6,
      "z": 1,
      "name": "Rock_Stone_Brick_Half"
    },
    {
      "x": 3,
      "y": 4,
      "z": 2,
      "name": "Rock_Stone_Brick"
    },
    {
      "x": 3,
      "y": 5,
      "z": 2,
      "name": "Rock_Stone_Brick"
    },
    {
      "x": 3,
      "y": 6,
      "z": 2,
      "name": "Rock_Stone_Brick"
    },
    {
      "x": 3,
      "y": 4,
      "z": 3,
      "name": "Rock_Stone_Brick"
    },
    {
      "x": 3,
      "y": 5,
      "z": 3,
      "name": "Rock_Stone_Brick"
    },
    {
      "x": 3,
      "y": 6,
      "z": 3,
      "name": "Rock_Stone_Brick"
    },
    {
      "x": 3,
      "y": 7,
      "z": 3,
      "name": "Rock_Stone_Brick_Pillar_Base"
    },
    {
      "x": 3,
      "y": 8,
      "z": 3,
      "name": "Rock_Stone_Brick_Pillar_Middle"
    },
    {
      "x": 3,
      "y": 9,
      "z": 3,
      "name": "Rock_Stone_Brick_Pillar_Middle"
    },
    {
      "x": 3,
      "y": 10,
      "z": 3,
      "name": "Rock_Stone_Brick_Pillar_Base",
      "rotation": 8
    },
    {
      "x": 3,
      "y": 4,
      "z": 4,
      "name": "Rock_Stone_Brick"
    },
    {
      "x": 3,
      "y": 5,
      "z": 4,
      "name": "Rock_Stone_Brick"
    },
    {
      "x": 3,
      "y": 6,
      "z": 4,
      "name": "Rock_Stone_Brick"
    },
    {
      "x": 3,
      "y": 7,
      "z": 4,
      "name": "Rock_Stone_Brick"
    },
    {
      "x": 3,
      "y": 4,
      "z": 5,
      "name": "Rock_Stone_Brick"
    },
    {
      "x": 3,
      "y": 5,
      "z": 5,
      "name": "Rock_Stone_Brick"
    },
    {
      "x": 3,
      "y": 6,
      "z": 5,
      "name": "Rock_Stone_Brick"
    },
    {
      "x": 3,
      "y": 7,
      "z": 5,
      "name": "Rock_Stone_Brick"
    },
    {
      "x": 3,
      "y": 4,
      "z": 6,
      "name": "Rock_Stone_Brick"
    },
    {
      "x": 3,
      "y": 5,
      "z": 6,
      "name": "Rock_Stone_Brick"
    },
    {
      "x": 3,
      "y": 6,
      "z": 6,
      "name": "Rock_Stone_Brick"
    },
    {
      "x": 3,
      "y": 7,
      "z": 6,
      "name": "Rock_Stone_Brick"
    },
    {
      "x": 3,
      "y": 4,
      "z": 7,
      "name": "Rock_Stone_Brick"
    },
    {
      "x": 3,
      "y": 5,
      "z": 7,
      "name": "Rock_Stone_Brick"
    },
    {
      "x": 3,
      "y": 6,
      "z": 7,
      "name": "Rock_Stone_Brick"
    },
    {
      "x": 3,
      "y": 7,
      "z": 7,
      "name": "Rock_Stone_Brick"
    },
    {
      "x": 3,
      "y": 4,
      "z": 8,
      "name": "Rock_Stone_Brick"
    },
    {
      "x": 3,
      "y": 5,
      "z": 8,
      "name": "Rock_Stone_Brick"
    },
    {
      "x": 3,
      "y": 6,
      "z": 8,
      "name": "Rock_Stone_Brick"
    },
    {
      "x": 3,
      "y": 7,
      "z": 8,
      "name": "Rock_Stone_Brick"
    },
    {
      "x": 4,
      "y": 4,
      "z": -19,
      "name": "Rock_Stone_Brick"
    },
    {
      "x": 4,
      "y": 4,
      "z": -18,
      "name": "Rock_Stone_Brick"
    },
    {
      "x": 4,
      "y": 4,
      "z": -17,
      "name": "Rock_Stone_Brick"
    },
    {
      "x": 4,
      "y": 4,
      "z": -16,
      "name": "Soil_Grass_Deep"
    },
    {
      "x": 4,
      "y": 5,
      "z": -16,
      "name": "Plant_Flower_Common_Red2"
    },
    {
      "x": 4,
      "y": 4,
      "z": -15,
      "name": "Soil_Grass_Deep"
    },
    {
      "x": 4,
      "y": 5,
      "z": -15,
      "name": "Plant_Fern_Forest"
    },
    {
      "x": 4,
      "y": 4,
      "z": -14,
      "name": "Soil_Grass_Deep"
    },
    {
      "x": 4,
      "y": 5,
      "z": -14,
      "name": "Plant_Flower_Common_Violet"
    },
    {
      "x": 4,
      "y": 4,
      "z": -13,
      "name": "Rock_Stone_Brick"
    },
    {
      "x": 4,
      "y": 4,
      "z": -12,
      "name": "Rock_Stone_Brick"
    },
    {
      "x": 4,
      "y": 4,
      "z": -11,
      "name": "Rock_Stone_Brick"
    },
    {
      "x": 4,
      "y": 4,
      "z": -10,
      "name": "Rock_Stone_Brick"
    },
    {
      "x": 4,
      "y": 4,
      "z": -9,
      "name": "Rock_Stone_Brick"
    },
    {
      "x": 4,
      "y": 4,
      "z": -8,
      "name": "Soil_Grass_Deep"
    },
    {
      "x": 4,
      "y": 5,
      "z": -8,
      "name": "Plant_Flower_Common_Orange"
    },
    {
      "x": 4,
      "y": 4,
      "z": -7,
      "name": "Soil_Grass_Deep"
    },
    {
      "x": 4,
      "y": 5,
      "z": -7,
      "name": "Plant_Flower_Flax_White"
    },
    {
      "x": 4,
      "y": 4,
      "z": -6,
      "name": "Soil_Grass_Deep"
    },
    {
      "x": 4,
      "y": 5,
      "z": -6,
      "name": "Plant_Flower_Common_Orange"
    },
    {
      "x": 4,
      "y": 4,
      "z": -5,
      "name": "Rock_Stone_Brick"
    },
    {
      "x": 4,
      "y": 4,
      "z": -4,
      "name": "Rock_Stone_Brick"
    },
    {
      "x": 4,
      "y": 4,
      "z": -3,
      "name": "Rock_Stone_Brick"
    },
    {
      "x": 5,
      "y": 4,
      "z": -18,
      "name": "Rock_Stone_Brick"
    },
    {
      "x": 5,
      "y": 4,
      "z": -17,
      "name": "Rock_Stone_Brick"
    },
    {
      "x": 5,
      "y": 4,
      "z": -16,
      "name": "Rock_Stone_Brick"
    },
    {
      "x": 5,
      "y": 4,
      "z": -15,
      "name": "Soil_Grass_Deep"
    },
    {
      "x": 5,
      "y": 5,
      "z": -15,
      "name": "Plant_Flower_Common_Purple"
    },
    {
      "x": 5,
      "y": 4,
      "z": -14,
      "name": "Soil_Grass_Deep"
    },
    {
      "x": 5,
      "y": 5,
      "z": -14,
      "name": "Plant_Fern_Forest"
    },
    {
      "x": 5,
      "y": 4,
      "z": -13,
      "name": "Soil_Grass_Deep"
    },
    {
      "x": 5,
      "y": 5,
      "z": -13,
      "name": "Plant_Flower_Common_Violet"
    },
    {
      "x": 5,
      "y": 4,
      "z": -12,
      "name": "Soil_Grass_Deep"
    },
    {
      "x": 5,
      "y": 5,
      "z": -12,
      "name": "Plant_Flower_Flax_White"
    },
    {
      "x": 5,
      "y": 4,
      "z": -11,
      "name": "Soil_Grass_Deep"
    },
    {
      "x": 5,
      "y": 5,
      "z": -11,
      "name": "Plant_Flower_Common_Red"
    },
    {
      "x": 5,
      "y": 4,
      "z": -10,
      "name": "Soil_Grass_Deep"
    },
    {
      "x": 5,
      "y": 5,
      "z": -10,
      "name": "Plant_Flower_Flax_White"
    },
    {
      "x": 5,
      "y": 4,
      "z": -9,
      "name": "Soil_Grass_Deep"
    },
    {
      "x": 5,
      "y": 5,
      "z": -9,
      "name": "Plant_Fern_Forest"
    },
    {
      "x": 5,
      "y": 4,
      "z": -8,
      "name": "Soil_Grass_Deep"
    },
    {
      "x": 5,
      "y": 5,
      "z": -8,
      "name": "Plant_Flower_Common_Red2"
    },
    {
      "x": 5,
      "y": 4,
      "z": -7,
      "name": "Soil_Grass_Deep"
    },
    {
      "x": 5,
      "y": 5,
      "z": -7,
      "name": "Plant_Fern_Forest"
    },
    {
      "x": 5,
      "y": 4,
      "z": -6,
      "name": "Rock_Stone_Brick"
    },
    {
      "x": 5,
      "y": 4,
      "z": -5,
      "name": "Rock_Stone_Brick"
    },
    {
      "x": 5,
      "y": 4,
      "z": -4,
      "name": "Rock_Stone_Brick"
    },
    {
      "x": 6,
      "y": 4,
      "z": -17,
      "name": "Rock_Stone_Brick"
    },
    {
      "x": 6,
      "y": 4,
      "z": -16,
      "name": "Rock_Stone_Brick"
    },
    {
      "x": 6,
      "y": 4,
      "z": -15,
      "name": "Rock_Stone_Brick"
    },
    {
      "x": 6,
      "y": 4,
      "z": -14,
      "name": "Soil_Grass_Deep"
    },
    {
      "x": 6,
      "y": 5,
      "z": -14,
      "name": "Plant_Flower_Flax_White"
    },
    {
      "x": 6,
      "y": 4,
      "z": -13,
      "name": "Soil_Grass_Deep"
    },
    {
      "x": 6,
      "y": 5,
      "z": -13,
      "name": "Plant_Flower_Common_Purple"
    },
    {
      "x": 6,
      "y": 4,
      "z": -12,
      "name": "Soil_Grass_Deep"
    },
    {
      "x": 6,
      "y": 5,
      "z": -12,
      "name": "Plant_Flower_Common_Violet"
    },
    {
      "x": 6,
      "y": 4,
      "z": -11,
      "name": "Soil_Grass_Deep"
    },
    {
      "x": 6,
      "y": 5,
      "z": -11,
      "name": "Plant_Fern_Forest"
    },
    {
      "x": 6,
      "y": 4,
      "z": -10,
      "name": "Soil_Grass_Deep"
    },
    {
      "x": 6,
      "y": 5,
      "z": -10,
      "name": "Plant_Flower_Common_Red"
    },
    {
      "x": 6,
      "y": 4,
      "z": -9,
      "name": "Soil_Grass_Deep"
    },
    {
      "x": 6,
      "y": 5,
      "z": -9,
      "name": "Plant_Flower_Common_Red2"
    },
    {
      "x": 6,
      "y": 4,
      "z": -8,
      "name": "Soil_Grass_Deep"
    },
    {
      "x": 6,
      "y": 5,
      "z": -8,
      "name": "Plant_Flower_Flax_White"
    },
    {
      "x": 6,
      "y": 4,
      "z": -7,
      "name": "Rock_Stone_Brick"
    },
    {
      "x": 6,
      "y": 4,
      "z": -6,
      "name": "Rock_Stone_Brick"
    },
    {
      "x": 6,
      "y": 4,
      "z": -5,
      "name": "Rock_Stone_Brick"
    },
    {
      "x": 7,
      "y": 4,
      "z": -16,
      "name": "Rock_Stone_Brick"
    },
    {
      "x": 7,
      "y": 4,
      "z": -15,
      "name": "Rock_Stone_Brick"
    },
    {
      "x": 7,
      "y": 4,
      "z": -14,
      "name": "Rock_Stone_Brick"
    },
    {
      "x": 7,
      "y": 4,
      "z": -13,
      "name": "Rock_Stone_Brick"
    },
    {
      "x": 7,
      "y": 5,
      "z": -13,
      "name": "Furniture_Castle_Bench",
      "rotation": 1
    },
    {
      "x": 7,
      "y": 4,
      "z": -12,
      "name": "Rock_Stone_Brick"
    },
    {
      "x": 7,
      "y": 5,
      "z": -12,
      "name": "Furniture_Castle_Bench",
      "filler": 32,
      "rotation": 1
    },
    {
      "x": 7,
      "y": 4,
      "z": -11,
      "name": "Rock_Stone_Brick"
    },
    {
      "x": 7,
      "y": 5,
      "z": -11,
      "name": "Furniture_Village_Brazier"
    },
    {
      "x": 7,
      "y": 4,
      "z": -10,
      "name": "Rock_Stone_Brick"
    },
    {
      "x": 7,
      "y": 5,
      "z": -10,
      "name": "Furniture_Castle_Bench",
      "rotation": 1
    },
    {
      "x": 7,
      "y": 4,
      "z": -9,
      "name": "Rock_Stone_Brick"
    },
    {
      "x": 7,
      "y": 5,
      "z": -9,
      "name": "Furniture_Castle_Bench",
      "filler": 32,
      "rotation": 1
    },
    {
      "x": 7,
      "y": 4,
      "z": -8,
      "name": "Rock_Stone_Brick"
    },
    {
      "x": 7,
      "y": 4,
      "z": -7,
      "name": "Rock_Stone_Brick"
    },
    {
      "x": 7,
      "y": 4,
      "z": -6,
      "name": "Rock_Stone_Brick"
    },
    {
      "x": 8,
      "y": 4,
      "z": -15,
      "name": "Rock_Stone_Brick"
    },
    {
      "x": 8,
      "y": 4,
      "z": -14,
      "name": "Rock_Stone_Brick"
    },
    {
      "x": 8,
      "y": 4,
      "z": -13,
      "name": "Rock_Stone_Brick"
    },
    {
      "x": 8,
      "y": 4,
      "z": -12,
      "name": "Rock_Stone_Brick"
    },
    {
      "x": 8,
      "y": 4,
      "z": -11,
      "name": "Rock_Stone_Brick"
    },
    {
      "x": 8,
      "y": 4,
      "z": -10,
      "name": "Rock_Stone_Brick"
    },
    {
      "x": 8,
      "y": 4,
      "z": -9,
      "name": "Rock_Stone_Brick"
    },
    {
      "x": 8,
      "y": 4,
      "z": -8,
      "name": "Rock_Stone_Brick"
    },
    {
      "x": 8,
      "y": 4,
      "z": -7,
      "name": "Rock_Stone_Brick"
    },
    {
      "x": 9,
      "y": 4,
      "z": -14,
      "name": "Rock_Stone_Brick"
    },
    {
      "x": 9,
      "y": 4,
      "z": -13,
      "name": "Rock_Stone_Brick"
    },
    {
      "x": 9,
      "y": 4,
      "z": -12,
      "name": "Rock_Stone_Brick"
    },
    {
      "x": 9,
      "y": 4,
      "z": -11,
      "name": "Rock_Stone_Brick"
    },
    {
      "x": 9,
      "y": 4,
      "z": -10,
      "name": "Rock_Stone_Brick"
    },
    {
      "x": 9,
      "y": 4,
      "z": -9,
      "name": "Rock_Stone_Brick"
    },
    {
      "x": 9,
      "y": 4,
      "z": -8,
      "name": "Rock_Stone_Brick"
    }
  ],
  "fluids": [
    {
      "x": 0,
      "y": 4,
      "z": -12,
      "name": "Water_Source",
      "level": 1
    },
    {
      "x": 0,
      "y": 4,
      "z": -11,
      "name": "Water_Source",
      "level": 1
    },
    {
      "x": 0,
      "y": 4,
      "z": -10,
      "name": "Water_Source",
      "level": 1
    },
    {
      "x": 1,
      "y": 4,
      "z": -12,
      "name": "Water_Source",
      "level": 1
    },
    {
      "x": 1,
      "y": 4,
      "z": -10,
      "name": "Water_Source",
      "level": 1
    },
    {
      "x": 2,
      "y": 4,
      "z": -12,
      "name": "Water_Source",
      "level": 1
    },
    {
      "x": 2,
      "y": 4,
      "z": -11,
      "name": "Water_Source",
      "level": 1
    },
    {
      "x": 2,
      "y": 4,
      "z": -10,
      "name": "Water_Source",
      "level": 1
    }
  ]
}